Workbook

Sheet Estoque de gado
C1: Categoria Animal | D1: Peso Est. | E1: uAs | G1: # | H1: Suplemento | J1: Gramas/100kg | K1: KG/uA | L1: KG/Dia | O1: KG/Mês
C2: Vaca Parida | D2: 600 | E2: =D2/450 -> 1.3333333 | G2: 1 | H2: Sal Águas | J2: 30 | K2: =J2*4.5/1000 -> 0.135 | L2: =SUMIF($Q$13:$Q$46,G2,$R$13:$R$46) -> 0 | O2: =30*L2 -> 0
C3: Vaca | D3: 450 | E3: =D3/450 -> 1 | G3: 2 | H3: Sal Transição | J3: 50 | K3: =J3*4.5/1000 -> 0.225 | L3: =SUMIF($Q$13:$Q$46,G3,$R$13:$R$46) -> 80.1 | O3: =30*L3 -> 2403
C4: Novilha | D4: 340 | E4: =D4/450 -> 0.75555556 | G4: 3 | H4: Sal Seca | J4: 60 | K4: =J4*4.5/1000 -> 0.27 | L4: =SUMIF($Q$13:$Q$46,G4,$R$13:$R$46) -> 0 | O4: =30*L4 -> 0
C5: Novilhota | D5: 250 | E5: =D5/450 -> 0.55555556 | G5: 4 | H5: Protéico 0.1% | J5: 100 | K5: =J5*4.5/1000 -> 0.45 | L5: =SUMIF($Q$13:$Q$46,G5,$R$13:$R$46) -> 299.41 | O5: =30*L5 -> 8982.3
C6: Bezerro Desm | D6: 225 | E6: =D6/450 -> 0.5 | G6: 5 | H6: Protéico 0.3% | J6: 300 | K6: =J6*4.5/1000 -> 1.35 | L6: =SUMIF($Q$13:$Q$46,G6,$R$13:$R$46) -> 0 | O6: =30*L6 -> 0
C7: Touro | D7: 800 | E7: =D7/450 -> 1.7777778 | G7: 6 | H7: Ração | J7: 1000 | K7: =J7*4.5/1000 -> 4.5 | L7: =SUMIF($Q$13:$Q$46,G7,$R$13:$R$46) -> 0 | O7: =30*L7 -> 0
C8: Tropa | D8: 675 | E8: =D8/450 -> 1.5 | G8: 7 | H8: Ração Tropa | J8: 0 | K8: =J8*4.5/1000 -> 0 | L8: =SUMIF($Q$13:$Q$46,G8,$R$13:$R$46) -> 0 | O8: =30*L8 -> 0
B12: Pasto | C12: Hectares | D12: Data | E12: Vaca Parida | F12: Vaca | G12: Novilha | H12: Novilhota | I12: Garrote | J12: Bez(O/A) | K12: Touro | L12: Tropa | M12: OBS | N12: Total Cabeças | O12: Total uAs | P12: uA/Ha real | Q12: Suplemento | R12: Kg/Dia | S12: uA/Hectare | T12: uAs [Águas] | U12: uAs [Seca] | V12: Corte 0-10 | W12: Capim | X12: Forma | Y12: Estado
A13: 1 | B13: Rotacionado Entrada | C13: 89.9 | D13: =MAX('HISTORICO '!A:A) -> 46237 | E13: =IFERROR(VLOOKUP(B13&$E$12&TEXT(D13,"dd/mm/aaaa"),'HISTORICO '!D:E,2,FALSE),0) -> 0 | F13: =IFERROR(VLOOKUP(B13&$F$12&TEXT(D13,"dd/mm/aaaa"),'HISTORICO '!D:E,2,FALSE),0) -> 37 | G13: =IFERROR(VLOOKUP(B13&G$12&TEXT(D13,"dd/mm/aaaa"),'HISTORICO '!D:E,2,FALSE),0) -> 0 | H13: =IFERROR(VLOOKUP(B13&H$12&TEXT(D13,"dd/mm/aaaa"),'HISTORICO '!D:E,2,FALSE),0) -> 0 | I13: =IFERROR(VLOOKUP(B13&I$12&TEXT(D13,"dd/mm/aaaa"),'HISTORICO '!D:E,2,FALSE),0) -> 0 | J13: =IFERROR(VLOOKUP(B13&J$12&TEXT(D13,"dd/mm/aaaa"),'HISTORICO '!D:E,2,FALSE),0) -> 16 | K13: =IFERROR(VLOOKUP(B13&K$12&TEXT(D13,"dd/mm/aaaa"),'HISTORICO '!D:E,2,FALSE),0) -> 0 | M13: =IFERROR(_xlfn.XLOOKUP(D13 & B13, 'HISTORICO '!G:G, 'HISTORICO '!F:F),"") -> 16 vacas paridas + 21 solteiras | N13: =SUM(E13:L13)+IF(E13>0,E13*1,0) -> 53 | O13: =E13*$E$2+F13*$E$3+G13*$E$4+H13*$E$5+J13*$E$6+K13*$E$7+L13*$E$8 -> 45 | P13: =O13/C13 -> 0.50055617 | Q13: 2 | R13: =SUMIF($G$2:$G$8,Q13,$K$2:$K$8)*O13 -> 10.125 | S13: 2 | T13: =S13*$C13 -> 179.8 | U13: =0.5*T13 -> 89.9 | V13: 5 | W13: Massai | X13: Boa
A14: 2 | B14: Cedro 1 | C14: 18 | D14: =MAX('HISTORICO '!A:A) -> 46237 | E14: =IFERROR(VLOOKUP(B14&$E$12&TEXT(D14,"dd/mm/aaaa"),'HISTORICO '!D:E,2,FALSE),0) -> 0 | F14: =IFERROR(VLOOKUP(B14&$F$12&TEXT(D14,"dd/mm/aaaa"),'HISTORICO '!D:E,2,FALSE),0) -> 0 | G14: =IFERROR(VLOOKUP(B14&G$12&TEXT(D14,"dd/mm/aaaa"),'HISTORICO '!D:E,2,FALSE),0) -> 0 | H14: =IFERROR(VLOOKUP(B14&H$12&TEXT(D14,"dd/mm/aaaa"),'HISTORICO '!D:E,2,FALSE),0) -> 0 | I14: =IFERROR(VLOOKUP(B14&I$12&TEXT(D14,"dd/mm/aaaa"),'HISTORICO '!D:E,2,FALSE),0) -> 0 | J14: =IFERROR(VLOOKUP(B14&J$12&TEXT(D14,"dd/mm/aaaa"),'HISTORICO '!D:E,2,FALSE),0) -> 0 | K14: =IFERROR(VLOOKUP(B14&K$12&TEXT(D14,"dd/mm/aaaa"),'HISTORICO '!D:E,2,FALSE),0) -> 0 | M14: =IFERROR(_xlfn.XLOOKUP(D14 & B14, 'HISTORICO '!G:G, 'HISTORICO '!F:F),"") | N14: =SUM(E14:L14)+IF(E14>0,E14*1,0) -> 0 | O14: =E14*$E$2+F14*$E$3+G14*$E$4+H14*$E$5+J14*$E$6+K14*$E$7+L14*$E$8 -> 0 | P14: =O14/C14 -> 0 | R14: =SUMIF($G$2:$G$8,Q14,$K$2:$K$8)*O14 -> 0 | S14: 0 | T14: =S14*$C14 -> 0 | U14: =0.5*T14 -> 0 | V14: 0 | W14: Massai | X14: Ruim
A15: 3 | B15: Cedro 2 | C15: 51.7 | D15: =MAX('HISTORICO '!A:A) -> 46237 | E15: =IFERROR(VLOOKUP(B15&$E$12&TEXT(D15,"dd/mm/aaaa"),'HISTORICO '!D:E,2,FALSE),0) -> 0 | F15: =IFERROR(VLOOKUP(B15&$F$12&TEXT(D15,"dd/mm/aaaa"),'HISTORICO '!D:E,2,FALSE),0) -> 0 | G15: =IFERROR(VLOOKUP(B15&G$12&TEXT(D15,"dd/mm/aaaa"),'HISTORICO '!D:E,2,FALSE),0) -> 0 | H15: =IFERROR(VLOOKUP(B15&H$12&TEXT(D15,"dd/mm/aaaa"),'HISTORICO '!D:E,2,FALSE),0) -> 0 | I15: =IFERROR(VLOOKUP(B15&I$12&TEXT(D15,"dd/mm/aaaa"),'HISTORICO '!D:E,2,FALSE),0) -> 0 | J15: =IFERROR(VLOOKUP(B15&J$12&TEXT(D15,"dd/mm/aaaa"),'HISTORICO '!D:E,2,FALSE),0) -> 0 | K15: =IFERROR(VLOOKUP(B15&K$12&TEXT(D15,"dd/mm/aaaa"),'HISTORICO '!D:E,2,FALSE),0) -> 0 | M15: =IFERROR(_xlfn.XLOOKUP(D15 & B15, 'HISTORICO '!G:G, 'HISTORICO '!F:F),"") | N15: =SUM(E15:L15)+IF(E15>0,E15*1,0) -> 0 | O15: =E15*$E$2+F15*$E$3+G15*$E$4+H15*$E$5+J15*$E$6+K15*$E$7+L15*$E$8 -> 0 | P15: =O15/C15 -> 0 | R15: =SUMIF($G$2:$G$8,Q15,$K$2:$K$8)*O15 -> 0 | S15: 1 | T15: =S15*$C15 -> 51.7 | U15: =0.5*T15 -> 25.85 | V15: 4 | W15: Braquiária | X15: Ruim
A16: 4 | B16: Matinha | C16: 4.69 | D16: =MAX('HISTORICO '!A:A) -> 46237 | E16: =IFERROR(VLOOKUP(B16&$E$12&TEXT(D16,"dd/mm/aaaa"),'HISTORICO '!D:E,2,FALSE),0) -> 0 | F16: =IFERROR(VLOOKUP(B16&$F$12&TEXT(D16,"dd/mm/aaaa"),'HISTORICO '!D:E,2,FALSE),0) -> 0 | G16: =IFERROR(VLOOKUP(B16&G$12&TEXT(D16,"dd/mm/aaaa"),'HISTORICO '!D:E,2,FALSE),0) -> 0 | H16: =IFERROR(VLOOKUP(B16&H$12&TEXT(D16,"dd/mm/aaaa"),'HISTORICO '!D:E,2,FALSE),0) -> 0 | I16: =IFERROR(VLOOKUP(B16&I$12&TEXT(D16,"dd/mm/aaaa"),'HISTORICO '!D:E,2,FALSE),0) -> 0 | J16: =IFERROR(VLOOKUP(B16&J$12&TEXT(D16,"dd/mm/aaaa"),'HISTORICO '!D:E,2,FALSE),0) -> 0 | K16: =IFERROR(VLOOKUP(B16&K$12&TEXT(D16,"dd/mm/aaaa"),'HISTORICO '!D:E,2,FALSE),0) -> 0 | M16: =IFERROR(_xlfn.XLOOKUP(D16 & B16, 'HISTORICO '!G:G, 'HISTORICO '!F:F),"") | N16: =SUM(E16:L16)+IF(E16>0,E16*1,0) -> 0 | O16: =E16*$E$2+F16*$E$3+G16*$E$4+H16*$E$5+J16*$E$6+K16*$E$7+L16*$E$8 -> 0 | P16: =O16/C16 -> 0 | Q16: 2 | R16: =SUMIF($G$2:$G$8,Q16,$K$2:$K$8)*O16 -> 0 | S16: 2 | T16: =S16*$C16 -> 9.38 | U16: =0.5*T16 -> 4.69 | W16: Tamani | X16: Boa
A17: 5 | B17: PQT Garanhão | C17: 0.76 | D17: =MAX('HISTORICO '!A:A) -> 46237 | E17: =IFERROR(VLOOKUP(B17&$E$12&TEXT(D17,"dd/mm/aaaa"),'HISTORICO '!D:E,2,FALSE),0) -> 0 | F17: =IFERROR(VLOOKUP(B17&$F$12&TEXT(D17,"dd/mm/aaaa"),'HISTORICO '!D:E,2,FALSE),0) -> 0 | G17: =IFERROR(VLOOKUP(B17&G$12&TEXT(D17,"dd/mm/aaaa"),'HISTORICO '!D:E,2,FALSE),0) -> 0 | H17: =IFERROR(VLOOKUP(B17&H$12&TEXT(D17,"dd/mm/aaaa"),'HISTORICO '!D:E,2,FALSE),0) -> 0 | I17: =IFERROR(VLOOKUP(B17&I$12&TEXT(D17,"dd/mm/aaaa"),'HISTORICO '!D:E,2,FALSE),0) -> 0 | J17: =IFERROR(VLOOKUP(B17&J$12&TEXT(D17,"dd/mm/aaaa"),'HISTORICO '!D:E,2,FALSE),0) -> 0 | K17: =IFERROR(VLOOKUP(B17&K$12&TEXT(D17,"dd/mm/aaaa"),'HISTORICO '!D:E,2,FALSE),0) -> 0 | M17: =IFERROR(_xlfn.XLOOKUP(D17 & B17, 'HISTORICO '!G:G, 'HISTORICO '!F:F),"") | N17: =SUM(E17:L17)+IF(E17>0,E17*1,0) -> 0 | O17: =E17*$E$2+F17*$E$3+G17*$E$4+H17*$E$5+J17*$E$6+K17*$E$7+L17*$E$8 -> 0 | P17: =O17/C17 -> 0 | R17: =SUMIF($G$2:$G$8,Q17,$K$2:$K$8)*O17 -> 0 | S17: 1 | T17: =S17*$C17 -> 0.76 | U17: =0.5*T17 -> 0.38 | W17: Tamani | X17: Boa
A18: 6 | B18: Vila 1 | C18: 7 | D18: =MAX('HISTORICO '!A:A) -> 46237 | E18: =IFERROR(VLOOKUP(B18&$E$12&TEXT(D18,"dd/mm/aaaa"),'HISTORICO '!D:E,2,FALSE),0) -> 0 | F18: =IFERROR(VLOOKUP(B18&$F$12&TEXT(D18,"dd/mm/aaaa"),'HISTORICO '!D:E,2,FALSE),0) -> 0 | G18: =IFERROR(VLOOKUP(B18&G$12&TEXT(D18,"dd/mm/aaaa"),'HISTORICO '!D:E,2,FALSE),0) -> 0 | H18: =IFERROR(VLOOKUP(B18&H$12&TEXT(D18,"dd/mm/aaaa"),'HISTORICO '!D:E,2,FALSE),0) -> 0 | I18: =IFERROR(VLOOKUP(B18&I$12&TEXT(D18,"dd/mm/aaaa"),'HISTORICO '!D:E,2,FALSE),0) -> 0 | J18: =IFERROR(VLOOKUP(B18&J$12&TEXT(D18,"dd/mm/aaaa"),'HISTORICO '!D:E,2,FALSE),0) -> 0 | K18: =IFERROR(VLOOKUP(B18&K$12&TEXT(D18,"dd/mm/aaaa"),'HISTORICO '!D:E,2,FALSE),0) -> 0 | M18: =IFERROR(_xlfn.XLOOKUP(D18 & B18, 'HISTORICO '!G:G, 'HISTORICO '!F:F),"") | N18: =SUM(E18:L18)+IF(E18>0,E18*1,0) -> 0 | O18: =E18*$E$2+F18*$E$3+G18*$E$4+H18*$E$5+J18*$E$6+K18*$E$7+L18*$E$8 -> 0 | P18: =O18/C18 -> 0 | R18: =SUMIF($G$2:$G$8,Q18,$K$2:$K$8)*O18 -> 0 | S18: 1.5 | T18: =S18*$C18 -> 10.5 | U18: =0.5*T18 -> 5.25 | W18: Tamani | X18: Média
A19: 7 | B19: Vila 2 | C19: 12.9 | D19: =MAX('HISTORICO '!A:A) -> 46237 | E19: =IFERROR(VLOOKUP(B19&$E$12&TEXT(D19,"dd/mm/aaaa"),'HISTORICO '!D:E,2,FALSE),0) -> 0 | F19: =IFERROR(VLOOKUP(B19&$F$12&TEXT(D19,"dd/mm/aaaa"),'HISTORICO '!D:E,2,FALSE),0) -> 0 | G19: =IFERROR(VLOOKUP(B19&G$12&TEXT(D19,"dd/mm/aaaa"),'HISTORICO '!D:E,2,FALSE),0) -> 0 | H19: =IFERROR(VLOOKUP(B19&H$12&TEXT(D19,"dd/mm/aaaa"),'HISTORICO '!D:E,2,FALSE),0) -> 0 | I19: =IFERROR(VLOOKUP(B19&I$12&TEXT(D19,"dd/mm/aaaa"),'HISTORICO '!D:E,2,FALSE),0) -> 0 | J19: =IFERROR(VLOOKUP(B19&J$12&TEXT(D19,"dd/mm/aaaa"),'HISTORICO '!D:E,2,FALSE),0) -> 0 | K19: =IFERROR(VLOOKUP(B19&K$12&TEXT(D19,"dd/mm/aaaa"),'HISTORICO '!D:E,2,FALSE),0) -> 0 | M19: =IFERROR(_xlfn.XLOOKUP(D19 & B19, 'HISTORICO '!G:G, 'HISTORICO '!F:F),"") | N19: =SUM(E19:L19)+IF(E19>0,E19*1,0) -> 0 | O19: =E19*$E$2+F19*$E$3+G19*$E$4+H19*$E$5+J19*$E$6+K19*$E$7+L19*$E$8 -> 0 | P19: =O19/C19 -> 0 | R19: =SUMIF($G$2:$G$8,Q19,$K$2:$K$8)*O19 -> 0 | S19: 1.5 | T19: =S19*$C19 -> 19.35 | U19: =0.5*T19 -> 9.675 | W19: Tamani | X19: Média
A20: 8 | B20: Rotacionado Vila 1 | C20: 8.07 | D20: =MAX('HISTORICO '!A:A) -> 46237 | E20: =IFERROR(VLOOKUP(B20&$E$12&TEXT(D20,"dd/mm/aaaa"),'HISTORICO '!D:E,2,FALSE),0) -> 0 | F20: =IFERROR(VLOOKUP(B20&$F$12&TEXT(D20,"dd/mm/aaaa"),'HISTORICO '!D:E,2,FALSE),0) -> 0 | G20: =IFERROR(VLOOKUP(B20&G$12&TEXT(D20,"dd/mm/aaaa"),'HISTORICO '!D:E,2,FALSE),0) -> 0 | H20: =IFERROR(VLOOKUP(B20&H$12&TEXT(D20,"dd/mm/aaaa"),'HISTORICO '!D:E,2,FALSE),0) -> 0 | I20: =IFERROR(VLOOKUP(B20&I$12&TEXT(D20,"dd/mm/aaaa"),'HISTORICO '!D:E,2,FALSE),0) -> 0 | J20: =IFERROR(VLOOKUP(B20&J$12&TEXT(D20,"dd/mm/aaaa"),'HISTORICO '!D:E,2,FALSE),0) -> 0 | K20: =IFERROR(VLOOKUP(B20&K$12&TEXT(D20,"dd/mm/aaaa"),'HISTORICO '!D:E,2,FALSE),0) -> 0 | M20: =IFERROR(_xlfn.XLOOKUP(D20 & B20, 'HISTORICO '!G:G, 'HISTORICO '!F:F),"") | N20: =SUM(E20:L20)+IF(E20>0,E20*1,0) -> 0 | O20: =E20*$E$2+F20*$E$3+G20*$E$4+H20*$E$5+J20*$E$6+K20*$E$7+L20*$E$8 -> 0 | P20: =O20/C20 -> 0 | Q20: 4 | R20: =SUMIF($G$2:$G$8,Q20,$K$2:$K$8)*O20 -> 0 | S20: 2.5 | T20: =S20*$C20 -> 20.175 | U20: =0.5*T20 -> 10.0875 | W20: Braquiária | X20: Média
A21: 9 | B21: Piquete da Tropa | C21: 4.31 | D21: =MAX('HISTORICO '!A:A) -> 46237 | E21: =IFERROR(VLOOKUP(B21&$E$12&TEXT(D21,"dd/mm/aaaa"),'HISTORICO '!D:E,2,FALSE),0) -> 0 | F21: =IFERROR(VLOOKUP(B21&$F$12&TEXT(D21,"dd/mm/aaaa"),'HISTORICO '!D:E,2,FALSE),0) -> 0 | G21: =IFERROR(VLOOKUP(B21&G$12&TEXT(D21,"dd/mm/aaaa"),'HISTORICO '!D:E,2,FALSE),0) -> 0 | H21: =IFERROR(VLOOKUP(B21&H$12&TEXT(D21,"dd/mm/aaaa"),'HISTORICO '!D:E,2,FALSE),0) -> 0 | I21: =IFERROR(VLOOKUP(B21&I$12&TEXT(D21,"dd/mm/aaaa"),'HISTORICO '!D:E,2,FALSE),0) -> 0 | J21: =IFERROR(VLOOKUP(B21&J$12&TEXT(D21,"dd/mm/aaaa"),'HISTORICO '!D:E,2,FALSE),0) -> 0 | K21: =IFERROR(VLOOKUP(B21&K$12&TEXT(D21,"dd/mm/aaaa"),'HISTORICO '!D:E,2,FALSE),0) -> 0 | M21: =IFERROR(_xlfn.XLOOKUP(D21 & B21, 'HISTORICO '!G:G, 'HISTORICO '!F:F),"") | N21: =SUM(E21:L21)+IF(E21>0,E21*1,0) -> 0 | O21: =E21*$E$2+F21*$E$3+G21*$E$4+H21*$E$5+J21*$E$6+K21*$E$7+L21*$E$8 -> 0 | P21: =O21/C21 -> 0 | R21: =SUMIF($G$2:$G$8,Q21,$K$2:$K$8)*O21 -> 0 | S21: 3 | T21: =S21*$C21 -> 12.93 | U21: =0.5*T21 -> 6.465 | W21: Zuri | X21: Boa
A22: 10 | B22: Remanga | C22: 2.48 | D22: =MAX('HISTORICO '!A:A) -> 46237 | E22: =IFERROR(VLOOKUP(B22&$E$12&TEXT(D22,"dd/mm/aaaa"),'HISTORICO '!D:E,2,FALSE),0) -> 0 | F22: =IFERROR(VLOOKUP(B22&$F$12&TEXT(D22,"dd/mm/aaaa"),'HISTORICO '!D:E,2,FALSE),0) -> 0 | G22: =IFERROR(VLOOKUP(B22&G$12&TEXT(D22,"dd/mm/aaaa"),'HISTORICO '!D:E,2,FALSE),0) -> 0 | H22: =IFERROR(VLOOKUP(B22&H$12&TEXT(D22,"dd/mm/aaaa"),'HISTORICO '!D:E,2,FALSE),0) -> 0 | I22: =IFERROR(VLOOKUP(B22&I$12&TEXT(D22,"dd/mm/aaaa"),'HISTORICO '!D:E,2,FALSE),0) -> 0 | J22: =IFERROR(VLOOKUP(B22&J$12&TEXT(D22,"dd/mm/aaaa"),'HISTORICO '!D:E,2,FALSE),0) -> 0 | K22: =IFERROR(VLOOKUP(B22&K$12&TEXT(D22,"dd/mm/aaaa"),'HISTORICO '!D:E,2,FALSE),0) -> 0 | M22: =IFERROR(_xlfn.XLOOKUP(D22 & B22, 'HISTORICO '!G:G, 'HISTORICO '!F:F),"") | N22: =SUM(E22:L22)+IF(E22>0,E22*1,0) -> 0 | O22: =E22*$E$2+F22*$E$3+G22*$E$4+H22*$E$5+J22*$E$6+K22*$E$7+L22*$E$8 -> 0 | P22: =O22/C22 -> 0 | R22: =SUMIF($G$2:$G$8,Q22,$K$2:$K$8)*O22 -> 0 | S22: 0 | T22: =S22*$C22 -> 0 | U22: =0.5*T22 -> 0 | W22: - | X22: Arado
A23: 11 | B23: Morro de trás | C23: 7.34 | D23: =MAX('HISTORICO '!A:A) -> 46237 | E23: =IFERROR(VLOOKUP(B23&$E$12&TEXT(D23,"dd/mm/aaaa"),'HISTORICO '!D:E,2,FALSE),0) -> 0 | F23: =IFERROR(VLOOKUP(B23&$F$12&TEXT(D23,"dd/mm/aaaa"),'HISTORICO '!D:E,2,FALSE),0) -> 0 | G23: =IFERROR(VLOOKUP(B23&G$12&TEXT(D23,"dd/mm/aaaa"),'HISTORICO '!D:E,2,FALSE),0) -> 0 | H23: =IFERROR(VLOOKUP(B23&H$12&TEXT(D23,"dd/mm/aaaa"),'HISTORICO '!D:E,2,FALSE),0) -> 0 | I23: =IFERROR(VLOOKUP(B23&I$12&TEXT(D23,"dd/mm/aaaa"),'HISTORICO '!D:E,2,FALSE),0) -> 0 | J23: =IFERROR(VLOOKUP(B23&J$12&TEXT(D23,"dd/mm/aaaa"),'HISTORICO '!D:E,2,FALSE),0) -> 0 | K23: =IFERROR(VLOOKUP(B23&K$12&TEXT(D23,"dd/mm/aaaa"),'HISTORICO '!D:E,2,FALSE),0) -> 0 | M23: =IFERROR(_xlfn.XLOOKUP(D23 & B23, 'HISTORICO '!G:G, 'HISTORICO '!F:F),"") | N23: =SUM(E23:L23)+IF(E23>0,E23*1,0) -> 0 | O23: =E23*$E$2+F23*$E$3+G23*$E$4+H23*$E$5+J23*$E$6+K23*$E$7+L23*$E$8 -> 0 | P23: =O23/C23 -> 0 | R23: =SUMIF($G$2:$G$8,Q23,$K$2:$K$8)*O23 -> 0 | S23: 0 | T23: =S23*$C23 -> 0 | U23: =0.5*T23 -> 0 | W23: - | X23: Arado
A24: 12 | B24: Rotacionado Caixa d'Água | C24: 24.45 | D24: =MAX('HISTORICO '!A:A) -> 46237 | E24: =IFERROR(VLOOKUP(B24&$E$12&TEXT(D24,"dd/mm/aaaa"),'HISTORICO '!D:E,2,FALSE),0) -> 0 | F24: =IFERROR(VLOOKUP(B24&$F$12&TEXT(D24,"dd/mm/aaaa"),'HISTORICO '!D:E,2,FALSE),0) -> 0 | G24: =IFERROR(VLOOKUP(B24&G$12&TEXT(D24,"dd/mm/aaaa"),'HISTORICO '!D:E,2,FALSE),0) -> 0 | H24: =IFERROR(VLOOKUP(B24&H$12&TEXT(D24,"dd/mm/aaaa"),'HISTORICO '!D:E,2,FALSE),0) -> 0 | I24: =IFERROR(VLOOKUP(B24&I$12&TEXT(D24,"dd/mm/aaaa"),'HISTORICO '!D:E,2,FALSE),0) -> 0 | J24: =IFERROR(VLOOKUP(B24&J$12&TEXT(D24,"dd/mm/aaaa"),'HISTORICO '!D:E,2,FALSE),0) -> 0 | K24: =IFERROR(VLOOKUP(B24&K$12&TEXT(D24,"dd/mm/aaaa"),'HISTORICO '!D:E,2,FALSE),0) -> 0 | M24: =IFERROR(_xlfn.XLOOKUP(D24 & B24, 'HISTORICO '!G:G, 'HISTORICO '!F:F),"") | N24: =SUM(E24:L24)+IF(E24>0,E24*1,0) -> 0 | O24: =E24*$E$2+F24*$E$3+G24*$E$4+H24*$E$5+J24*$E$6+K24*$E$7+L24*$E$8 -> 0 | P24: =O24/C24 -> 0 | Q24: 4 | R24: =SUMIF($G$2:$G$8,Q24,$K$2:$K$8)*O24 -> 0 | S24: 1.5 | T24: =S24*$C24 -> 36.675 | U24: =0.5*T24 -> 18.3375 | W24: Braquiária | X24: Ruim/médio
A25: 13 | B25: Rotacionado Macaúba | C25: 18.69 | D25: =MAX('HISTORICO '!A:A) -> 46237 | E25: =IFERROR(VLOOKUP(B25&$E$12&TEXT(D25,"dd/mm/aaaa"),'HISTORICO '!D:E,2,FALSE),0) -> 0 | F25: =IFERROR(VLOOKUP(B25&$F$12&TEXT(D25,"dd/mm/aaaa"),'HISTORICO '!D:E,2,FALSE),0) -> 12 | G25: =IFERROR(VLOOKUP(B25&G$12&TEXT(D25,"dd/mm/aaaa"),'HISTORICO '!D:E,2,FALSE),0) -> 14 | H25: =IFERROR(VLOOKUP(B25&H$12&TEXT(D25,"dd/mm/aaaa"),'HISTORICO '!D:E,2,FALSE),0) -> 0 | I25: =IFERROR(VLOOKUP(B25&I$12&TEXT(D25,"dd/mm/aaaa"),'HISTORICO '!D:E,2,FALSE),0) -> 0 | J25: =IFERROR(VLOOKUP(B25&J$12&TEXT(D25,"dd/mm/aaaa"),'HISTORICO '!D:E,2,FALSE),0) -> 6 | K25: =IFERROR(VLOOKUP(B25&K$12&TEXT(D25,"dd/mm/aaaa"),'HISTORICO '!D:E,2,FALSE),0) -> 10 | M25: =IFERROR(_xlfn.XLOOKUP(D25 & B25, 'HISTORICO '!G:G, 'HISTORICO '!F:F),"") -> 0 | N25: =SUM(E25:L25)+IF(E25>0,E25*1,0) -> 42 | O25: =E25*$E$2+F25*$E$3+G25*$E$4+H25*$E$5+J25*$E$6+K25*$E$7+L25*$E$8 -> 43.355556 | P25: =O25/C25 -> 2.3197194 | Q25: 4 | R25: =SUMIF($G$2:$G$8,Q25,$K$2:$K$8)*O25 -> 19.51 | S25: 1.5 | T25: =S25*$C25 -> 28.035 | U25: =0.5*T25 -> 14.0175 | W25: Andropogon | X25: Ruim/médio
A26: 14 | B26: Jacaré 1 | C26: 37.7 | D26: =MAX('HISTORICO '!A:A) -> 46237 | E26: =IFERROR(VLOOKUP(B26&$E$12&TEXT(D26,"dd/mm/aaaa"),'HISTORICO '!D:E,2,FALSE),0) -> 0 | F26: =IFERROR(VLOOKUP(B26&$F$12&TEXT(D26,"dd/mm/aaaa"),'HISTORICO '!D:E,2,FALSE),0) -> 0 | G26: =IFERROR(VLOOKUP(B26&G$12&TEXT(D26,"dd/mm/aaaa"),'HISTORICO '!D:E,2,FALSE),0) -> 0 | H26: =IFERROR(VLOOKUP(B26&H$12&TEXT(D26,"dd/mm/aaaa"),'HISTORICO '!D:E,2,FALSE),0) -> 0 | I26: =IFERROR(VLOOKUP(B26&I$12&TEXT(D26,"dd/mm/aaaa"),'HISTORICO '!D:E,2,FALSE),0) -> 0 | J26: =IFERROR(VLOOKUP(B26&J$12&TEXT(D26,"dd/mm/aaaa"),'HISTORICO '!D:E,2,FALSE),0) -> 0 | K26: =IFERROR(VLOOKUP(B26&K$12&TEXT(D26,"dd/mm/aaaa"),'HISTORICO '!D:E,2,FALSE),0) -> 0 | M26: =IFERROR(_xlfn.XLOOKUP(D26 & B26, 'HISTORICO '!G:G, 'HISTORICO '!F:F),"") | N26: =SUM(E26:L26)+IF(E26>0,E26*1,0) -> 0 | O26: =E26*$E$2+F26*$E$3+G26*$E$4+H26*$E$5+J26*$E$6+K26*$E$7+L26*$E$8 -> 0 | P26: =O26/C26 -> 0 | R26: =SUMIF($G$2:$G$8,Q26,$K$2:$K$8)*O26 -> 0 | S26: 1 | T26: =S26*$C26 -> 37.7 | U26: =0.5*T26 -> 18.85 | W26: Andropogon | X26: Ruim
A27: 15 | B27: Jacaré 2 | C27: 34.4 | D27: =MAX('HISTORICO '!A:A) -> 46237 | E27: =IFERROR(VLOOKUP(B27&$E$12&TEXT(D27,"dd/mm/aaaa"),'HISTORICO '!D:E,2,FALSE),0) -> 0 | F27: =IFERROR(VLOOKUP(B27&$F$12&TEXT(D27,"dd/mm/aaaa"),'HISTORICO '!D:E,2,FALSE),0) -> 0 | G27: =IFERROR(VLOOKUP(B27&G$12&TEXT(D27,"dd/mm/aaaa"),'HISTORICO '!D:E,2,FALSE),0) -> 0 | H27: =IFERROR(VLOOKUP(B27&H$12&TEXT(D27,"dd/mm/aaaa"),'HISTORICO '!D:E,2,FALSE),0) -> 0 | I27: =IFERROR(VLOOKUP(B27&I$12&TEXT(D27,"dd/mm/aaaa"),'HISTORICO '!D:E,2,FALSE),0) -> 0 | J27: =IFERROR(VLOOKUP(B27&J$12&TEXT(D27,"dd/mm/aaaa"),'HISTORICO '!D:E,2,FALSE),0) -> 0 | K27: =IFERROR(VLOOKUP(B27&K$12&TEXT(D27,"dd/mm/aaaa"),'HISTORICO '!D:E,2,FALSE),0) -> 0 | M27: =IFERROR(_xlfn.XLOOKUP(D27 & B27, 'HISTORICO '!G:G, 'HISTORICO '!F:F),"") | N27: =SUM(E27:L27)+IF(E27>0,E27*1,0) -> 0 | O27: =E27*$E$2+F27*$E$3+G27*$E$4+H27*$E$5+J27*$E$6+K27*$E$7+L27*$E$8 -> 0 | P27: =O27/C27 -> 0 | R27: =SUMIF($G$2:$G$8,Q27,$K$2:$K$8)*O27 -> 0 | S27: 0 | T27: =S27*$C27 -> 0 | U27: =0.5*T27 -> 0 | W27: Zuri | X27: Lavoura
A28: 16 | B28: Meio | C28: 28.8 | D28: =MAX('HISTORICO '!A:A) -> 46237 | E28: =IFERROR(VLOOKUP(B28&$E$12&TEXT(D28,"dd/mm/aaaa"),'HISTORICO '!D:E,2,FALSE),0) -> 0 | F28: =IFERROR(VLOOKUP(B28&$F$12&TEXT(D28,"dd/mm/aaaa"),'HISTORICO '!D:E,2,FALSE),0) -> 0 | G28: =IFERROR(VLOOKUP(B28&G$12&TEXT(D28,"dd/mm/aaaa"),'HISTORICO '!D:E,2,FALSE),0) -> 0 | H28: =IFERROR(VLOOKUP(B28&H$12&TEXT(D28,"dd/mm/aaaa"),'HISTORICO '!D:E,2,FALSE),0) -> 0 | I28: =IFERROR(VLOOKUP(B28&I$12&TEXT(D28,"dd/mm/aaaa"),'HISTORICO '!D:E,2,FALSE),0) -> 0 | J28: =IFERROR(VLOOKUP(B28&J$12&TEXT(D28,"dd/mm/aaaa"),'HISTORICO '!D:E,2,FALSE),0) -> 0 | K28: =IFERROR(VLOOKUP(B28&K$12&TEXT(D28,"dd/mm/aaaa"),'HISTORICO '!D:E,2,FALSE),0) -> 0 | M28: =IFERROR(_xlfn.XLOOKUP(D28 & B28, 'HISTORICO '!G:G, 'HISTORICO '!F:F),"") | N28: =SUM(E28:L28)+IF(E28>0,E28*1,0) -> 0 | O28: =E28*$E$2+F28*$E$3+G28*$E$4+H28*$E$5+J28*$E$6+K28*$E$7+L28*$E$8 -> 0 | P28: =O28/C28 -> 0 | R28: =SUMIF($G$2:$G$8,Q28,$K$2:$K$8)*O28 -> 0 | S28: 0 | T28: =S28*$C28 -> 0 | U28: =0.5*T28 -> 0 | W28: - | X28: Arado
A29: 17 | B29: Barriguda 1 | C29: 12.9 | D29: =MAX('HISTORICO '!A:A) -> 46237 | E29: =IFERROR(VLOOKUP(B29&$E$12&TEXT(D29,"dd/mm/aaaa"),'HISTORICO '!D:E,2,FALSE),0) -> 0 | F29: =IFERROR(VLOOKUP(B29&$F$12&TEXT(D29,"dd/mm/aaaa"),'HISTORICO '!D:E,2,FALSE),0) -> 0 | G29: =IFERROR(VLOOKUP(B29&G$12&TEXT(D29,"dd/mm/aaaa"),'HISTORICO '!D:E,2,FALSE),0) -> 0 | H29: =IFERROR(VLOOKUP(B29&H$12&TEXT(D29,"dd/mm/aaaa"),'HISTORICO '!D:E,2,FALSE),0) -> 0 | I29: =IFERROR(VLOOKUP(B29&I$12&TEXT(D29,"dd/mm/aaaa"),'HISTORICO '!D:E,2,FALSE),0) -> 0 | J29: =IFERROR(VLOOKUP(B29&J$12&TEXT(D29,"dd/mm/aaaa"),'HISTORICO '!D:E,2,FALSE),0) -> 0 | K29: =IFERROR(VLOOKUP(B29&K$12&TEXT(D29,"dd/mm/aaaa"),'HISTORICO '!D:E,2,FALSE),0) -> 0 | M29: =IFERROR(_xlfn.XLOOKUP(D29 & B29, 'HISTORICO '!G:G, 'HISTORICO '!F:F),"") | N29: =SUM(E29:L29)+IF(E29>0,E29*1,0) -> 0 | O29: =E29*$E$2+F29*$E$3+G29*$E$4+H29*$E$5+J29*$E$6+K29*$E$7+L29*$E$8 -> 0 | P29: =O29/C29 -> 0 | Q29: 5 | R29: =SUMIF($G$2:$G$8,Q29,$K$2:$K$8)*O29 -> 0 | S29: 2 | T29: =S29*$C29 -> 25.8 | U29: =0.5*T29 -> 12.9 | W29: Zuri | X29: Boa
A30: 18 | B30: Barriguda 2 | C30: 25.2 | D30: =MAX('HISTORICO '!A:A) -> 46237 | E30: =IFERROR(VLOOKUP(B30&$E$12&TEXT(D30,"dd/mm/aaaa"),'HISTORICO '!D:E,2,FALSE),0) -> 0 | F30: =IFERROR(VLOOKUP(B30&$F$12&TEXT(D30,"dd/mm/aaaa"),'HISTORICO '!D:E,2,FALSE),0) -> 0 | G30: =IFERROR(VLOOKUP(B30&G$12&TEXT(D30,"dd/mm/aaaa"),'HISTORICO '!D:E,2,FALSE),0) -> 0 | H30: =IFERROR(VLOOKUP(B30&H$12&TEXT(D30,"dd/mm/aaaa"),'HISTORICO '!D:E,2,FALSE),0) -> 0 | I30: =IFERROR(VLOOKUP(B30&I$12&TEXT(D30,"dd/mm/aaaa"),'HISTORICO '!D:E,2,FALSE),0) -> 0 | J30: =IFERROR(VLOOKUP(B30&J$12&TEXT(D30,"dd/mm/aaaa"),'HISTORICO '!D:E,2,FALSE),0) -> 0 | K30: =IFERROR(VLOOKUP(B30&K$12&TEXT(D30,"dd/mm/aaaa"),'HISTORICO '!D:E,2,FALSE),0) -> 0 | M30: =IFERROR(_xlfn.XLOOKUP(D30 & B30, 'HISTORICO '!G:G, 'HISTORICO '!F:F),"") | N30: =SUM(E30:L30)+IF(E30>0,E30*1,0) -> 0 | O30: =E30*$E$2+F30*$E$3+G30*$E$4+H30*$E$5+J30*$E$6+K30*$E$7+L30*$E$8 -> 0 | P30: =O30/C30 -> 0 | R30: =SUMIF($G$2:$G$8,Q30,$K$2:$K$8)*O30 -> 0 | S30: 4 | T30: =S30*$C30 -> 100.8 | U30: =0.5*T30 -> 50.4 | W30: Zuri | X30: Boa
A31: 19 | B31: Forno 1 | C31: 38 | D31: =MAX('HISTORICO '!A:A) -> 46237 | E31: =IFERROR(VLOOKUP(B31&$E$12&TEXT(D31,"dd/mm/aaaa"),'HISTORICO '!D:E,2,FALSE),0) -> 0 | F31: =IFERROR(VLOOKUP(B31&$F$12&TEXT(D31,"dd/mm/aaaa"),'HISTORICO '!D:E,2,FALSE),0) -> 0 | G31: =IFERROR(VLOOKUP(B31&G$12&TEXT(D31,"dd/mm/aaaa"),'HISTORICO '!D:E,2,FALSE),0) -> 0 | H31: =IFERROR(VLOOKUP(B31&H$12&TEXT(D31,"dd/mm/aaaa"),'HISTORICO '!D:E,2,FALSE),0) -> 0 | I31: =IFERROR(VLOOKUP(B31&I$12&TEXT(D31,"dd/mm/aaaa"),'HISTORICO '!D:E,2,FALSE),0) -> 0 | J31: =IFERROR(VLOOKUP(B31&J$12&TEXT(D31,"dd/mm/aaaa"),'HISTORICO '!D:E,2,FALSE),0) -> 0 | K31: =IFERROR(VLOOKUP(B31&K$12&TEXT(D31,"dd/mm/aaaa"),'HISTORICO '!D:E,2,FALSE),0) -> 0 | M31: =IFERROR(_xlfn.XLOOKUP(D31 & B31, 'HISTORICO '!G:G, 'HISTORICO '!F:F),"") | N31: =SUM(E31:L31)+IF(E31>0,E31*1,0) -> 0
A32: 20 | B32: Forno 2 | C32: 39.7 | D32: =MAX('HISTORICO '!A:A) -> 46237 | E32: =IFERROR(VLOOKUP(B32&$E$12&TEXT(D32,"dd/mm/aaaa"),'HISTORICO '!D:E,2,FALSE),0) -> 0 | F32: =IFERROR(VLOOKUP(B32&$F$12&TEXT(D32,"dd/mm/aaaa"),'HISTORICO '!D:E,2,FALSE),0) -> 0 | G32: =IFERROR(VLOOKUP(B32&G$12&TEXT(D32,"dd/mm/aaaa"),'HISTORICO '!D:E,2,FALSE),0) -> 0 | H32: =IFERROR(VLOOKUP(B32&H$12&TEXT(D32,"dd/mm/aaaa"),'HISTORICO '!D:E,2,FALSE),0) -> 0 | I32: =IFERROR(VLOOKUP(B32&I$12&TEXT(D32,"dd/mm/aaaa"),'HISTORICO '!D:E,2,FALSE),0) -> 0 | J32: =IFERROR(VLOOKUP(B32&J$12&TEXT(D32,"dd/mm/aaaa"),'HISTORICO '!D:E,2,FALSE),0) -> 0 | K32: =IFERROR(VLOOKUP(B32&K$12&TEXT(D32,"dd/mm/aaaa"),'HISTORICO '!D:E,2,FALSE),0) -> 0 | M32: =IFERROR(_xlfn.XLOOKUP(D32 & B32, 'HISTORICO '!G:G, 'HISTORICO '!F:F),"") | N32: =SUM(E32:L32)+IF(E32>0,E32*1,0) -> 0 | O32: =E32*$E$2+F32*$E$3+G32*$E$4+H32*$E$5+J32*$E$6+K32*$E$7+L32*$E$8 -> 0 | P32: =O32/C32 -> 0 | R32: =SUMIF($G$2:$G$8,Q32,$K$2:$K$8)*O32 -> 0 | S32: 4 | T32: =S32*$C32 -> 158.8 | U32: =0.5*T32 -> 79.4 | W32: Andropogon | X32: Boa
A33: 21 | B33: Piquetes da Mata | C33: 106.47 | D33: =MAX('HISTORICO '!A:A) -> 46237 | E33: =IFERROR(VLOOKUP(B33&$E$12&TEXT(D33,"dd/mm/aaaa"),'HISTORICO '!D:E,2,FALSE),0) -> 0 | F33: =IFERROR(VLOOKUP(B33&$F$12&TEXT(D33,"dd/mm/aaaa"),'HISTORICO '!D:E,2,FALSE),0) -> 102 | G33: =IFERROR(VLOOKUP(B33&G$12&TEXT(D33,"dd/mm/aaaa"),'HISTORICO '!D:E,2,FALSE),0) -> 0 | H33: =IFERROR(VLOOKUP(B33&H$12&TEXT(D33,"dd/mm/aaaa"),'HISTORICO '!D:E,2,FALSE),0) -> 0 | I33: =IFERROR(VLOOKUP(B33&I$12&TEXT(D33,"dd/mm/aaaa"),'HISTORICO '!D:E,2,FALSE),0) -> 0 | J33: =IFERROR(VLOOKUP(B33&J$12&TEXT(D33,"dd/mm/aaaa"),'HISTORICO '!D:E,2,FALSE),0) -> 0 | K33: =IFERROR(VLOOKUP(B33&K$12&TEXT(D33,"dd/mm/aaaa"),'HISTORICO '!D:E,2,FALSE),0) -> 0 | M33: =IFERROR(_xlfn.XLOOKUP(D33 & B33, 'HISTORICO '!G:G, 'HISTORICO '!F:F),"") -> Vacas prenhas | N33: =SUM(E33:L33)+IF(E33>0,E33*1,0) -> 102 | O33: =E33*$E$2+F33*$E$3+G33*$E$4+H33*$E$5+J33*$E$6+K33*$E$7+L33*$E$8 -> 102 | P33: =O33/C33 -> 0.95801634 | Q33: 4 | R33: =SUMIF($G$2:$G$8,Q33,$K$2:$K$8)*O33 -> 45.9 | S33: 2 | T33: =S33*$C33 -> 212.94 | U33: =0.5*T33 -> 106.47 | W33: Braquiária | X33: Média
A34: 22 | B34: Rotacionado Cipó Preto | C34: 77.3 | D34: =MAX('HISTORICO '!A:A) -> 46237 | E34: =IFERROR(VLOOKUP(B34&$E$12&TEXT(D34,"dd/mm/aaaa"),'HISTORICO '!D:E,2,FALSE),0) -> 0 | F34: =IFERROR(VLOOKUP(B34&$F$12&TEXT(D34,"dd/mm/aaaa"),'HISTORICO '!D:E,2,FALSE),0) -> 171 | G34: =IFERROR(VLOOKUP(B34&G$12&TEXT(D34,"dd/mm/aaaa"),'HISTORICO '!D:E,2,FALSE),0) -> 0 | H34: =IFERROR(VLOOKUP(B34&H$12&TEXT(D34,"dd/mm/aaaa"),'HISTORICO '!D:E,2,FALSE),0) -> 0 | I34: =IFERROR(VLOOKUP(B34&I$12&TEXT(D34,"dd/mm/aaaa"),'HISTORICO '!D:E,2,FALSE),0) -> 0 | J34: =IFERROR(VLOOKUP(B34&J$12&TEXT(D34,"dd/mm/aaaa"),'HISTORICO '!D:E,2,FALSE),0) -> 0 | K34: =IFERROR(VLOOKUP(B34&K$12&TEXT(D34,"dd/mm/aaaa"),'HISTORICO '!D:E,2,FALSE),0) -> 0 | M34: =IFERROR(_xlfn.XLOOKUP(D34 & B34, 'HISTORICO '!G:G, 'HISTORICO '!F:F),"") -> Vacas prenhas | N34: =SUM(E34:L34)+IF(E34>0,E34*1,0) -> 171 | O34: =E34*$E$2+F34*$E$3+G34*$E$4+H34*$E$5+J34*$E$6+K34*$E$7+L34*$E$8 -> 171 | P34: =O34/C34 -> 2.2121604 | Q34: 4 | R34: =SUMIF($G$2:$G$8,Q34,$K$2:$K$8)*O34 -> 76.95 | S34: 2.5 | T34: =S34*$C34 -> 193.25 | U34: =0.5*T34 -> 96.625 | W34: Andropogon | X34: Boa
A35: 23 | B35: Timbó 1 | C35: 17.2 | D35: =MAX('HISTORICO '!A:A) -> 46237 | E35: =IFERROR(VLOOKUP(B35&$E$12&TEXT(D35,"dd/mm/aaaa"),'HISTORICO '!D:E,2,FALSE),0) -> 0 | F35: =IFERROR(VLOOKUP(B35&$F$12&TEXT(D35,"dd/mm/aaaa"),'HISTORICO '!D:E,2,FALSE),0) -> 0 | G35: =IFERROR(VLOOKUP(B35&G$12&TEXT(D35,"dd/mm/aaaa"),'HISTORICO '!D:E,2,FALSE),0) -> 0 | H35: =IFERROR(VLOOKUP(B35&H$12&TEXT(D35,"dd/mm/aaaa"),'HISTORICO '!D:E,2,FALSE),0) -> 0 | I35: =IFERROR(VLOOKUP(B35&I$12&TEXT(D35,"dd/mm/aaaa"),'HISTORICO '!D:E,2,FALSE),0) -> 0 | J35: =IFERROR(VLOOKUP(B35&J$12&TEXT(D35,"dd/mm/aaaa"),'HISTORICO '!D:E,2,FALSE),0) -> 0 | K35: =IFERROR(VLOOKUP(B35&K$12&TEXT(D35,"dd/mm/aaaa"),'HISTORICO '!D:E,2,FALSE),0) -> 0 | M35: =IFERROR(_xlfn.XLOOKUP(D35 & B35, 'HISTORICO '!G:G, 'HISTORICO '!F:F),"") | N35: =SUM(E35:L35)+IF(E35>0,E35*1,0) -> 0 | O35: =E35*$E$2+F35*$E$3+G35*$E$4+H35*$E$5+J35*$E$6+K35*$E$7+L35*$E$8 -> 0 | P35: =O35/C35 -> 0 | R35: =SUMIF($G$2:$G$8,Q35,$K$2:$K$8)*O35 -> 0 | S35: 2.5 | T35: =S35*$C35 -> 43 | U35: =0.5*T35 -> 21.5 | W35: Andropogon | X35: Boa
A36: 24 | B36: Timbó 2 | C36: 15.7 | D36: =MAX('HISTORICO '!A:A) -> 46237 | E36: =IFERROR(VLOOKUP(B36&$E$12&TEXT(D36,"dd/mm/aaaa"),'HISTORICO '!D:E,2,FALSE),0) -> 0 | F36: =IFERROR(VLOOKUP(B36&$F$12&TEXT(D36,"dd/mm/aaaa"),'HISTORICO '!D:E,2,FALSE),0) -> 0 | G36: =IFERROR(VLOOKUP(B36&G$12&TEXT(D36,"dd/mm/aaaa"),'HISTORICO '!D:E,2,FALSE),0) -> 0 | H36: =IFERROR(VLOOKUP(B36&H$12&TEXT(D36,"dd/mm/aaaa"),'HISTORICO '!D:E,2,FALSE),0) -> 0 | I36: =IFERROR(VLOOKUP(B36&I$12&TEXT(D36,"dd/mm/aaaa"),'HISTORICO '!D:E,2,FALSE),0) -> 0 | J36: =IFERROR(VLOOKUP(B36&J$12&TEXT(D36,"dd/mm/aaaa"),'HISTORICO '!D:E,2,FALSE),0) -> 0 | K36: =IFERROR(VLOOKUP(B36&K$12&TEXT(D36,"dd/mm/aaaa"),'HISTORICO '!D:E,2,FALSE),0) -> 0 | M36: =IFERROR(_xlfn.XLOOKUP(D36 & B36, 'HISTORICO '!G:G, 'HISTORICO '!F:F),"") | N36: =SUM(E36:L36)+IF(E36>0,E36*1,0) -> 0 | O36: =E36*$E$2+F36*$E$3+G36*$E$4+H36*$E$5+J36*$E$6+K36*$E$7+L36*$E$8 -> 0 | P36: =O36/C36 -> 0 | Q36: 7 | R36: =SUMIF($G$2:$G$8,Q36,$K$2:$K$8)*O36 -> 0 | S36: 2.5 | T36: =S36*$C36 -> 39.25 | U36: =0.5*T36 -> 19.625 | W36: Quicuio | X36: Média
A37: 25 | B37: Piatã | C37: 69.4 | D37: =MAX('HISTORICO '!A:A) -> 46237 | E37: =IFERROR(VLOOKUP(B37&$E$12&TEXT(D37,"dd/mm/aaaa"),'HISTORICO '!D:E,2,FALSE),0) -> 0 | F37: =IFERROR(VLOOKUP(B37&$F$12&TEXT(D37,"dd/mm/aaaa"),'HISTORICO '!D:E,2,FALSE),0) -> 115 | G37: =IFERROR(VLOOKUP(B37&G$12&TEXT(D37,"dd/mm/aaaa"),'HISTORICO '!D:E,2,FALSE),0) -> 0 | H37: =IFERROR(VLOOKUP(B37&H$12&TEXT(D37,"dd/mm/aaaa"),'HISTORICO '!D:E,2,FALSE),0) -> 0 | I37: =IFERROR(VLOOKUP(B37&I$12&TEXT(D37,"dd/mm/aaaa"),'HISTORICO '!D:E,2,FALSE),0) -> 0 | J37: =IFERROR(VLOOKUP(B37&J$12&TEXT(D37,"dd/mm/aaaa"),'HISTORICO '!D:E,2,FALSE),0) -> 0 | K37: =IFERROR(VLOOKUP(B37&K$12&TEXT(D37,"dd/mm/aaaa"),'HISTORICO '!D:E,2,FALSE),0) -> 29 | M37: =IFERROR(_xlfn.XLOOKUP(D37 & B37, 'HISTORICO '!G:G, 'HISTORICO '!F:F),"") -> Vacas prenhas | N37: =SUM(E37:L37)+IF(E37>0,E37*1,0) -> 144 | O37: =E37*$E$2+F37*$E$3+G37*$E$4+H37*$E$5+J37*$E$6+K37*$E$7+L37*$E$8 -> 166.55556 | P37: =O37/C37 -> 2.399936 | Q37: 7 | R37: =SUMIF($G$2:$G$8,Q37,$K$2:$K$8)*O37 -> 0 | S37: 2.5 | T37: =S37*$C37 -> 173.5 | U37: =0.5*T37 -> 86.75 | W37: Andropogon | X37: Boa
A38: 26 | B38: Pasto dos Ipês | C38: 55.7 | D38: =MAX('HISTORICO '!A:A) -> 46237 | E38: =IFERROR(VLOOKUP(B38&$E$12&TEXT(D38,"dd/mm/aaaa"),'HISTORICO '!D:E,2,FALSE),0) -> 0 | F38: =IFERROR(VLOOKUP(B38&$F$12&TEXT(D38,"dd/mm/aaaa"),'HISTORICO '!D:E,2,FALSE),0) -> 154 | G38: =IFERROR(VLOOKUP(B38&G$12&TEXT(D38,"dd/mm/aaaa"),'HISTORICO '!D:E,2,FALSE),0) -> 0 | H38: =IFERROR(VLOOKUP(B38&H$12&TEXT(D38,"dd/mm/aaaa"),'HISTORICO '!D:E,2,FALSE),0) -> 0 | I38: =IFERROR(VLOOKUP(B38&I$12&TEXT(D38,"dd/mm/aaaa"),'HISTORICO '!D:E,2,FALSE),0) -> 0 | J38: =IFERROR(VLOOKUP(B38&J$12&TEXT(D38,"dd/mm/aaaa"),'HISTORICO '!D:E,2,FALSE),0) -> 0 | K38: =IFERROR(VLOOKUP(B38&K$12&TEXT(D38,"dd/mm/aaaa"),'HISTORICO '!D:E,2,FALSE),0) -> 0 | M38: =IFERROR(_xlfn.XLOOKUP(D38 & B38, 'HISTORICO '!G:G, 'HISTORICO '!F:F),"") -> Vacas para abate | N38: =SUM(E38:L38)+IF(E38>0,E38*1,0) -> 154 | O38: =E38*$E$2+F38*$E$3+G38*$E$4+H38*$E$5+J38*$E$6+K38*$E$7+L38*$E$8 -> 154 | P38: =O38/C38 -> 2.7648115 | Q38: 2 | R38: =SUMIF($G$2:$G$8,Q38,$K$2:$K$8)*O38 -> 34.65 | S38: 3.5 | T38: =S38*$C38 -> 194.95 | U38: =0.5*T38 -> 97.475 | W38: Zuri | X38: Boa
A39: 27 | B39: Mangas | C39: 109 | D39: =MAX('HISTORICO '!A:A) -> 46237 | E39: =IFERROR(VLOOKUP(B39&$E$12&TEXT(D39,"dd/mm/aaaa"),'HISTORICO '!D:E,2,FALSE),0) -> 0 | F39: =IFERROR(VLOOKUP(B39&$F$12&TEXT(D39,"dd/mm/aaaa"),'HISTORICO '!D:E,2,FALSE),0) -> 157 | G39: =IFERROR(VLOOKUP(B39&G$12&TEXT(D39,"dd/mm/aaaa"),'HISTORICO '!D:E,2,FALSE),0) -> 0 | H39: =IFERROR(VLOOKUP(B39&H$12&TEXT(D39,"dd/mm/aaaa"),'HISTORICO '!D:E,2,FALSE),0) -> 0 | I39: =IFERROR(VLOOKUP(B39&I$12&TEXT(D39,"dd/mm/aaaa"),'HISTORICO '!D:E,2,FALSE),0) -> 0 | J39: =IFERROR(VLOOKUP(B39&J$12&TEXT(D39,"dd/mm/aaaa"),'HISTORICO '!D:E,2,FALSE),0) -> 0 | K39: =IFERROR(VLOOKUP(B39&K$12&TEXT(D39,"dd/mm/aaaa"),'HISTORICO '!D:E,2,FALSE),0) -> 0 | M39: =IFERROR(_xlfn.XLOOKUP(D39 & B39, 'HISTORICO '!G:G, 'HISTORICO '!F:F),"") -> Vacas prenhas | N39: =SUM(E39:L39)+IF(E39>0,E39*1,0) -> 157 | O39: =E39*$E$2+F39*$E$3+G39*$E$4+H39*$E$5+J39*$E$6+K39*$E$7+L39*$E$8 -> 157 | P39: =O39/C39 -> 1.440367 | Q39: 2 | R39: =SUMIF($G$2:$G$8,Q39,$K$2:$K$8)*O39 -> 35.325 | S39: 2 | T39: =S39*$C39 -> 218 | U39: =0.5*T39 -> 109 | W39: Andropogon | X39: Boa
A40: 28 | B40: Cemitério | C40: 137 | D40: =MAX('HISTORICO '!A:A) -> 46237 | E40: =IFERROR(VLOOKUP(B40&$E$12&TEXT(D40,"dd/mm/aaaa"),'HISTORICO '!D:E,2,FALSE),0) -> 0 | F40: =IFERROR(VLOOKUP(B40&$F$12&TEXT(D40,"dd/mm/aaaa"),'HISTORICO '!D:E,2,FALSE),0) -> 0 | G40: =IFERROR(VLOOKUP(B40&G$12&TEXT(D40,"dd/mm/aaaa"),'HISTORICO '!D:E,2,FALSE),0) -> 0 | H40: =IFERROR(VLOOKUP(B40&H$12&TEXT(D40,"dd/mm/aaaa"),'HISTORICO '!D:E,2,FALSE),0) -> 0 | I40: =IFERROR(VLOOKUP(B40&I$12&TEXT(D40,"dd/mm/aaaa"),'HISTORICO '!D:E,2,FALSE),0) -> 0 | J40: =IFERROR(VLOOKUP(B40&J$12&TEXT(D40,"dd/mm/aaaa"),'HISTORICO '!D:E,2,FALSE),0) -> 0 | K40: =IFERROR(VLOOKUP(B40&K$12&TEXT(D40,"dd/mm/aaaa"),'HISTORICO '!D:E,2,FALSE),0) -> 0 | M40: =IFERROR(_xlfn.XLOOKUP(D40 & B40, 'HISTORICO '!G:G, 'HISTORICO '!F:F),"") | N40: =SUM(E40:L40)+IF(E40>0,E40*1,0) -> 0 | O40: =E40*$E$2+F40*$E$3+G40*$E$4+H40*$E$5+J40*$E$6+K40*$E$7+L40*$E$8 -> 0 | P40: =O40/C40 -> 0 | R40: =SUMIF($G$2:$G$8,Q40,$K$2:$K$8)*O40 -> 0 | S40: 2 | T40: =S40*$C40 -> 274 | U40: =0.5*T40 -> 137 | W40: Brachiária | X40: Média
A41: 29 | B41: Avenida 1 | C41: 48.8 | D41: =MAX('HISTORICO '!A:A) -> 46237 | E41: =IFERROR(VLOOKUP(B41&$E$12&TEXT(D41,"dd/mm/aaaa"),'HISTORICO '!D:E,2,FALSE),0) -> 0 | F41: =IFERROR(VLOOKUP(B41&$F$12&TEXT(D41,"dd/mm/aaaa"),'HISTORICO '!D:E,2,FALSE),0) -> 0 | G41: =IFERROR(VLOOKUP(B41&G$12&TEXT(D41,"dd/mm/aaaa"),'HISTORICO '!D:E,2,FALSE),0) -> 0 | H41: =IFERROR(VLOOKUP(B41&H$12&TEXT(D41,"dd/mm/aaaa"),'HISTORICO '!D:E,2,FALSE),0) -> 0 | I41: =IFERROR(VLOOKUP(B41&I$12&TEXT(D41,"dd/mm/aaaa"),'HISTORICO '!D:E,2,FALSE),0) -> 0 | J41: =IFERROR(VLOOKUP(B41&J$12&TEXT(D41,"dd/mm/aaaa"),'HISTORICO '!D:E,2,FALSE),0) -> 0 | K41: =IFERROR(VLOOKUP(B41&K$12&TEXT(D41,"dd/mm/aaaa"),'HISTORICO '!D:E,2,FALSE),0) -> 0 | M41: =IFERROR(_xlfn.XLOOKUP(D41 & B41, 'HISTORICO '!G:G, 'HISTORICO '!F:F),"") | N41: =SUM(E41:L41)+IF(E41>0,E41*1,0) -> 0 | O41: =E41*$E$2+F41*$E$3+G41*$E$4+H41*$E$5+J41*$E$6+K41*$E$7+L41*$E$8 -> 0 | P41: =O41/C41 -> 0 | R41: =SUMIF($G$2:$G$8,Q41,$K$2:$K$8)*O41 -> 0 | S41: 2 | T41: =S41*$C41 -> 97.6 | U41: =0.5*T41 -> 48.8 | W41: Andropogon | X41: Média
A42: 30 | B42: Avenida 2 | C42: 89 | D42: =MAX('HISTORICO '!A:A) -> 46237 | E42: =IFERROR(VLOOKUP(B42&$E$12&TEXT(D42,"dd/mm/aaaa"),'HISTORICO '!D:E,2,FALSE),0) -> 0 | F42: =IFERROR(VLOOKUP(B42&$F$12&TEXT(D42,"dd/mm/aaaa"),'HISTORICO '!D:E,2,FALSE),0) -> 0 | G42: =IFERROR(VLOOKUP(B42&G$12&TEXT(D42,"dd/mm/aaaa"),'HISTORICO '!D:E,2,FALSE),0) -> 51 | H42: =IFERROR(VLOOKUP(B42&H$12&TEXT(D42,"dd/mm/aaaa"),'HISTORICO '!D:E,2,FALSE),0) -> 0 | I42: =IFERROR(VLOOKUP(B42&I$12&TEXT(D42,"dd/mm/aaaa"),'HISTORICO '!D:E,2,FALSE),0) -> 0 | J42: =IFERROR(VLOOKUP(B42&J$12&TEXT(D42,"dd/mm/aaaa"),'HISTORICO '!D:E,2,FALSE),0) -> 0 | K42: =IFERROR(VLOOKUP(B42&K$12&TEXT(D42,"dd/mm/aaaa"),'HISTORICO '!D:E,2,FALSE),0) -> 0 | M42: =IFERROR(_xlfn.XLOOKUP(D42 & B42, 'HISTORICO '!G:G, 'HISTORICO '!F:F),"") -> 0 | N42: =SUM(E42:L42)+IF(E42>0,E42*1,0) -> 51 | O42: =E42*$E$2+F42*$E$3+G42*$E$4+H42*$E$5+J42*$E$6+K42*$E$7+L42*$E$8 -> 38.533333 | P42: =O42/C42 -> 0.4329588 | R42: =SUMIF($G$2:$G$8,Q42,$K$2:$K$8)*O42 -> 0 | S42: 2.5 | T42: =S42*$C42 -> 222.5 | U42: =0.5*T42 -> 111.25 | W42: Andropogon | X42: Boa
A43: 31 | B43: Piquete Curral do Retiro | C43: 17.2 | D43: =MAX('HISTORICO '!A:A) -> 46237 | E43: =IFERROR(VLOOKUP(B43&$E$12&TEXT(D43,"dd/mm/aaaa"),'HISTORICO '!D:E,2,FALSE),0) -> 0 | F43: =IFERROR(VLOOKUP(B43&$F$12&TEXT(D43,"dd/mm/aaaa"),'HISTORICO '!D:E,2,FALSE),0) -> 0 | G43: =IFERROR(VLOOKUP(B43&G$12&TEXT(D43,"dd/mm/aaaa"),'HISTORICO '!D:E,2,FALSE),0) -> 0 | H43: =IFERROR(VLOOKUP(B43&H$12&TEXT(D43,"dd/mm/aaaa"),'HISTORICO '!D:E,2,FALSE),0) -> 0 | I43: =IFERROR(VLOOKUP(B43&I$12&TEXT(D43,"dd/mm/aaaa"),'HISTORICO '!D:E,2,FALSE),0) -> 0 | J43: =IFERROR(VLOOKUP(B43&J$12&TEXT(D43,"dd/mm/aaaa"),'HISTORICO '!D:E,2,FALSE),0) -> 0 | K43: =IFERROR(VLOOKUP(B43&K$12&TEXT(D43,"dd/mm/aaaa"),'HISTORICO '!D:E,2,FALSE),0) -> 0 | M43: =IFERROR(_xlfn.XLOOKUP(D43 & B43, 'HISTORICO '!G:G, 'HISTORICO '!F:F),"") | N43: =SUM(E43:L43)+IF(E43>0,E43*1,0) -> 0 | O43: =E43*$E$2+F43*$E$3+G43*$E$4+H43*$E$5+J43*$E$6+K43*$E$7+L43*$E$8 -> 0 | P43: =O43/C43 -> 0 | R43: =SUMIF($G$2:$G$8,Q43,$K$2:$K$8)*O43 -> 0 | S43: 2.5 | T43: =S43*$C43 -> 43 | U43: =0.5*T43 -> 21.5 | W43: Andropogon | X43: Boa
...

Sheet HISTORICO 
A1: Data | B1: Pasto | C1: Categoria Animal | D1: Chave | E1: Quantidade | F1: OBS | G1: Chave OBS
A2: 45845 | B2: Rotacionado Entrada | C2: Vaca Parida | D2: =B2&C2&TEXT(A2,"dd/mm/aaaa") -> Rotacionado EntradaVaca Parida07/07/2025 | E2: 185 | G2: =A2&B2 -> 45845Rotacionado Entrada
A3: 45845 | B3: Rotacionado Entrada | C3: Bez. Desm | D3: =B3&C3&TEXT(A3,"dd/mm/aaaa") -> Rotacionado EntradaBez. Desm07/07/2025 | E3: 191 | G3: =A3&B3 -> 45845Rotacionado Entrada
A4: 45845 | B4: Rotacionado Entrada | C4: Touro | D4: =B4&C4&TEXT(A4,"dd/mm/aaaa") -> Rotacionado EntradaTouro07/07/2025 | E4: 15 | G4: =A4&B4 -> 45845Rotacionado Entrada
A5: 45845 | B5: Rotacionado Caixa d'Água | C5: Vaca Parida | D5: =B5&C5&TEXT(A5,"dd/mm/aaaa") -> Rotacionado Caixa d'ÁguaVaca Parida07/07/2025 | E5: 7 | G5: =A5&B5 -> 45845Rotacionado Caixa d'Água
A6: 45845 | B6: Rotacionado Caixa d'Água | C6: Vaca | D6: =B6&C6&TEXT(A6,"dd/mm/aaaa") -> Rotacionado Caixa d'ÁguaVaca07/07/2025 | E6: 4 | G6: =A6&B6 -> 45845Rotacionado Caixa d'Água
A7: 45845 | B7: Rotacionado Caixa d'Água | C7: Novilha | D7: =B7&C7&TEXT(A7,"dd/mm/aaaa") -> Rotacionado Caixa d'ÁguaNovilha07/07/2025 | E7: 3 | G7: =A7&B7 -> 45845Rotacionado Caixa d'Água
A8: 45845 | B8: Rotacionado Caixa d'Água | C8: Touro | D8: =B8&C8&TEXT(A8,"dd/mm/aaaa") -> Rotacionado Caixa d'ÁguaTouro07/07/2025 | E8: 11 | G8: =A8&B8 -> 45845Rotacionado Caixa d'Água
A9: 45845 | B9: Barriguda 2 | C9: Bez. Desm | D9: =B9&C9&TEXT(A9,"dd/mm/aaaa") -> Barriguda 2Bez. Desm07/07/2025 | E9: 185 | G9: =A9&B9 -> 45845Barriguda 2
A10: 45845 | B10: Barriguda 2 | C10: Vaca | D10: =B10&C10&TEXT(A10,"dd/mm/aaaa") -> Barriguda 2Vaca07/07/2025 | E10: 6 | G10: =A10&B10 -> 45845Barriguda 2
A11: 45845 | B11: Piquetes da Mata | C11: Novilha | D11: =B11&C11&TEXT(A11,"dd/mm/aaaa") -> Piquetes da MataNovilha07/07/2025 | E11: 25 | G11: =A11&B11 -> 45845Piquetes da Mata
A12: 45845 | B12: Piquetes da Mata | C12: Vaca | D12: =B12&C12&TEXT(A12,"dd/mm/aaaa") -> Piquetes da MataVaca07/07/2025 | E12: 30 | G12: =A12&B12 -> 45845Piquetes da Mata
A13: 45845 | B13: Piquetes da Mata | C13: Boi capão | D13: =B13&C13&TEXT(A13,"dd/mm/aaaa") -> Piquetes da MataBoi capão 07/07/2025 | E13: 1 | G13: =A13&B13 -> 45845Piquetes da Mata
... A41: 45852 | B41: Mangas | C41: Vaca | D41: =B41&C41&TEXT(A41,"dd/mm/aaaa") -> MangasVaca14/07/2025 | E41: 4 | G41: =A41&B41 -> 45852Mangas
A42: 45852 | B42: Boqueirão | C42: Vaca | D42: =B42&C42&TEXT(A43,"dd/mm/aaaa") -> BoqueirãoVaca14/07/2025 | E42: 71 | G42: =A42&B42 -> 45852Boqueirão
A43: 45852 | B43: Reserva Boqueirão | C43: Vaca | D43: =B43&C43&TEXT(A44,"dd/mm/aaaa") -> Reserva Boqueirão Vaca14/07/2025 | E43: 284 | G43: =A43&B43 -> 45852Reserva Boqueirão
A44: 45852 | B44: Caixa D'água Retiro | C44: Novilha | D44: =B44&C44&TEXT(A45,"dd/mm/aaaa") -> Caixa D'água RetiroNovilha21/07/2025 | E44: 366 | G44: =A44&B44 -> 45852Caixa D'água Retiro
A45: 45859 | B45: Rotacionado Entrada | C45: Vaca Parida | D45: =B45&C45&TEXT(A47,"dd/mm/aaaa") -> Rotacionado EntradaVaca Parida21/07/2025 | E45: 189 | G45: =A45&B45 -> 45859Rotacionado Entrada
A46: 45859 | B46: Rotacionado Entrada | C46: Vaca | D46: =B46&C46&TEXT(A48,"dd/mm/aaaa") -> Rotacionado EntradaVaca21/07/2025 | E46: 15 | G46: =A46&B46 -> 45859Rotacionado Entrada
A47: 45859 | B47: Rotacionado Entrada | C47: Touro | D47: =B47&C47&TEXT(A48,"dd/mm/aaaa") -> Rotacionado EntradaTouro21/07/2025 | E47: 35 | G47: =A47&B47 -> 45859Rotacionado Entrada
A48: 45859 | B48: Matinha | C48: Vaca | D48: =B48&C48&TEXT(A50,"dd/mm/aaaa") -> MatinhaVaca21/07/2025 | E48: 2 | G48: =A48&B48 -> 45859Matinha
A49: 45859 | B49: Matinha | C49: Vaca Parida | D49: =B49&C49&TEXT(A51,"dd/mm/aaaa") -> MatinhaVaca Parida21/07/2025 | E49: 2 | G49: =A49&B49 -> 45859Matinha
A50: 45859 | B50: Matinha | C50: Novilha | D50: =B50&C50&TEXT(A51,"dd/mm/aaaa") -> MatinhaNovilha21/07/2025 | E50: 1 | G50: =A50&B50 -> 45859Matinha
A51: 45859 | B51: Vila 2 | C51: Tropa | D51: =B51&C51&TEXT(A52,"dd/mm/aaaa") -> Vila 2Tropa21/07/2025 | E51: 6 | G51: =A51&B51 -> 45859Vila 2
A52: 45859 | B52: Rotacionado Caixa d'Água | C52: Vaca Parida | D52: =B52&C52&TEXT(A53,"dd/mm/aaaa") -> Rotacionado Caixa d'ÁguaVaca Parida21/07/2025 | E52: 4 | G52: =A52&B52 -> 45859Rotacionado Caixa d'Água
A53: 45859 | B53: Rotacionado Caixa d'Água | C53: Vaca | D53: =B53&C53&TEXT(A54,"dd/mm/aaaa") -> Rotacionado Caixa d'ÁguaVaca21/07/2025 | E53: 1 | G53: =A53&B53 -> 45859Rotacionado Caixa d'Água
A54: 45859 | B54: Rotacionado Caixa d'Água | C54: Touro | D54: =B54&C54&TEXT(A55,"dd/mm/aaaa") -> Rotacionado Caixa d'ÁguaTouro21/07/2025 | E54: 4 | G54: =A54&B54 -> 45859Rotacionado Caixa d'Água
A55: 45859 | B55: Barriguda 1 | C55: Bez. Desm | D55: =B55&C55&TEXT(A56,"dd/mm/aaaa") -> Barriguda 1Bez. Desm21/07/2025 | E55: 173 | G55: =A55&B55 -> 45859Barriguda 1
A56: 45859 | B56: Barriguda 1 | C56: Novilha | D56: =B56&C56&TEXT(A57,"dd/mm/aaaa") -> Barriguda 1Novilha21/07/2025 | E56: 2 | G56: =A56&B56 -> 45859Barriguda 1
A57: 45859 | B57: Piatã | C57: Tropa | D57: =B57&C57&TEXT(A58,"dd/mm/aaaa") -> PiatãTropa21/07/2025 | E57: 2 | G57: =A57&B57 -> 45859Piatã
A58: 45859 | B58: Pasto dos Ipês | C58: Novilha | D58: =B58&C58&TEXT(A59,"dd/mm/aaaa") -> Pasto dos IpêsNovilha21/07/2025 | E58: 6 | G58: =A58&B58 -> 45859Pasto dos Ipês
A59: 45859 | B59: Rotacionado Cipó Preto | C59: Novilha | D59: =B59&C59&TEXT(A60,"dd/mm/aaaa") -> Rotacionado Cipó PretoNovilha21/07/2025 | E59: 314 | G59: =A59&B59 -> 45859Rotacionado Cipó Preto
A60: 45859 | B60: Rotacionado Cipó Preto | C60: Vaca | D60: =B60&C60&TEXT(A61,"dd/mm/aaaa") -> Rotacionado Cipó PretoVaca21/07/2025 | E60: 1 | G60: =A60&B60 -> 45859Rotacionado Cipó Preto
A61: 45859 | B61: Caixa D'água Retiro | C61: Vaca | D61: =B61&C61&TEXT(A62,"dd/mm/aaaa") -> Caixa D'água RetiroVaca21/07/2025 | E61: 134 | G61: =A61&B61 -> 45859Caixa D'água Retiro
... A84: 45873 | B84: Confinamento | C84: Vaca | D84: =B84&C84&TEXT(A85,"dd/mm/aaaa") -> Confinamento Vaca04/08/2025 | E84: 129 | G84: =A84&B84 -> 45873Confinamento
A85: 45873 | B85: Confinamento | C85: Touro | D85: =B85&C85&TEXT(A85,"dd/mm/aaaa") -> Confinamento Touro04/08/2025 | E85: 3 | G85: =A85&B85 -> 45873Confinamento
A86: 45915 | B86: Rotacionado Entrada | C86: Vaca | D86: =B86&C86&TEXT(A86,"dd/mm/aaaa") -> Rotacionado EntradaVaca15/09/2025 | E86: 235 | G86: =A86&B86 -> 45915Rotacionado Entrada
A87: 45915 | B87: Rotacionado Entrada | C87: Bez(O/A) | D87: =B87&C87&TEXT(A87,"dd/mm/aaaa") -> Rotacionado EntradaBez(O/A)15/09/2025 | E87: 49 | G87: =A87&B87 -> 45915Rotacionado Entrada
A88: 45915 | B88: Confinamento | C88: Touro | D88: =B88&C88&TEXT(A88,"dd/mm/aaaa") -> Confinamento Touro15/09/2025 | E88: 38 | G88: =A88&B88 -> 45915Confinamento
A89: 45915 | B89: Confinamento | C89: Novilha | D89: =B89&C89&TEXT(A89,"dd/mm/aaaa") -> Confinamento Novilha15/09/2025 | E89: 90 | G89: =A89&B89 -> 45915Confinamento
...

Sheet Movimentações
A1: Origem | B1: Destino | C1: Categoria | D1: Quantidade | E1: Idade
A2: Pau D'arco | B2: Aurora | C2: novilhas | D2: 300 | E2: 19-36
A3: Aurora | B3: Pau D'arco | C3: novilhas p+ | D3: 170 | E3: 19-36
A4: Aurora | B4: Pau D'arco | C4: novilhas vz | D4: 16
A5: Aurora | B5: Pau D'arco | C5: novilhas morte | D5: -1
A6: Aurora | B6: Pau D'arco | C6: bezerros | D6: 4
A7: Pau D'arco | B7: Boi Brasil | C7: vacas e novilhas | D7: 60
A8: Pau D'arco | B8: Boi Brasil | C8: vacas e novilhas | D8: 100
A9: Tesla | B9: Pau D'arco | C9: novilhas p+ | D9: 11
A10: Tesla | B10: Pau D'arco | C10: novilhas vz | D10: 16
A11: Tesla | B11: Pau D'arco | C11: vacas paridas | D11: 22
A12: Tesla | B12: Pau D'arco | C12: bezerros | D12: 22
A13: Tesla | B13: Pau D'arco | C13: morte bezerro | D13: -1
A14: Pau D'arco | B14: Chuva de manga | C14: novilhas vz | D14: 350

Sheet Estoque verificação
C1: Categoria Animal | D1: Peso Est. | E1: uAs | G1: # | H1: Suplemento | J1: Gramas/100kg | K1: KG/uA | L1: KG/Dia | O1: KG/Mês
C2: Vaca Parida | D2: 600 | E2: =D2/450 -> 1.3333333 | G2: 1 | H2: Sal Águas | J2: 30 | K2: =J2*4.5/1000 -> 0.135 | L2: =SUMIF($Q$13:$Q$45,G2,$R$13:$R$45) -> 0 | O2: =30*L2 -> 0
C3: Vaca | D3: 450 | E3: =D3/450 -> 1 | G3: 2 | H3: Sal Transição | J3: 50 | K3: =J3*4.5/1000 -> 0.225 | L3: =SUMIF($Q$13:$Q$45,G3,$R$13:$R$45) -> 129.525 | O3: =30*L3 -> 3885.75
C4: Novilha | D4: 340 | E4: =D4/450 -> 0.75555556 | G4: 3 | H4: Sal Seca | J4: 60 | K4: =J4*4.5/1000 -> 0.27 | L4: =SUMIF($Q$13:$Q$45,G4,$R$13:$R$45) -> 0 | O4: =30*L4 -> 0
C5: Novilhota | D5: 250 | E5: =D5/450 -> 0.55555556 | G5: 4 | H5: Protéico 0.1% | J5: 100 | K5: =J5*4.5/1000 -> 0.45 | L5: =SUMIF($Q$13:$Q$45,G5,$R$13:$R$45) -> 136.57 | O5: =30*L5 -> 4097.1
C6: Bezerro Desm | D6: 225 | E6: =D6/450 -> 0.5 | G6: 5 | H6: Protéico 0.3% | J6: 300 | K6: =J6*4.5/1000 -> 1.35 | L6: =SUMIF($Q$13:$Q$45,G6,$R$13:$R$45) -> 121.5 | O6: =30*L6 -> 3645
C7: Touro | D7: 800 | E7: =D7/450 -> 1.7777778 | G7: 6 | H7: Ração | J7: 1000 | K7: =J7*4.5/1000 -> 4.5 | L7: =SUMIF($Q$13:$Q$45,G7,$R$13:$R$45) -> 0 | O7: =30*L7 -> 0
C8: Tropa | D8: 675 | E8: =D8/450 -> 1.5 | G8: 7 | H8: Ração Tropa | J8: 0 | K8: =J8*4.5/1000 -> 0 | L8: =SUMIF($Q$13:$Q$45,G8,$R$13:$R$45) -> 0 | O8: =30*L8 -> 0
C10: DATA VERIFICAÇÃO | D10: 46181
B12: Pasto | C12: Hectares | D12: Data | E12: Vaca Parida | F12: Vaca | G12: Novilha | H12: Novilhota | I12: Garrote | J12: Bez(O/A) | K12: Touro | L12: Tropa | M12: OBS | N12: Total Cabeças | O12: Total uAs | P12: uA/Ha real | Q12: Suplemento | R12: Kg/Dia | S12: uA/Hectare | T12: uAs [Águas] | U12: uAs [Seca] | V12: Corte 0-10 | W12: Capim | X12: Forma | Y12: Estado
A13: 1 | B13: Rotacionado Entrada | C13: 89.9 | D13: =$D$10 -> 46181 | E13: =IFERROR(VLOOKUP(B13&$E$12&TEXT(D13,"dd/mm/aaaa"),'HISTORICO '!D:E,2,FALSE),0) -> 104 | F13: =IFERROR(VLOOKUP(B13&$F$12&TEXT(D13,"dd/mm/aaaa"),'HISTORICO '!D:E,2,FALSE),0) -> 23 | G13: =IFERROR(VLOOKUP(B13&G$12&TEXT(D13,"dd/mm/aaaa"),'HISTORICO '!D:E,2,FALSE),0) -> 0 | H13: =IFERROR(VLOOKUP(B13&H$12&TEXT(D13,"dd/mm/aaaa"),'HISTORICO '!D:E,2,FALSE),0) -> 0 | I13: =IFERROR(VLOOKUP(B13&I$12&TEXT(D13,"dd/mm/aaaa"),'HISTORICO '!D:E,2,FALSE),0) -> 0 | J13: =IFERROR(VLOOKUP(B13&J$12&TEXT(D13,"dd/mm/aaaa"),'HISTORICO '!D:E,2,FALSE),0) -> 0 | K13: =IFERROR(VLOOKUP(B13&K$12&TEXT(D13,"dd/mm/aaaa"),'HISTORICO '!D:E,2,FALSE),0) -> 0 | M13: =IFERROR(_xlfn.XLOOKUP(D13 & B13, 'HISTORICO '!G:G, 'HISTORICO '!F:F),"") -> 0 | N13: =SUM(E13:L13)+IF(E13>0,E13*1,0) -> 231 | O13: =E13*$E$2+F13*$E$3+G13*$E$4+H13*$E$5+J13*$E$6+K13*$E$7+L13*$E$8 -> 161.66667 | P13: =O13/C13 -> 1.7982944 | Q13: 2 | R13: =SUMIF($G$2:$G$8,Q13,$K$2:$K$8)*O13 -> 36.375 | S13: 2 | T13: =S13*$C13 -> 179.8 | U13: =0.5*T13 -> 89.9 | V13: 5 | W13: Massai | X13: Boa
A14: 2 | B14: Cedro 1 | C14: 18 | D14: =$D$10 -> 46181 | E14: =IFERROR(VLOOKUP(B14&$E$12&TEXT(D14,"dd/mm/aaaa"),'HISTORICO '!D:E,2,FALSE),0) -> 0 | F14: =IFERROR(VLOOKUP(B14&$F$12&TEXT(D14,"dd/mm/aaaa"),'HISTORICO '!D:E,2,FALSE),0) -> 0 | G14: =IFERROR(VLOOKUP(B14&G$12&TEXT(D14,"dd/mm/aaaa"),'HISTORICO '!D:E,2,FALSE),0) -> 0 | H14: =IFERROR(VLOOKUP(B14&H$12&TEXT(D14,"dd/mm/aaaa"),'HISTORICO '!D:E,2,FALSE),0) -> 0 | I14: =IFERROR(VLOOKUP(B14&I$12&TEXT(D14,"dd/mm/aaaa"),'HISTORICO '!D:E,2,FALSE),0) -> 0 | J14: =IFERROR(VLOOKUP(B14&J$12&TEXT(D14,"dd/mm/aaaa"),'HISTORICO '!D:E,2,FALSE),0) -> 0 | K14: =IFERROR(VLOOKUP(B14&K$12&TEXT(D14,"dd/mm/aaaa"),'HISTORICO '!D:E,2,FALSE),0) -> 0 | M14: =IFERROR(_xlfn.XLOOKUP(D14 & B14, 'HISTORICO '!G:G, 'HISTORICO '!F:F),"") | N14: =SUM(E14:L14)+IF(E14>0,E14*1,0) -> 0 | O14: =E14*$E$2+F14*$E$3+G14*$E$4+H14*$E$5+J14*$E$6+K14*$E$7+L14*$E$8 -> 0 | P14: =O14/C14 -> 0 | R14: =SUMIF($G$2:$G$8,Q14,$K$2:$K$8)*O14 -> 0 | S14: 0 | T14: =S14*$C14 -> 0 | U14: =0.5*T14 -> 0 | V14: 0 | W14: Massai | X14: Ruim
A15: 3 | B15: Cedro 2 | C15: 51.7 | D15: =$D$10 -> 46181 | E15: =IFERROR(VLOOKUP(B15&$E$12&TEXT(D15,"dd/mm/aaaa"),'HISTORICO '!D:E,2,FALSE),0) -> 0 | F15: =IFERROR(VLOOKUP(B15&$F$12&TEXT(D15,"dd/mm/aaaa"),'HISTORICO '!D:E,2,FALSE),0) -> 0 | G15: =IFERROR(VLOOKUP(B15&G$12&TEXT(D15,"dd/mm/aaaa"),'HISTORICO '!D:E,2,FALSE),0) -> 0 | H15: =IFERROR(VLOOKUP(B15&H$12&TEXT(D15,"dd/mm/aaaa"),'HISTORICO '!D:E,2,FALSE),0) -> 0 | I15: =IFERROR(VLOOKUP(B15&I$12&TEXT(D15,"dd/mm/aaaa"),'HISTORICO '!D:E,2,FALSE),0) -> 0 | J15: =IFERROR(VLOOKUP(B15&J$12&TEXT(D15,"dd/mm/aaaa"),'HISTORICO '!D:E,2,FALSE),0) -> 0 | K15: =IFERROR(VLOOKUP(B15&K$12&TEXT(D15,"dd/mm/aaaa"),'HISTORICO '!D:E,2,FALSE),0) -> 0 | M15: =IFERROR(_xlfn.XLOOKUP(D15 & B15, 'HISTORICO '!G:G, 'HISTORICO '!F:F),"") | N15: =SUM(E15:L15)+IF(E15>0,E15*1,0) -> 0 | O15: =E15*$E$2+F15*$E$3+G15*$E$4+H15*$E$5+J15*$E$6+K15*$E$7+L15*$E$8 -> 0 | P15: =O15/C15 -> 0 | R15: =SUMIF($G$2:$G$8,Q15,$K$2:$K$8)*O15 -> 0 | S15: 1 | T15: =S15*$C15 -> 51.7 | U15: =0.5*T15 -> 25.85 | V15: 4 | W15: Braquiária | X15: Ruim
A16: 4 | B16: Matinha | C16: 4.69 | D16: =$D$10 -> 46181 | E16: =IFERROR(VLOOKUP(B16&$E$12&TEXT(D16,"dd/mm/aaaa"),'HISTORICO '!D:E,2,FALSE),0) -> 0 | F16: =IFERROR(VLOOKUP(B16&$F$12&TEXT(D16,"dd/mm/aaaa"),'HISTORICO '!D:E,2,FALSE),0) -> 0 | G16: =IFERROR(VLOOKUP(B16&G$12&TEXT(D16,"dd/mm/aaaa"),'HISTORICO '!D:E,2,FALSE),0) -> 0 | H16: =IFERROR(VLOOKUP(B16&H$12&TEXT(D16,"dd/mm/aaaa"),'HISTORICO '!D:E,2,FALSE),0) -> 0 | I16: =IFERROR(VLOOKUP(B16&I$12&TEXT(D16,"dd/mm/aaaa"),'HISTORICO '!D:E,2,FALSE),0) -> 36 | J16: =IFERROR(VLOOKUP(B16&J$12&TEXT(D16,"dd/mm/aaaa"),'HISTORICO '!D:E,2,FALSE),0) -> 0 | K16: =IFERROR(VLOOKUP(B16&K$12&TEXT(D16,"dd/mm/aaaa"),'HISTORICO '!D:E,2,FALSE),0) -> 0 | M16: =IFERROR(_xlfn.XLOOKUP(D16 & B16, 'HISTORICO '!G:G, 'HISTORICO '!F:F),"") -> 0 | N16: =SUM(E16:L16)+IF(E16>0,E16*1,0) -> 36 | O16: =E16*$E$2+F16*$E$3+G16*$E$4+H16*$E$5+J16*$E$6+K16*$E$7+L16*$E$8 -> 0 | P16: =O16/C16 -> 0 | Q16: 2 | R16: =SUMIF($G$2:$G$8,Q16,$K$2:$K$8)*O16 -> 0 | S16: 2 | T16: =S16*$C16 -> 9.38 | U16: =0.5*T16 -> 4.69 | W16: Tamani | X16: Boa
A17: 5 | B17: PQT Garanhão | C17: 0.76 | D17: =$D$10 -> 46181 | E17: =IFERROR(VLOOKUP(B17&$E$12&TEXT(D17,"dd/mm/aaaa"),'HISTORICO '!D:E,2,FALSE),0) -> 0 | F17: =IFERROR(VLOOKUP(B17&$F$12&TEXT(D17,"dd/mm/aaaa"),'HISTORICO '!D:E,2,FALSE),0) -> 0 | G17: =IFERROR(VLOOKUP(B17&G$12&TEXT(D17,"dd/mm/aaaa"),'HISTORICO '!D:E,2,FALSE),0) -> 0 | H17: =IFERROR(VLOOKUP(B17&H$12&TEXT(D17,"dd/mm/aaaa"),'HISTORICO '!D:E,2,FALSE),0) -> 0 | I17: =IFERROR(VLOOKUP(B17&I$12&TEXT(D17,"dd/mm/aaaa"),'HISTORICO '!D:E,2,FALSE),0) -> 0 | J17: =IFERROR(VLOOKUP(B17&J$12&TEXT(D17,"dd/mm/aaaa"),'HISTORICO '!D:E,2,FALSE),0) -> 0 | K17: =IFERROR(VLOOKUP(B17&K$12&TEXT(D17,"dd/mm/aaaa"),'HISTORICO '!D:E,2,FALSE),0) -> 0 | M17: =IFERROR(_xlfn.XLOOKUP(D17 & B17, 'HISTORICO '!G:G, 'HISTORICO '!F:F),"") | N17: =SUM(E17:L17)+IF(E17>0,E17*1,0) -> 0 | O17: =E17*$E$2+F17*$E$3+G17*$E$4+H17*$E$5+J17*$E$6+K17*$E$7+L17*$E$8 -> 0 | P17: =O17/C17 -> 0 | R17: =SUMIF($G$2:$G$8,Q17,$K$2:$K$8)*O17 -> 0 | S17: 1 | T17: =S17*$C17 -> 0.76 | U17: =0.5*T17 -> 0.38 | W17: Tamani | X17: Boa
A18: 6 | B18: Vila 1 | C18: 7 | D18: =$D$10 -> 46181 | E18: =IFERROR(VLOOKUP(B18&$E$12&TEXT(D18,"dd/mm/aaaa"),'HISTORICO '!D:E,2,FALSE),0) -> 0 | F18: =IFERROR(VLOOKUP(B18&$F$12&TEXT(D18,"dd/mm/aaaa"),'HISTORICO '!D:E,2,FALSE),0) -> 0 | G18: =IFERROR(VLOOKUP(B18&G$12&TEXT(D18,"dd/mm/aaaa"),'HISTORICO '!D:E,2,FALSE),0) -> 0 | H18: =IFERROR(VLOOKUP(B18&H$12&TEXT(D18,"dd/mm/aaaa"),'HISTORICO '!D:E,2,FALSE),0) -> 0 | I18: =IFERROR(VLOOKUP(B18&I$12&TEXT(D18,"dd/mm/aaaa"),'HISTORICO '!D:E,2,FALSE),0) -> 0 | J18: =IFERROR(VLOOKUP(B18&J$12&TEXT(D18,"dd/mm/aaaa"),'HISTORICO '!D:E,2,FALSE),0) -> 0 | K18: =IFERROR(VLOOKUP(B18&K$12&TEXT(D18,"dd/mm/aaaa"),'HISTORICO '!D:E,2,FALSE),0) -> 0 | M18: =IFERROR(_xlfn.XLOOKUP(D18 & B18, 'HISTORICO '!G:G, 'HISTORICO '!F:F),"") | N18: =SUM(E18:L18)+IF(E18>0,E18*1,0) -> 0 | O18: =E18*$E$2+F18*$E$3+G18*$E$4+H18*$E$5+J18*$E$6+K18*$E$7+L18*$E$8 -> 0 | P18: =O18/C18 -> 0 | R18: =SUMIF($G$2:$G$8,Q18,$K$2:$K$8)*O18 -> 0 | S18: 1.5 | T18: =S18*$C18 -> 10.5 | U18: =0.5*T18 -> 5.25 | W18: Tamani | X18: Média
A19: 7 | B19: Vila 2 | C19: 12.9 | D19: =$D$10 -> 46181 | E19: =IFERROR(VLOOKUP(B19&$E$12&TEXT(D19,"dd/mm/aaaa"),'HISTORICO '!D:E,2,FALSE),0) -> 0 | F19: =IFERROR(VLOOKUP(B19&$F$12&TEXT(D19,"dd/mm/aaaa"),'HISTORICO '!D:E,2,FALSE),0) -> 0 | G19: =IFERROR(VLOOKUP(B19&G$12&TEXT(D19,"dd/mm/aaaa"),'HISTORICO '!D:E,2,FALSE),0) -> 0 | H19: =IFERROR(VLOOKUP(B19&H$12&TEXT(D19,"dd/mm/aaaa"),'HISTORICO '!D:E,2,FALSE),0) -> 0 | I19: =IFERROR(VLOOKUP(B19&I$12&TEXT(D19,"dd/mm/aaaa"),'HISTORICO '!D:E,2,FALSE),0) -> 0 | J19: =IFERROR(VLOOKUP(B19&J$12&TEXT(D19,"dd/mm/aaaa"),'HISTORICO '!D:E,2,FALSE),0) -> 119 | K19: =IFERROR(VLOOKUP(B19&K$12&TEXT(D19,"dd/mm/aaaa"),'HISTORICO '!D:E,2,FALSE),0) -> 0 | M19: =IFERROR(_xlfn.XLOOKUP(D19 & B19, 'HISTORICO '!G:G, 'HISTORICO '!F:F),"") -> Bezerros desmama | N19: =SUM(E19:L19)+IF(E19>0,E19*1,0) -> 119 | O19: =E19*$E$2+F19*$E$3+G19*$E$4+H19*$E$5+J19*$E$6+K19*$E$7+L19*$E$8 -> 59.5 | P19: =O19/C19 -> 4.6124031 | R19: =SUMIF($G$2:$G$8,Q19,$K$2:$K$8)*O19 -> 0 | S19: 1.5 | T19: =S19*$C19 -> 19.35 | U19: =0.5*T19 -> 9.675 | W19: Tamani | X19: Média
A20: 8 | B20: Rotacionado Vila 1 | C20: 8.07 | D20: =$D$10 -> 46181 | E20: =IFERROR(VLOOKUP(B20&$E$12&TEXT(D20,"dd/mm/aaaa"),'HISTORICO '!D:E,2,FALSE),0) -> 0 | F20: =IFERROR(VLOOKUP(B20&$F$12&TEXT(D20,"dd/mm/aaaa"),'HISTORICO '!D:E,2,FALSE),0) -> 0 | G20: =IFERROR(VLOOKUP(B20&G$12&TEXT(D20,"dd/mm/aaaa"),'HISTORICO '!D:E,2,FALSE),0) -> 0 | H20: =IFERROR(VLOOKUP(B20&H$12&TEXT(D20,"dd/mm/aaaa"),'HISTORICO '!D:E,2,FALSE),0) -> 0 | I20: =IFERROR(VLOOKUP(B20&I$12&TEXT(D20,"dd/mm/aaaa"),'HISTORICO '!D:E,2,FALSE),0) -> 0 | J20: =IFERROR(VLOOKUP(B20&J$12&TEXT(D20,"dd/mm/aaaa"),'HISTORICO '!D:E,2,FALSE),0) -> 0 | K20: =IFERROR(VLOOKUP(B20&K$12&TEXT(D20,"dd/mm/aaaa"),'HISTORICO '!D:E,2,FALSE),0) -> 0 | M20: =IFERROR(_xlfn.XLOOKUP(D20 & B20, 'HISTORICO '!G:G, 'HISTORICO '!F:F),"") | N20: =SUM(E20:L20)+IF(E20>0,E20*1,0) -> 0 | O20: =E20*$E$2+F20*$E$3+G20*$E$4+H20*$E$5+J20*$E$6+K20*$E$7+L20*$E$8 -> 0 | P20: =O20/C20 -> 0 | Q20: 4 | R20: =SUMIF($G$2:$G$8,Q20,$K$2:$K$8)*O20 -> 0 | S20: 2.5 | T20: =S20*$C20 -> 20.175 | U20: =0.5*T20 -> 10.0875 | W20: Braquiária | X20: Média
A21: 9 | B21: Piquete da Tropa | C21: 4.31 | D21: =$D$10 -> 46181 | E21: =IFERROR(VLOOKUP(B21&$E$12&TEXT(D21,"dd/mm/aaaa"),'HISTORICO '!D:E,2,FALSE),0) -> 0 | F21: =IFERROR(VLOOKUP(B21&$F$12&TEXT(D21,"dd/mm/aaaa"),'HISTORICO '!D:E,2,FALSE),0) -> 0 | G21: =IFERROR(VLOOKUP(B21&G$12&TEXT(D21,"dd/mm/aaaa"),'HISTORICO '!D:E,2,FALSE),0) -> 0 | H21: =IFERROR(VLOOKUP(B21&H$12&TEXT(D21,"dd/mm/aaaa"),'HISTORICO '!D:E,2,FALSE),0) -> 0 | I21: =IFERROR(VLOOKUP(B21&I$12&TEXT(D21,"dd/mm/aaaa"),'HISTORICO '!D:E,2,FALSE),0) -> 0 | J21: =IFERROR(VLOOKUP(B21&J$12&TEXT(D21,"dd/mm/aaaa"),'HISTORICO '!D:E,2,FALSE),0) -> 0 | K21: =IFERROR(VLOOKUP(B21&K$12&TEXT(D21,"dd/mm/aaaa"),'HISTORICO '!D:E,2,FALSE),0) -> 0 | M21: =IFERROR(_xlfn.XLOOKUP(D21 & B21, 'HISTORICO '!G:G, 'HISTORICO '!F:F),"") | N21: =SUM(E21:L21)+IF(E21>0,E21*1,0) -> 0 | O21: =E21*$E$2+F21*$E$3+G21*$E$4+H21*$E$5+J21*$E$6+K21*$E$7+L21*$E$8 -> 0 | P21: =O21/C21 -> 0 | R21: =SUMIF($G$2:$G$8,Q21,$K$2:$K$8)*O21 -> 0 | S21: 3 | T21: =S21*$C21 -> 12.93 | U21: =0.5*T21 -> 6.465 | W21: Zuri | X21: Boa
A22: 10 | B22: Remanga | C22: 2.48 | D22: =$D$10 -> 46181 | E22: =IFERROR(VLOOKUP(B22&$E$12&TEXT(D22,"dd/mm/aaaa"),'HISTORICO '!D:E,2,FALSE),0) -> 0 | F22: =IFERROR(VLOOKUP(B22&$F$12&TEXT(D22,"dd/mm/aaaa"),'HISTORICO '!D:E,2,FALSE),0) -> 0 | G22: =IFERROR(VLOOKUP(B22&G$12&TEXT(D22,"dd/mm/aaaa"),'HISTORICO '!D:E,2,FALSE),0) -> 0 | H22: =IFERROR(VLOOKUP(B22&H$12&TEXT(D22,"dd/mm/aaaa"),'HISTORICO '!D:E,2,FALSE),0) -> 0 | I22: =IFERROR(VLOOKUP(B22&I$12&TEXT(D22,"dd/mm/aaaa"),'HISTORICO '!D:E,2,FALSE),0) -> 0 | J22: =IFERROR(VLOOKUP(B22&J$12&TEXT(D22,"dd/mm/aaaa"),'HISTORICO '!D:E,2,FALSE),0) -> 0 | K22: =IFERROR(VLOOKUP(B22&K$12&TEXT(D22,"dd/mm/aaaa"),'HISTORICO '!D:E,2,FALSE),0) -> 0 | M22: =IFERROR(_xlfn.XLOOKUP(D22 & B22, 'HISTORICO '!G:G, 'HISTORICO '!F:F),"") | N22: =SUM(E22:L22)+IF(E22>0,E22*1,0) -> 0 | O22: =E22*$E$2+F22*$E$3+G22*$E$4+H22*$E$5+J22*$E$6+K22*$E$7+L22*$E$8 -> 0 | P22: =O22/C22 -> 0 | R22: =SUMIF($G$2:$G$8,Q22,$K$2:$K$8)*O22 -> 0 | S22: 0 | T22: =S22*$C22 -> 0 | U22: =0.5*T22 -> 0 | W22: - | X22: Arado
A23: 11 | B23: Morro de trás | C23: 7.34 | D23: =$D$10 -> 46181 | E23: =IFERROR(VLOOKUP(B23&$E$12&TEXT(D23,"dd/mm/aaaa"),'HISTORICO '!D:E,2,FALSE),0) -> 0 | F23: =IFERROR(VLOOKUP(B23&$F$12&TEXT(D23,"dd/mm/aaaa"),'HISTORICO '!D:E,2,FALSE),0) -> 0 | G23: =IFERROR(VLOOKUP(B23&G$12&TEXT(D23,"dd/mm/aaaa"),'HISTORICO '!D:E,2,FALSE),0) -> 0 | H23: =IFERROR(VLOOKUP(B23&H$12&TEXT(D23,"dd/mm/aaaa"),'HISTORICO '!D:E,2,FALSE),0) -> 0 | I23: =IFERROR(VLOOKUP(B23&I$12&TEXT(D23,"dd/mm/aaaa"),'HISTORICO '!D:E,2,FALSE),0) -> 0 | J23: =IFERROR(VLOOKUP(B23&J$12&TEXT(D23,"dd/mm/aaaa"),'HISTORICO '!D:E,2,FALSE),0) -> 0 | K23: =IFERROR(VLOOKUP(B23&K$12&TEXT(D23,"dd/mm/aaaa"),'HISTORICO '!D:E,2,FALSE),0) -> 0 | M23: =IFERROR(_xlfn.XLOOKUP(D23 & B23, 'HISTORICO '!G:G, 'HISTORICO '!F:F),"") | N23: =SUM(E23:L23)+IF(E23>0,E23*1,0) -> 0 | O23: =E23*$E$2+F23*$E$3+G23*$E$4+H23*$E$5+J23*$E$6+K23*$E$7+L23*$E$8 -> 0 | P23: =O23/C23 -> 0 | R23: =SUMIF($G$2:$G$8,Q23,$K$2:$K$8)*O23 -> 0 | S23: 0 | T23: =S23*$C23 -> 0 | U23: =0.5*T23 -> 0 | W23: - | X23: Arado
A24: 12 | B24: Rotacionado Caixa d'Água | C24: 24.45 | D24: =$D$10 -> 46181 | E24: =IFERROR(VLOOKUP(B24&$E$12&TEXT(D24,"dd/mm/aaaa"),'HISTORICO '!D:E,2,FALSE),0) -> 0 | F24: =IFERROR(VLOOKUP(B24&$F$12&TEXT(D24,"dd/mm/aaaa"),'HISTORICO '!D:E,2,FALSE),0) -> 0 | G24: =IFERROR(VLOOKUP(B24&G$12&TEXT(D24,"dd/mm/aaaa"),'HISTORICO '!D:E,2,FALSE),0) -> 0 | H24: =IFERROR(VLOOKUP(B24&H$12&TEXT(D24,"dd/mm/aaaa"),'HISTORICO '!D:E,2,FALSE),0) -> 0 | I24: =IFERROR(VLOOKUP(B24&I$12&TEXT(D24,"dd/mm/aaaa"),'HISTORICO '!D:E,2,FALSE),0) -> 0 | J24: =IFERROR(VLOOKUP(B24&J$12&TEXT(D24,"dd/mm/aaaa"),'HISTORICO '!D:E,2,FALSE),0) -> 0 | K24: =IFERROR(VLOOKUP(B24&K$12&TEXT(D24,"dd/mm/aaaa"),'HISTORICO '!D:E,2,FALSE),0) -> 0 | M24: =IFERROR(_xlfn.XLOOKUP(D24 & B24, 'HISTORICO '!G:G, 'HISTORICO '!F:F),"") | N24: =SUM(E24:L24)+IF(E24>0,E24*1,0) -> 0 | O24: =E24*$E$2+F24*$E$3+G24*$E$4+H24*$E$5+J24*$E$6+K24*$E$7+L24*$E$8 -> 0 | P24: =O24/C24 -> 0 | Q24: 4 | R24: =SUMIF($G$2:$G$8,Q24,$K$2:$K$8)*O24 -> 0 | S24: 1.5 | T24: =S24*$C24 -> 36.675 | U24: =0.5*T24 -> 18.3375 | W24: Braquiária | X24: Ruim/médio
A25: 13 | B25: Rotacionado Macaúba | C25: 18.69 | D25: =$D$10 -> 46181 | E25: =IFERROR(VLOOKUP(B25&$E$12&TEXT(D25,"dd/mm/aaaa"),'HISTORICO '!D:E,2,FALSE),0) -> 3 | F25: =IFERROR(VLOOKUP(B25&$F$12&TEXT(D25,"dd/mm/aaaa"),'HISTORICO '!D:E,2,FALSE),0) -> 7 | G25: =IFERROR(VLOOKUP(B25&G$12&TEXT(D25,"dd/mm/aaaa"),'HISTORICO '!D:E,2,FALSE),0) -> 0 | H25: =IFERROR(VLOOKUP(B25&H$12&TEXT(D25,"dd/mm/aaaa"),'HISTORICO '!D:E,2,FALSE),0) -> 0 | I25: =IFERROR(VLOOKUP(B25&I$12&TEXT(D25,"dd/mm/aaaa"),'HISTORICO '!D:E,2,FALSE),0) -> 0 | J25: =IFERROR(VLOOKUP(B25&J$12&TEXT(D25,"dd/mm/aaaa"),'HISTORICO '!D:E,2,FALSE),0) -> 0 | K25: =IFERROR(VLOOKUP(B25&K$12&TEXT(D25,"dd/mm/aaaa"),'HISTORICO '!D:E,2,FALSE),0) -> 6 | M25: =IFERROR(_xlfn.XLOOKUP(D25 & B25, 'HISTORICO '!G:G, 'HISTORICO '!F:F),"") -> 0 | N25: =SUM(E25:L25)+IF(E25>0,E25*1,0) -> 19 | O25: =E25*$E$2+F25*$E$3+G25*$E$4+H25*$E$5+J25*$E$6+K25*$E$7+L25*$E$8 -> 21.666667 | P25: =O25/C25 -> 1.1592652 | Q25: 4 | R25: =SUMIF($G$2:$G$8,Q25,$K$2:$K$8)*O25 -> 9.75 | S25: 1.5 | T25: =S25*$C25 -> 28.035 | U25: =0.5*T25 -> 14.0175 | W25: Andropogon | X25: Ruim/médio
A26: 14 | B26: Jacaré 1 | C26: 37.7 | D26: =$D$10 -> 46181 | E26: =IFERROR(VLOOKUP(B26&$E$12&TEXT(D26,"dd/mm/aaaa"),'HISTORICO '!D:E,2,FALSE),0) -> 0 | F26: =IFERROR(VLOOKUP(B26&$F$12&TEXT(D26,"dd/mm/aaaa"),'HISTORICO '!D:E,2,FALSE),0) -> 0 | G26: =IFERROR(VLOOKUP(B26&G$12&TEXT(D26,"dd/mm/aaaa"),'HISTORICO '!D:E,2,FALSE),0) -> 0 | H26: =IFERROR(VLOOKUP(B26&H$12&TEXT(D26,"dd/mm/aaaa"),'HISTORICO '!D:E,2,FALSE),0) -> 0 | I26: =IFERROR(VLOOKUP(B26&I$12&TEXT(D26,"dd/mm/aaaa"),'HISTORICO '!D:E,2,FALSE),0) -> 0 | J26: =IFERROR(VLOOKUP(B26&J$12&TEXT(D26,"dd/mm/aaaa"),'HISTORICO '!D:E,2,FALSE),0) -> 0 | K26: =IFERROR(VLOOKUP(B26&K$12&TEXT(D26,"dd/mm/aaaa"),'HISTORICO '!D:E,2,FALSE),0) -> 0 | M26: =IFERROR(_xlfn.XLOOKUP(D26 & B26, 'HISTORICO '!G:G, 'HISTORICO '!F:F),"") | N26: =SUM(E26:L26)+IF(E26>0,E26*1,0) -> 0 | O26: =E26*$E$2+F26*$E$3+G26*$E$4+H26*$E$5+J26*$E$6+K26*$E$7+L26*$E$8 -> 0 | P26: =O26/C26 -> 0 | R26: =SUMIF($G$2:$G$8,Q26,$K$2:$K$8)*O26 -> 0 | S26: 1 | T26: =S26*$C26 -> 37.7 | U26: =0.5*T26 -> 18.85 | W26: Andropogon | X26: Ruim
