Workbook

Sheet Dashboard
B2: DASHBOARD — VISÃO GERAL DO CONFINAMENTO BG
B4: REBANHO | E4: ECONÔMICO / NUTRIÇÃO
B5: Total de animais | C5: =COUNTA(Cadastro_Animais!$B$3:$B$5001) -> 385 | E5: Preço da arroba (R$/@) | F5: =Parâmetros!$C$5 -> 310
B6: Touros Bonsmara | C6: =COUNTIF(Cadastro_Animais!$C$3:$C$5001,"Touro Bonsmara") -> 84 | E6: Valor do rebanho (R$) | F6: =SUM(Cadastro_Animais!$O$3:$O$5001) -> 1471372.2
B7: Touros Nelore | C7: =COUNTIF(Cadastro_Animais!$C$3:$C$5001,"Touro Nelore") -> 29 | E7: Custo dieta médio (R$/kg MN) | F7: =Parâmetros!$C$6 -> 0.54970799
B8: Bezerros | C8: =COUNTIF(Cadastro_Animais!$C$3:$C$5001,"Bezerro") -> 165 | E8: Consumo planejado/dia (kg MN) | F8: =Calculadora_Trato!$I$14 -> 3223.944
B9: Novilhas Nelore | C9: =COUNTIF(Cadastro_Animais!$C$3:$C$5001,"Novilha Nelore") -> 70 | E9: Custo total ração/dia (R$) | F9: =Calculadora_Trato!$N$14 -> 1772.2278
B10: Bonsmara Descarte | C10: =COUNTIF(Cadastro_Animais!$C$3:$C$5001,"Touro Bonsmara Descarte") -> 37 | E10: Custo ração/cab/dia (R$) | F10: =IFERROR(Calculadora_Trato!$N$14/COUNTA(Cadastro_Animais!$B$3:$B$5001),"") -> 4.603189
B11: Peso vivo total atual (kg) | C11: =SUM(Cadastro_Animais!$I$3:$I$5001) -> 134331 | E11: @ totais em estoque | F11: =SUM(Cadastro_Animais!$M$3:$M$5001) -> 4746.362
B13: DESEMPENHO (onde há 2+ pesagens) | E13: CUSTO ACUMULADO / @
B14: GMD médio do rebanho (kg/dia) | C14: =IFERROR(AVERAGE(Cadastro_Animais!$L$3:$L$5001),"") -> 2.369628 | E14: Custo nutrição estim. acum. (R$) | F14: =Custo_Nutricao_Lote!$I$12 -> 64360.099
B15: Ganho total acumulado (kg) | C15: =SUM(Cadastro_Animais!$K$3:$K$5001) -> 5995 | E15: Custo nutrição real acum. (R$) | F15: =Custo_Nutricao_Lote!$J$12 -> 101992
B16: @ produzidas (ganho) | C16: =SUM(Cadastro_Animais!$N$3:$N$5001) -> 211.82333 | E16: Custo estim./@ produzida (R$) | F16: =IF(Custo_Nutricao_Lote!$L$12<=0,"",Custo_Nutricao_Lote!$I$12/Custo_Nutricao_Lote!$L$12) -> 303.83857
B17: GMD meta (kg/dia) | C17: =Parâmetros!$C$10 -> 1.4 | E17: Obs.: consumo/custo de ração vêm da Calculadora (planejado). Lance o Trato_Diario para o custo real.

Sheet Venda_Nelore
B2: VENDA — TOUROS NELORE (curral 4-TN)
B3: Frigorífico | C3: PRIMA FOODS S.A. — Araguari/MG
B4: Nota Fiscal / Pedido | C4: NF 78727 · PR/01-239058-01
B5: Data do abate | C5: 46247
B6: Data saída da fazenda | C6: 46246
B8: DADOS DA VENDA
B9: Cabeças | C9: 29
B10: Preço da arroba (R$/@) | C10: 330
B11: Peso de carcaça total (kg) | C11: 8819.5
B12: Arrobas de carcaça (@) | C12: 587.97
B13: Carcaça média por cabeça (kg) | C13: 304.12
B14: Rendimento de carcaça (carcaça ÷ peso fazenda) | C14: 0.5443
B15: Valor bruto | C15: 194029
B16: (−) SENAR | C16: 388.06
B17: VALOR LÍQUIDO | C17: 193640.94
B18: Preço médio por cabeça (líquido) | C18: 6677.27
B19: Pagamento | C19: 32 dias — vencimento 14/09/2026
B20: Dentição | C20: 10× 0 dente · 15× 2 dentes · 4× 4 dentes
B22: CUSTO DO LOTE
B23: Custo de entrada (13.462 kg × 50% ÷ 15 × R$310/@) | C23: 139107.33
B24: Custo de ração (real — Trato_Diário) | C24: 20138.4
B25: Custo fixo (R$2,50/cab/dia × 1.217 cab-dias) | C25: 3042.5
B26: CUSTO TOTAL | C26: 162288.24
B27: Custo total por cabeça | C27: 5596.15
B29: RESULTADO
B30: Receita líquida | C30: 193640.94
B31: (−) Custo total | C31: 162288.24
B32: LUCRO DO LOTE | C32: 31352.7
B33: Lucro por cabeça | C33: 1081.13
B34: Margem sobre a receita | C34: 0.162
B35: ROI sobre o custo | C35: 0.193
B36: Custo da arroba produzida (ração+fixo) | C36: 166.49
B38: ZOOTÉCNICO
B39: Peso médio de entrada (kg) | C39: 464.2
B40: Peso médio de saída (kg) | C40: 558.7
B41: Ganho total do lote (kg) | C41: 2741
B42: GMD médio (kg/dia) | C42: 2.26
B43: Dias de confinamento (média) | C43: 43

Sheet Parâmetros
B2: PARÂMETROS (edite as células amarelas)
B3: Parâmetro | C3: Valor | D3: Observação
B4: Data de referência | C4: 46246 | D4: Data usada para calcular os dias de confinamento.
B5: Preço da arroba (R$/@) | C5: 310 | D5: PLACEHOLDER — ajuste ao preço da arroba do boi gordo que você usa.
B6: Custo da ração (R$/kg matéria natural) | C6: =IFERROR(Calculadora_Trato!$N$14/Calculadora_Trato!$I$14,"") -> 0.54970799 | D6: Automático: custo médio ponderado das dietas (Calculadora_Trato). Cada curral usa sua própria dieta.
B7: % Matéria seca da dieta | C7: 0.55 | D7: PLACEHOLDER — teor de MS da dieta (ex.: 55%). Usado para converter MN em MS.
B8: Rendimento de carcaça (%) | C8: 0.53 | D8: PLACEHOLDER — rendimento de carcaça para converter peso vivo em @.
B9: Custo fixo diário (R$/cab/dia) | C9: 2.5 | D9: PLACEHOLDER — sanidade + mão de obra + demais custos por cabeça/dia (fora ração).
B10: GMD meta (kg/dia) | C10: 1.4 | D10: Meta de ganho médio diário para comparação.
B11: Peso de abate alvo (kg) | C11: 500 | D11: Peso vivo alvo para projeções.

Sheet Precos_Insumos
A1: COMPRAS / PREÇOS DE INSUMOS (por data)
A2: Registre CADA compra: Data, Insumo, Preço R$/kg e Qtd. O custo das dietas usa sempre o preço da compra mais recente de cada insumo.
A3: Data | B3: Insumo | C3: Preço (R$/kg) | D3: Qtd Comprada (kg) | E3: Valor Total (R$) | F3: Fornecedor | G3: Obs
A4: 46202 | B4: Silagem de Capim | C4: 0.1 | E4: =IF(D4="","",C4*D4)
A5: 46202 | B5: Promill | C5: 1.1 | E5: =IF(D5="","",C5*D5)
A6: 46202 | B6: Milho Moído | C6: 1.13 | E6: =IF(D6="","",C6*D6)
A7: 46202 | B7: Ureia | C7: 3.8 | E7: =IF(D7="","",C7*D7)
A8: 46202 | B8: Núcleo Flex (Flexbeef MD) | C8: 3.8 | E8: =IF(D8="","",C8*D8)
E9: =IF(D9="","",C9*D9)
E10: =IF(D10="","",C10*D10)
E11: =IF(D11="","",C11*D11)
E12: =IF(D12="","",C12*D12)
E13: =IF(D13="","",C13*D13)
E14: =IF(D14="","",C14*D14)
E15: =IF(D15="","",C15*D15)
E16: =IF(D16="","",C16*D16)
E17: =IF(D17="","",C17*D17)
E18: =IF(D18="","",C18*D18)
E19: =IF(D19="","",C19*D19)
E20: =IF(D20="","",C20*D20)
... E203: =IF(D203="","",C203*D203)

Sheet Estoque_Insumos
B2: ESTOQUE DE INSUMOS (estimativa) — BG
B3: Informe o Estoque na data-base e a Data-base de cada insumo (amarelo). O consumo vem dos lançamentos do Trato_Diario, considerando a dieta de cada curral. Consumo/dia = consumo planejado atual (Calculadora).
B5: Insumo | C5: Estoque na data-base (kg) | D5: Data-base | E5: Compras após (kg) | F5: Consumo após (kg) | G5: Estoque Atual (kg) | H5: Consumo/dia atual (kg) | I5: Dias de estoque
B6: Silagem de Capim | E6: =IF($D6="","",SUMIFS(Precos_Insumos!$D$4:$D$203,Precos_Insumos!$B$4:$B$203,$B6,Precos_Insumos!$A$4:$A$203,">"&$D6)) | F6: =IF($D6="","",SUMPRODUCT(SUMIFS(Trato_Diario!$F$4:$F$203,Trato_Diario!$B$4:$B$203,Currais!$A$3:$A$8,Trato_Diario!$A$4:$A$203,">="&$D6),Currais!$L$3:$L$8)) | G6: =IF($C6="","",$C6+N(E6)-N(F6)) | H6: =SUMPRODUCT(Calculadora_Trato!$I$8:$I$13,Currais!$L$3:$L$8) -> 1913.057 | I6: =IF(OR(G6="",H6=0),"",G6/H6)
B7: Promill | E7: =IF($D7="","",SUMIFS(Precos_Insumos!$D$4:$D$203,Precos_Insumos!$B$4:$B$203,$B7,Precos_Insumos!$A$4:$A$203,">"&$D7)) | F7: =IF($D7="","",SUMPRODUCT(SUMIFS(Trato_Diario!$F$4:$F$203,Trato_Diario!$B$4:$B$203,Currais!$A$3:$A$8,Trato_Diario!$A$4:$A$203,">="&$D7),Currais!$M$3:$M$8)) | G7: =IF($C7="","",$C7+N(E7)-N(F7)) | H7: =SUMPRODUCT(Calculadora_Trato!$I$8:$I$13,Currais!$M$3:$M$8) -> 791.34672 | I7: =IF(OR(G7="",H7=0),"",G7/H7)
B8: Milho Moído | E8: =IF($D8="","",SUMIFS(Precos_Insumos!$D$4:$D$203,Precos_Insumos!$B$4:$B$203,$B8,Precos_Insumos!$A$4:$A$203,">"&$D8)) | F8: =IF($D8="","",SUMPRODUCT(SUMIFS(Trato_Diario!$F$4:$F$203,Trato_Diario!$B$4:$B$203,Currais!$A$3:$A$8,Trato_Diario!$A$4:$A$203,">="&$D8),Currais!$N$3:$N$8)) | G8: =IF($C8="","",$C8+N(E8)-N(F8)) | H8: =SUMPRODUCT(Calculadora_Trato!$I$8:$I$13,Currais!$N$3:$N$8) -> 473.33791 | I8: =IF(OR(G8="",H8=0),"",G8/H8)
B9: Ureia | E9: =IF($D9="","",SUMIFS(Precos_Insumos!$D$4:$D$203,Precos_Insumos!$B$4:$B$203,$B9,Precos_Insumos!$A$4:$A$203,">"&$D9)) | F9: =IF($D9="","",SUMPRODUCT(SUMIFS(Trato_Diario!$F$4:$F$203,Trato_Diario!$B$4:$B$203,Currais!$A$3:$A$8,Trato_Diario!$A$4:$A$203,">="&$D9),Currais!$O$3:$O$8)) | G9: =IF($C9="","",$C9+N(E9)-N(F9)) | H9: =SUMPRODUCT(Calculadora_Trato!$I$8:$I$13,Currais!$O$3:$O$8) -> 16.11972 | I9: =IF(OR(G9="",H9=0),"",G9/H9)
B10: Núcleo Flex (Flexbeef MD) | E10: =IF($D10="","",SUMIFS(Precos_Insumos!$D$4:$D$203,Precos_Insumos!$B$4:$B$203,$B10,Precos_Insumos!$A$4:$A$203,">"&$D10)) | F10: =IF($D10="","",SUMPRODUCT(SUMIFS(Trato_Diario!$F$4:$F$203,Trato_Diario!$B$4:$B$203,Currais!$A$3:$A$8,Trato_Diario!$A$4:$A$203,">="&$D10),Currais!$P$3:$P$8)) | G10: =IF($C10="","",$C10+N(E10)-N(F10)) | H10: =SUMPRODUCT(Calculadora_Trato!$I$8:$I$13,Currais!$P$3:$P$8) -> 30.082608 | I10: =IF(OR(G10="",H10=0),"",G10/H10)
B12: Obs.: preencha o estoque e a data-base de cada insumo. O 'Consumo/dia atual' já aparece (consumo planejado da Calculadora × % da dieta de cada curral). 'Dias de estoque' = estoque ÷ consumo/dia.

Sheet Ingredientes_Dieta
B2: INGREDIENTES E DIETAS — BARRA GRANDE
B3: Preço vem AUTOMÁTICO da última compra (Precos_Insumos). Edite as % de inclusão (amarelo) de cada dieta. Valores nas colunas Touros/Boi Nelore/Bezerros/Descarte = % de inclusão.
B5: Ingrediente | C5: Preço (R$/kg) | D5: Última compra | E5: Touros | F5: Boi Nelore | G5: Bezerros | H5: Descarte
B6: Silagem de Capim | C6: =IFERROR(AVERAGEIFS(Precos_Insumos!$C$4:$C$203,Precos_Insumos!$B$4:$B$203,B6,Precos_Insumos!$A$4:$A$203,D6),0) -> 0.1 | D6: =IFERROR(_xlfn.MAXIFS(Precos_Insumos!$A$4:$A$203,Precos_Insumos!$B$4:$B$203,B6),"") -> 46202 | E6: 0.68 | F6: 0.48 | G6: 0.62 | H6: 0.57
B7: Promill | C7: =IFERROR(AVERAGEIFS(Precos_Insumos!$C$4:$C$203,Precos_Insumos!$B$4:$B$203,B7,Precos_Insumos!$A$4:$A$203,D7),0) -> 1.1 | D7: =IFERROR(_xlfn.MAXIFS(Precos_Insumos!$A$4:$A$203,Precos_Insumos!$B$4:$B$203,B7),"") -> 46202 | E7: 0.22 | F7: 0.22 | G7: 0.3 | H7: 0.26
B8: Milho Moído | C8: =IFERROR(AVERAGEIFS(Precos_Insumos!$C$4:$C$203,Precos_Insumos!$B$4:$B$203,B8,Precos_Insumos!$A$4:$A$203,D8),0) -> 1.13 | D8: =IFERROR(_xlfn.MAXIFS(Precos_Insumos!$A$4:$A$203,Precos_Insumos!$B$4:$B$203,B8),"") -> 46202 | E8: 0.087 | F8: 0.285 | G8: 0.065 | H8: 0.155
B9: Ureia | C9: =IFERROR(AVERAGEIFS(Precos_Insumos!$C$4:$C$203,Precos_Insumos!$B$4:$B$203,B9,Precos_Insumos!$A$4:$A$203,D9),0) -> 3.8 | D9: =IFERROR(_xlfn.MAXIFS(Precos_Insumos!$A$4:$A$203,Precos_Insumos!$B$4:$B$203,B9),"") -> 46202 | E9: 0.005 | F9: 0.005 | G9: 0.005 | H9: 0.005
B10: Núcleo Flex (Flexbeef MD) | C10: =IFERROR(AVERAGEIFS(Precos_Insumos!$C$4:$C$203,Precos_Insumos!$B$4:$B$203,B10,Precos_Insumos!$A$4:$A$203,D10),0) -> 3.8 | D10: =IFERROR(_xlfn.MAXIFS(Precos_Insumos!$A$4:$A$203,Precos_Insumos!$B$4:$B$203,B10),"") -> 46202 | E10: 0.008 | F10: 0.01 | G10: 0.01 | H10: 0.01
B11: Custo da dieta (R$/kg) | E11: =SUMPRODUCT($C$6:$C$10,E6:E10) -> 0.45771 | F11: =SUMPRODUCT($C$6:$C$10,F6:F10) -> 0.66905 | G11: =SUMPRODUCT($C$6:$C$10,G6:G10) -> 0.52245 | H11: =SUMPRODUCT($C$6:$C$10,H6:H10) -> 0.57515
B13: Conferência % (cada dieta deve dar 100%): | E13: =SUM(E6:E10) -> 1 | F13: =SUM(F6:F10) -> 1 | G13: =SUM(G6:G10) -> 1 | H13: =SUM(H6:H10) -> 1

Sheet Calculadora_Trato
B2: CALCULADORA DE TRATO POR CURRAL — BG
B3: Base = Nº cabeças × Peso médio × % do peso vivo (MN). Ajuste a % do peso vivo e o Ajuste % de cada curral (amarelo). Cada curral usa sua dieta (Currais). Split manhã/almoço/tarde editável.
B5: % do peso vivo (MN): | D5: 0.024 | E5: Manhã | F5: 0.4 | G5: Almoço | H5: 0.2 | I5: Tarde | J5: 0.4
B7: Curral | C7: Nº Cab | D7: Peso Médio (kg) | E7: Dieta | F7: Custo Dieta (R$/kg) | G7: Base Total (kg MN/dia) | H7: Ajuste % | I7: Consumo Ajustado (kg MN/dia) | J7: kg MN/cab | K7: Trato Manhã (kg) | L7: Trato Almoço (kg) | M7: Trato Tarde (kg) | N7: Custo Planejado/dia (R$) | O7: Custo/cab/dia (R$)
B8: 2 | C8: =IFERROR(INDEX(Currais!$C$3:$C$8,MATCH(B8,Currais!$A$3:$A$8,0)),0) -> 38 | D8: =IFERROR(INDEX(Currais!$E$3:$E$8,MATCH(B8,Currais!$A$3:$A$8,0)),0) -> 551.84211 | E8: =IFERROR(INDEX(Currais!$J$3:$J$8,MATCH(B8,Currais!$A$3:$A$8,0)),"") -> Touros | F8: =IFERROR(INDEX(Currais!$K$3:$K$8,MATCH(B8,Currais!$A$3:$A$8,0)),0) -> 0.45771 | G8: =C8*D8*$D$5 -> 503.28 | H8: 0 | I8: =G8*(1+H8) -> 503.28 | J8: =IF(C8=0,"",I8/C8) -> 13.244211 | K8: =I8*$F$5 -> 201.312 | L8: =I8*$H$5 -> 100.656 | M8: =I8*$J$5 -> 201.312 | N8: =I8*F8 -> 230.35629 | O8: =IF(C8=0,"",N8/C8) -> 6.0620076
B9: 3 | C9: =IFERROR(INDEX(Currais!$C$3:$C$8,MATCH(B9,Currais!$A$3:$A$8,0)),0) -> 46 | D9: =IFERROR(INDEX(Currais!$E$3:$E$8,MATCH(B9,Currais!$A$3:$A$8,0)),0) -> 520.95652 | E9: =IFERROR(INDEX(Currais!$J$3:$J$8,MATCH(B9,Currais!$A$3:$A$8,0)),"") -> Touros | F9: =IFERROR(INDEX(Currais!$K$3:$K$8,MATCH(B9,Currais!$A$3:$A$8,0)),0) -> 0.45771 | G9: =C9*D9*$D$5 -> 575.136 | H9: 0 | I9: =G9*(1+H9) -> 575.136 | J9: =IF(C9=0,"",I9/C9) -> 12.502957 | K9: =I9*$F$5 -> 230.0544 | L9: =I9*$H$5 -> 115.0272 | M9: =I9*$J$5 -> 230.0544 | N9: =I9*F9 -> 263.2455 | O9: =IF(C9=0,"",N9/C9) -> 5.7227282
B10: 4 | C10: =IFERROR(INDEX(Currais!$C$3:$C$8,MATCH(B10,Currais!$A$3:$A$8,0)),0) -> 165 | D10: =IFERROR(INDEX(Currais!$E$3:$E$8,MATCH(B10,Currais!$A$3:$A$8,0)),0) -> 219.67879 | E10: =IFERROR(INDEX(Currais!$J$3:$J$8,MATCH(B10,Currais!$A$3:$A$8,0)),"") -> Bezerros | F10: =IFERROR(INDEX(Currais!$K$3:$K$8,MATCH(B10,Currais!$A$3:$A$8,0)),0) -> 0.52245 | G10: =C10*D10*$D$5 -> 869.928 | H10: 0 | I10: =G10*(1+H10) -> 869.928 | J10: =IF(C10=0,"",I10/C10) -> 5.2722909 | K10: =I10*$F$5 -> 347.9712 | L10: =I10*$H$5 -> 173.9856 | M10: =I10*$J$5 -> 347.9712 | N10: =I10*F10 -> 454.49388 | O10: =IF(C10=0,"",N10/C10) -> 2.7545084
B11: 4-TN | C11: =IFERROR(INDEX(Currais!$C$3:$C$8,MATCH(B11,Currais!$A$3:$A$8,0)),0) -> 29 | D11: =IFERROR(INDEX(Currais!$E$3:$E$8,MATCH(B11,Currais!$A$3:$A$8,0)),0) -> 558.72414 | E11: =IFERROR(INDEX(Currais!$J$3:$J$8,MATCH(B11,Currais!$A$3:$A$8,0)),"") -> Boi Nelore | F11: =IFERROR(INDEX(Currais!$K$3:$K$8,MATCH(B11,Currais!$A$3:$A$8,0)),0) -> 0.66905 | G11: =C11*D11*$D$5 -> 388.872 | H11: 0 | I11: =G11*(1+H11) -> 388.872 | J11: =IF(C11=0,"",I11/C11) -> 13.409379 | K11: =I11*$F$5 -> 155.5488 | L11: =I11*$H$5 -> 77.7744 | M11: =I11*$J$5 -> 155.5488 | N11: =I11*F11 -> 260.17481 | O11: =IF(C11=0,"",N11/C11) -> 8.9715452
B12: (a definir) | C12: =IFERROR(INDEX(Currais!$C$3:$C$8,MATCH(B12,Currais!$A$3:$A$8,0)),0) -> 70 | D12: =IFERROR(INDEX(Currais!$E$3:$E$8,MATCH(B12,Currais!$A$3:$A$8,0)),0) -> 342.02857 | E12: =IFERROR(INDEX(Currais!$J$3:$J$8,MATCH(B12,Currais!$A$3:$A$8,0)),"") -> Boi Nelore | F12: =IFERROR(INDEX(Currais!$K$3:$K$8,MATCH(B12,Currais!$A$3:$A$8,0)),0) -> 0.66905 | G12: =C12*D12*$D$5 -> 574.608 | H12: 0 | I12: =G12*(1+H12) -> 574.608 | J12: =IF(C12=0,"",I12/C12) -> 8.2086857 | K12: =I12*$F$5 -> 229.8432 | L12: =I12*$H$5 -> 114.9216 | M12: =I12*$J$5 -> 229.8432 | N12: =I12*F12 -> 384.44148 | O12: =IF(C12=0,"",N12/C12) -> 5.4920212
B13: 5 | C13: =IFERROR(INDEX(Currais!$C$3:$C$8,MATCH(B13,Currais!$A$3:$A$8,0)),0) -> 37 | D13: =IFERROR(INDEX(Currais!$E$3:$E$8,MATCH(B13,Currais!$A$3:$A$8,0)),0) -> 351.48649 | E13: =IFERROR(INDEX(Currais!$J$3:$J$8,MATCH(B13,Currais!$A$3:$A$8,0)),"") -> Descarte | F13: =IFERROR(INDEX(Currais!$K$3:$K$8,MATCH(B13,Currais!$A$3:$A$8,0)),0) -> 0.57515 | G13: =C13*D13*$D$5 -> 312.12 | H13: 0 | I13: =G13*(1+H13) -> 312.12 | J13: =IF(C13=0,"",I13/C13) -> 8.4356757 | K13: =I13*$F$5 -> 124.848 | L13: =I13*$H$5 -> 62.424 | M13: =I13*$J$5 -> 124.848 | N13: =I13*F13 -> 179.51582 | O13: =IF(C13=0,"",N13/C13) -> 4.8517789
B14: TOTAL | C14: =SUM(C8:C13) -> 385 | G14: =SUM(G8:G13) -> 3223.944 | I14: =SUM(I8:I13) -> 3223.944 | K14: =SUM(K8:K13) -> 1289.5776 | L14: =SUM(L8:L13) -> 644.7888 | M14: =SUM(M8:M13) -> 1289.5776 | N14: =SUM(N8:N13) -> 1772.2278 | O14: =IF(C14=0,"",N14/C14) -> 4.603189

Sheet Trato_Diario
A1: LANÇAMENTO DIÁRIO DE TRATO (REAL) POR CURRAL
A2: Lance o que foi realmente fornecido por dia/curral (amarelo). O custo usa a dieta do curral (Currais). Alimenta o Custo Real por lote e o Estoque.
A3: Data | B3: Curral | C3: Trato Manhã (kg MN) | D3: Trato Almoço (kg MN) | E3: Trato Tarde (kg MN) | F3: Total Dia (kg MN) | G3: Nº Cab | H3: kg MN/cab | I3: Custo Dieta (R$/kg) | J3: Custo Total (R$) | K3: Obs
A4: 46203 | B4: 2 | C4: 320 | D4: 160 | E4: 320 | F4: =IF(AND(C4="",D4="",E4=""),"",N(C4)+N(D4)+N(E4)) -> 800 | G4: =IF(B4="","",IFERROR(INDEX(Currais!$C$3:$C$8,MATCH(B4,Currais!$A$3:$A$8,0)),"")) -> 38 | H4: =IF(OR(F4="",G4="",G4=0),"",F4/G4) -> 21.052632 | I4: =IF(F4="","",IFERROR(INDEX(Currais!$K$3:$K$8,MATCH(B4,Currais!$A$3:$A$8,0)),0)) -> 0.45771 | J4: =IF(F4="","",F4*I4) -> 366.168 | K4: Estimado — rampa
A5: 46204 | B5: 2 | C5: 320 | D5: 160 | E5: 320 | F5: =IF(AND(C5="",D5="",E5=""),"",N(C5)+N(D5)+N(E5)) -> 800 | G5: =IF(B5="","",IFERROR(INDEX(Currais!$C$3:$C$8,MATCH(B5,Currais!$A$3:$A$8,0)),"")) -> 38 | H5: =IF(OR(F5="",G5="",G5=0),"",F5/G5) -> 21.052632 | I5: =IF(F5="","",IFERROR(INDEX(Currais!$K$3:$K$8,MATCH(B5,Currais!$A$3:$A$8,0)),0)) -> 0.45771 | J5: =IF(F5="","",F5*I5) -> 366.168 | K5: Estimado — rampa
A6: 46205 | B6: 2 | C6: 320 | D6: 160 | E6: 320 | F6: =IF(AND(C6="",D6="",E6=""),"",N(C6)+N(D6)+N(E6)) -> 800 | G6: =IF(B6="","",IFERROR(INDEX(Currais!$C$3:$C$8,MATCH(B6,Currais!$A$3:$A$8,0)),"")) -> 38 | H6: =IF(OR(F6="",G6="",G6=0),"",F6/G6) -> 21.052632 | I6: =IF(F6="","",IFERROR(INDEX(Currais!$K$3:$K$8,MATCH(B6,Currais!$A$3:$A$8,0)),0)) -> 0.45771 | J6: =IF(F6="","",F6*I6) -> 366.168 | K6: Estimado — rampa
A7: 46206 | B7: 2 | C7: 360 | D7: 180 | E7: 360 | F7: =IF(AND(C7="",D7="",E7=""),"",N(C7)+N(D7)+N(E7)) -> 900 | G7: =IF(B7="","",IFERROR(INDEX(Currais!$C$3:$C$8,MATCH(B7,Currais!$A$3:$A$8,0)),"")) -> 38 | H7: =IF(OR(F7="",G7="",G7=0),"",F7/G7) -> 23.684211 | I7: =IF(F7="","",IFERROR(INDEX(Currais!$K$3:$K$8,MATCH(B7,Currais!$A$3:$A$8,0)),0)) -> 0.45771 | J7: =IF(F7="","",F7*I7) -> 411.939 | K7: Estimado — rampa
A8: 46207 | B8: 2 | C8: 360 | D8: 180 | E8: 360 | F8: =IF(AND(C8="",D8="",E8=""),"",N(C8)+N(D8)+N(E8)) -> 900 | G8: =IF(B8="","",IFERROR(INDEX(Currais!$C$3:$C$8,MATCH(B8,Currais!$A$3:$A$8,0)),"")) -> 38 | H8: =IF(OR(F8="",G8="",G8=0),"",F8/G8) -> 23.684211 | I8: =IF(F8="","",IFERROR(INDEX(Currais!$K$3:$K$8,MATCH(B8,Currais!$A$3:$A$8,0)),0)) -> 0.45771 | J8: =IF(F8="","",F8*I8) -> 411.939 | K8: Estimado — rampa
A9: 46208 | B9: 2 | C9: 360 | D9: 180 | E9: 360 | F9: =IF(AND(C9="",D9="",E9=""),"",N(C9)+N(D9)+N(E9)) -> 900 | G9: =IF(B9="","",IFERROR(INDEX(Currais!$C$3:$C$8,MATCH(B9,Currais!$A$3:$A$8,0)),"")) -> 38 | H9: =IF(OR(F9="",G9="",G9=0),"",F9/G9) -> 23.684211 | I9: =IF(F9="","",IFERROR(INDEX(Currais!$K$3:$K$8,MATCH(B9,Currais!$A$3:$A$8,0)),0)) -> 0.45771 | J9: =IF(F9="","",F9*I9) -> 411.939 | K9: Estimado — rampa
A10: 46209 | B10: 2 | C10: 400 | D10: 200 | E10: 400 | F10: =IF(AND(C10="",D10="",E10=""),"",N(C10)+N(D10)+N(E10)) -> 1000 | G10: =IF(B10="","",IFERROR(INDEX(Currais!$C$3:$C$8,MATCH(B10,Currais!$A$3:$A$8,0)),"")) -> 38 | H10: =IF(OR(F10="",G10="",G10=0),"",F10/G10) -> 26.315789 | I10: =IF(F10="","",IFERROR(INDEX(Currais!$K$3:$K$8,MATCH(B10,Currais!$A$3:$A$8,0)),0)) -> 0.45771 | J10: =IF(F10="","",F10*I10) -> 457.71 | K10: Estimado — rampa
A11: 46210 | B11: 2 | C11: 400 | D11: 200 | E11: 400 | F11: =IF(AND(C11="",D11="",E11=""),"",N(C11)+N(D11)+N(E11)) -> 1000 | G11: =IF(B11="","",IFERROR(INDEX(Currais!$C$3:$C$8,MATCH(B11,Currais!$A$3:$A$8,0)),"")) -> 38 | H11: =IF(OR(F11="",G11="",G11=0),"",F11/G11) -> 26.315789 | I11: =IF(F11="","",IFERROR(INDEX(Currais!$K$3:$K$8,MATCH(B11,Currais!$A$3:$A$8,0)),0)) -> 0.45771 | J11: =IF(F11="","",F11*I11) -> 457.71 | K11: Estimado — rampa
A12: 46211 | B12: 2 | C12: 400 | D12: 200 | E12: 400 | F12: =IF(AND(C12="",D12="",E12=""),"",N(C12)+N(D12)+N(E12)) -> 1000 | G12: =IF(B12="","",IFERROR(INDEX(Currais!$C$3:$C$8,MATCH(B12,Currais!$A$3:$A$8,0)),"")) -> 38 | H12: =IF(OR(F12="",G12="",G12=0),"",F12/G12) -> 26.315789 | I12: =IF(F12="","",IFERROR(INDEX(Currais!$K$3:$K$8,MATCH(B12,Currais!$A$3:$A$8,0)),0)) -> 0.45771 | J12: =IF(F12="","",F12*I12) -> 457.71 | K12: Estimado — rampa
A13: 46212 | B13: 2 | C13: 440 | D13: 220 | E13: 440 | F13: =IF(AND(C13="",D13="",E13=""),"",N(C13)+N(D13)+N(E13)) -> 1100 | G13: =IF(B13="","",IFERROR(INDEX(Currais!$C$3:$C$8,MATCH(B13,Currais!$A$3:$A$8,0)),"")) -> 38 | H13: =IF(OR(F13="",G13="",G13=0),"",F13/G13) -> 28.947368 | I13: =IF(F13="","",IFERROR(INDEX(Currais!$K$3:$K$8,MATCH(B13,Currais!$A$3:$A$8,0)),0)) -> 0.45771 | J13: =IF(F13="","",F13*I13) -> 503.481 | K13: Estimado — rampa
A14: 46213 | B14: 2 | C14: 440 | D14: 220 | E14: 440 | F14: =IF(AND(C14="",D14="",E14=""),"",N(C14)+N(D14)+N(E14)) -> 1100 | G14: =IF(B14="","",IFERROR(INDEX(Currais!$C$3:$C$8,MATCH(B14,Currais!$A$3:$A$8,0)),"")) -> 38 | H14: =IF(OR(F14="",G14="",G14=0),"",F14/G14) -> 28.947368 | I14: =IF(F14="","",IFERROR(INDEX(Currais!$K$3:$K$8,MATCH(B14,Currais!$A$3:$A$8,0)),0)) -> 0.45771 | J14: =IF(F14="","",F14*I14) -> 503.481 | K14: Estimado — rampa
A15: 46214 | B15: 2 | C15: 440 | D15: 220 | E15: 440 | F15: =IF(AND(C15="",D15="",E15=""),"",N(C15)+N(D15)+N(E15)) -> 1100 | G15: =IF(B15="","",IFERROR(INDEX(Currais!$C$3:$C$8,MATCH(B15,Currais!$A$3:$A$8,0)),"")) -> 38 | H15: =IF(OR(F15="",G15="",G15=0),"",F15/G15) -> 28.947368 | I15: =IF(F15="","",IFERROR(INDEX(Currais!$K$3:$K$8,MATCH(B15,Currais!$A$3:$A$8,0)),0)) -> 0.45771 | J15: =IF(F15="","",F15*I15) -> 503.481 | K15: Estimado — rampa
... A147: 46237 | B147: 4-TN | C147: 280 | D147: 140 | E147: 280 | F147: =IF(AND(C147="",D147="",E147=""),"",N(C147)+N(D147)+N(E147)) -> 700 | G147: =IF(B147="","",IFERROR(INDEX(Currais!$C$3:$C$8,MATCH(B147,Currais!$A$3:$A$8,0)),"")) -> 29 | H147: =IF(OR(F147="",G147="",G147=0),"",F147/G147) -> 24.137931 | I147: =IF(F147="","",IFERROR(INDEX(Currais!$K$3:$K$8,MATCH(B147,Currais!$A$3:$A$8,0)),0)) -> 0.66905 | J147: =IF(F147="","",F147*I147) -> 468.335 | K147: Estimado — constante
A148: 46238 | B148: 4-TN | C148: 280 | D148: 140 | E148: 280 | F148: =IF(AND(C148="",D148="",E148=""),"",N(C148)+N(D148)+N(E148)) -> 700 | G148: =IF(B148="","",IFERROR(INDEX(Currais!$C$3:$C$8,MATCH(B148,Currais!$A$3:$A$8,0)),"")) -> 29 | H148: =IF(OR(F148="",G148="",G148=0),"",F148/G148) -> 24.137931 | I148: =IF(F148="","",IFERROR(INDEX(Currais!$K$3:$K$8,MATCH(B148,Currais!$A$3:$A$8,0)),0)) -> 0.66905 | J148: =IF(F148="","",F148*I148) -> 468.335
A149: 46239 | B149: 4-TN | C149: 280 | D149: 140 | E149: 280 | F149: =IF(AND(C149="",D149="",E149=""),"",N(C149)+N(D149)+N(E149)) -> 700 | G149: =IF(B149="","",IFERROR(INDEX(Currais!$C$3:$C$8,MATCH(B149,Currais!$A$3:$A$8,0)),"")) -> 29 | H149: =IF(OR(F149="",G149="",G149=0),"",F149/G149) -> 24.137931 | I149: =IF(F149="","",IFERROR(INDEX(Currais!$K$3:$K$8,MATCH(B149,Currais!$A$3:$A$8,0)),0)) -> 0.66905 | J149: =IF(F149="","",F149*I149) -> 468.335
A150: 46240 | B150: 4-TN | C150: 280 | D150: 140 | E150: 280 | F150: =IF(AND(C150="",D150="",E150=""),"",N(C150)+N(D150)+N(E150)) -> 700 | G150: =IF(B150="","",IFERROR(INDEX(Currais!$C$3:$C$8,MATCH(B150,Currais!$A$3:$A$8,0)),"")) -> 29 | H150: =IF(OR(F150="",G150="",G150=0),"",F150/G150) -> 24.137931 | I150: =IF(F150="","",IFERROR(INDEX(Currais!$K$3:$K$8,MATCH(B150,Currais!$A$3:$A$8,0)),0)) -> 0.66905 | J150: =IF(F150="","",F150*I150) -> 468.335
A151: 46241 | B151: 4-TN | C151: 280 | D151: 140 | E151: 280 | F151: =IF(AND(C151="",D151="",E151=""),"",N(C151)+N(D151)+N(E151)) -> 700 | G151: =IF(B151="","",IFERROR(INDEX(Currais!$C$3:$C$8,MATCH(B151,Currais!$A$3:$A$8,0)),"")) -> 29 | H151: =IF(OR(F151="",G151="",G151=0),"",F151/G151) -> 24.137931 | I151: =IF(F151="","",IFERROR(INDEX(Currais!$K$3:$K$8,MATCH(B151,Currais!$A$3:$A$8,0)),0)) -> 0.66905 | J151: =IF(F151="","",F151*I151) -> 468.335
A152: 46242 | B152: 4-TN | C152: 280 | D152: 140 | E152: 280 | F152: =IF(AND(C152="",D152="",E152=""),"",N(C152)+N(D152)+N(E152)) -> 700 | G152: =IF(B152="","",IFERROR(INDEX(Currais!$C$3:$C$8,MATCH(B152,Currais!$A$3:$A$8,0)),"")) -> 29 | H152: =IF(OR(F152="",G152="",G152=0),"",F152/G152) -> 24.137931 | I152: =IF(F152="","",IFERROR(INDEX(Currais!$K$3:$K$8,MATCH(B152,Currais!$A$3:$A$8,0)),0)) -> 0.66905 | J152: =IF(F152="","",F152*I152) -> 468.335
A153: 46243 | B153: 4-TN | C153: 280 | D153: 140 | E153: 280 | F153: =IF(AND(C153="",D153="",E153=""),"",N(C153)+N(D153)+N(E153)) -> 700 | G153: =IF(B153="","",IFERROR(INDEX(Currais!$C$3:$C$8,MATCH(B153,Currais!$A$3:$A$8,0)),"")) -> 29 | H153: =IF(OR(F153="",G153="",G153=0),"",F153/G153) -> 24.137931 | I153: =IF(F153="","",IFERROR(INDEX(Currais!$K$3:$K$8,MATCH(B153,Currais!$A$3:$A$8,0)),0)) -> 0.66905 | J153: =IF(F153="","",F153*I153) -> 468.335
A154: 46244 | B154: 4-TN | C154: 280 | D154: 140 | E154: 280 | F154: =IF(AND(C154="",D154="",E154=""),"",N(C154)+N(D154)+N(E154)) -> 700 | G154: =IF(B154="","",IFERROR(INDEX(Currais!$C$3:$C$8,MATCH(B154,Currais!$A$3:$A$8,0)),"")) -> 29 | H154: =IF(OR(F154="",G154="",G154=0),"",F154/G154) -> 24.137931 | I154: =IF(F154="","",IFERROR(INDEX(Currais!$K$3:$K$8,MATCH(B154,Currais!$A$3:$A$8,0)),0)) -> 0.66905 | J154: =IF(F154="","",F154*I154) -> 468.335
A155: 46245 | B155: 4-TN | C155: 280 | D155: 140 | E155: 280 | F155: =IF(AND(C155="",D155="",E155=""),"",N(C155)+N(D155)+N(E155)) -> 700 | G155: =IF(B155="","",IFERROR(INDEX(Currais!$C$3:$C$8,MATCH(B155,Currais!$A$3:$A$8,0)),"")) -> 29 | H155: =IF(OR(F155="",G155="",G155=0),"",F155/G155) -> 24.137931 | I155: =IF(F155="","",IFERROR(INDEX(Currais!$K$3:$K$8,MATCH(B155,Currais!$A$3:$A$8,0)),0)) -> 0.66905 | J155: =IF(F155="","",F155*I155) -> 468.335
F156: =IF(AND(C156="",D156="",E156=""),"",N(C156)+N(D156)+N(E156)) | G156: =IF(B156="","",IFERROR(INDEX(Currais!$C$3:$C$8,MATCH(B156,Currais!$A$3:$A$8,0)),"")) | H156: =IF(OR(F156="",G156="",G156=0),"",F156/G156) | I156: =IF(F156="","",IFERROR(INDEX(Currais!$K$3:$K$8,MATCH(B156,Currais!$A$3:$A$8,0)),0)) | J156: =IF(F156="","",F156*I156)
F157: =IF(AND(C157="",D157="",E157=""),"",N(C157)+N(D157)+N(E157)) | G157: =IF(B157="","",IFERROR(INDEX(Currais!$C$3:$C$8,MATCH(B157,Currais!$A$3:$A$8,0)),"")) | H157: =IF(OR(F157="",G157="",G157=0),"",F157/G157) | I157: =IF(F157="","",IFERROR(INDEX(Currais!$K$3:$K$8,MATCH(B157,Currais!$A$3:$A$8,0)),0)) | J157: =IF(F157="","",F157*I157)
F158: =IF(AND(C158="",D158="",E158=""),"",N(C158)+N(D158)+N(E158)) | G158: =IF(B158="","",IFERROR(INDEX(Currais!$C$3:$C$8,MATCH(B158,Currais!$A$3:$A$8,0)),"")) | H158: =IF(OR(F158="",G158="",G158=0),"",F158/G158) | I158: =IF(F158="","",IFERROR(INDEX(Currais!$K$3:$K$8,MATCH(B158,Currais!$A$3:$A$8,0)),0)) | J158: =IF(F158="","",F158*I158)
F159: =IF(AND(C159="",D159="",E159=""),"",N(C159)+N(D159)+N(E159)) | G159: =IF(B159="","",IFERROR(INDEX(Currais!$C$3:$C$8,MATCH(B159,Currais!$A$3:$A$8,0)),"")) | H159: =IF(OR(F159="",G159="",G159=0),"",F159/G159) | I159: =IF(F159="","",IFERROR(INDEX(Currais!$K$3:$K$8,MATCH(B159,Currais!$A$3:$A$8,0)),0)) | J159: =IF(F159="","",F159*I159)
F160: =IF(AND(C160="",D160="",E160=""),"",N(C160)+N(D160)+N(E160)) | G160: =IF(B160="","",IFERROR(INDEX(Currais!$C$3:$C$8,MATCH(B160,Currais!$A$3:$A$8,0)),"")) | H160: =IF(OR(F160="",G160="",G160=0),"",F160/G160) | I160: =IF(F160="","",IFERROR(INDEX(Currais!$K$3:$K$8,MATCH(B160,Currais!$A$3:$A$8,0)),0)) | J160: =IF(F160="","",F160*I160)
F161: =IF(AND(C161="",D161="",E161=""),"",N(C161)+N(D161)+N(E161)) | G161: =IF(B161="","",IFERROR(INDEX(Currais!$C$3:$C$8,MATCH(B161,Currais!$A$3:$A$8,0)),"")) | H161: =IF(OR(F161="",G161="",G161=0),"",F161/G161) | I161: =IF(F161="","",IFERROR(INDEX(Currais!$K$3:$K$8,MATCH(B161,Currais!$A$3:$A$8,0)),0)) | J161: =IF(F161="","",F161*I161)
F162: =IF(AND(C162="",D162="",E162=""),"",N(C162)+N(D162)+N(E162)) | G162: =IF(B162="","",IFERROR(INDEX(Currais!$C$3:$C$8,MATCH(B162,Currais!$A$3:$A$8,0)),"")) | H162: =IF(OR(F162="",G162="",G162=0),"",F162/G162) | I162: =IF(F162="","",IFERROR(INDEX(Currais!$K$3:$K$8,MATCH(B162,Currais!$A$3:$A$8,0)),0)) | J162: =IF(F162="","",F162*I162)
F163: =IF(AND(C163="",D163="",E163=""),"",N(C163)+N(D163)+N(E163)) | G163: =IF(B163="","",IFERROR(INDEX(Currais!$C$3:$C$8,MATCH(B163,Currais!$A$3:$A$8,0)),"")) | H163: =IF(OR(F163="",G163="",G163=0),"",F163/G163) | I163: =IF(F163="","",IFERROR(INDEX(Currais!$K$3:$K$8,MATCH(B163,Currais!$A$3:$A$8,0)),0)) | J163: =IF(F163="","",F163*I163)
F164: =IF(AND(C164="",D164="",E164=""),"",N(C164)+N(D164)+N(E164)) | G164: =IF(B164="","",IFERROR(INDEX(Currais!$C$3:$C$8,MATCH(B164,Currais!$A$3:$A$8,0)),"")) | H164: =IF(OR(F164="",G164="",G164=0),"",F164/G164) | I164: =IF(F164="","",IFERROR(INDEX(Currais!$K$3:$K$8,MATCH(B164,Currais!$A$3:$A$8,0)),0)) | J164: =IF(F164="","",F164*I164)
F165: =IF(AND(C165="",D165="",E165=""),"",N(C165)+N(D165)+N(E165)) | G165: =IF(B165="","",IFERROR(INDEX(Currais!$C$3:$C$8,MATCH(B165,Currais!$A$3:$A$8,0)),"")) | H165: =IF(OR(F165="",G165="",G165=0),"",F165/G165) | I165: =IF(F165="","",IFERROR(INDEX(Currais!$K$3:$K$8,MATCH(B165,Currais!$A$3:$A$8,0)),0)) | J165: =IF(F165="","",F165*I165)
F166: =IF(AND(C166="",D166="",E166=""),"",N(C166)+N(D166)+N(E166)) | G166: =IF(B166="","",IFERROR(INDEX(Currais!$C$3:$C$8,MATCH(B166,Currais!$A$3:$A$8,0)),"")) | H166: =IF(OR(F166="",G166="",G166=0),"",F166/G166) | I166: =IF(F166="","",IFERROR(INDEX(Currais!$K$3:$K$8,MATCH(B166,Currais!$A$3:$A$8,0)),0)) | J166: =IF(F166="","",F166*I166)
F167: =IF(AND(C167="",D167="",E167=""),"",N(C167)+N(D167)+N(E167)) | G167: =IF(B167="","",IFERROR(INDEX(Currais!$C$3:$C$8,MATCH(B167,Currais!$A$3:$A$8,0)),"")) | H167: =IF(OR(F167="",G167="",G167=0),"",F167/G167) | I167: =IF(F167="","",IFERROR(INDEX(Currais!$K$3:$K$8,MATCH(B167,Currais!$A$3:$A$8,0)),0)) | J167: =IF(F167="","",F167*I167)
... F203: =IF(AND(C203="",D203="",E203=""),"",N(C203)+N(D203)+N(E203)) | G203: =IF(B203="","",IFERROR(INDEX(Currais!$C$3:$C$8,MATCH(B203,Currais!$A$3:$A$8,0)),"")) | H203: =IF(OR(F203="",G203="",G203=0),"",F203/G203) | I203: =IF(F203="","",IFERROR(INDEX(Currais!$K$3:$K$8,MATCH(B203,Currais!$A$3:$A$8,0)),0)) | J203: =IF(F203="","",F203*I203)

Sheet Custo_Nutricao_Lote
B2: CUSTO DE NUTRIÇÃO POR LOTE (CURRAL) — BG
B3: Estimativa = consumo planejado/dia (Calculadora) × dias de confinamento × custo da dieta do curral. Real = soma dos lançamentos do Trato_Diario. @ produzidas vêm das pesagens.
B5: Lote (Curral) | C5: Nº Cab | D5: Dias Conf | E5: Consumo Planej./dia (kg MN) | F5: Custo Dieta (R$/kg) | G5: Custo Ração/dia (R$) | H5: Custo/cab/dia (R$) | I5: Custo Estim. Acum. (R$) | J5: Custo Real Acum. (R$) | K5: Custo/cab Acum. (R$) | L5: @ Produzidas | M5: Custo Estim./@ (R$)
B6: 2 | C6: =IFERROR(INDEX(Currais!$C$3:$C$8,MATCH(B6,Currais!$A$3:$A$8,0)),0) -> 38 | D6: =IFERROR(Parâmetros!$C$4-_xlfn.MINIFS(Cadastro_Animais!$F$3:$F$5001,Cadastro_Animais!$E$3:$E$5001,B6),"") -> 43 | E6: =IFERROR(INDEX(Calculadora_Trato!$I$8:$I$13,MATCH(B6,Calculadora_Trato!$B$8:$B$13,0)),0) -> 503.28 | F6: =IFERROR(INDEX(Currais!$K$3:$K$8,MATCH(B6,Currais!$A$3:$A$8,0)),0) -> 0.45771 | G6: =E6*F6 -> 230.35629 | H6: =IF(C6=0,"",G6/C6) -> 6.0620076 | I6: =IF(D6="","",G6*D6) -> 9905.3204 | J6: =SUMIFS(Trato_Diario!$J$4:$J$203,Trato_Diario!$B$4:$B$203,B6) -> 18766.11 | K6: =IF(C6=0,"",I6/C6) -> 260.66633 | L6: =SUMIFS(Cadastro_Animais!$N$3:$N$5001,Cadastro_Animais!$E$3:$E$5001,B6) -> 0 | M6: =IF(L6<=0,"",I6/L6)
B7: 3 | C7: =IFERROR(INDEX(Currais!$C$3:$C$8,MATCH(B7,Currais!$A$3:$A$8,0)),0) -> 46 | D7: =IFERROR(Parâmetros!$C$4-_xlfn.MINIFS(Cadastro_Animais!$F$3:$F$5001,Cadastro_Animais!$E$3:$E$5001,B7),"") -> 43 | E7: =IFERROR(INDEX(Calculadora_Trato!$I$8:$I$13,MATCH(B7,Calculadora_Trato!$B$8:$B$13,0)),0) -> 575.136 | F7: =IFERROR(INDEX(Currais!$K$3:$K$8,MATCH(B7,Currais!$A$3:$A$8,0)),0) -> 0.45771 | G7: =E7*F7 -> 263.2455 | H7: =IF(C7=0,"",G7/C7) -> 5.7227282 | I7: =IF(D7="","",G7*D7) -> 11319.556 | J7: =SUMIFS(Trato_Diario!$J$4:$J$203,Trato_Diario!$B$4:$B$203,B7) -> 17164.125 | K7: =IF(C7=0,"",I7/C7) -> 246.07731 | L7: =SUMIFS(Cadastro_Animais!$N$3:$N$5001,Cadastro_Animais!$E$3:$E$5001,B7) -> 114.97467 | M7: =IF(L7<=0,"",I7/L7) -> 98.452614
B8: 4 | C8: =IFERROR(INDEX(Currais!$C$3:$C$8,MATCH(B8,Currais!$A$3:$A$8,0)),0) -> 165 | D8: =IFERROR(Parâmetros!$C$4-_xlfn.MINIFS(Cadastro_Animais!$F$3:$F$5001,Cadastro_Animais!$E$3:$E$5001,B8),"") -> 47 | E8: =IFERROR(INDEX(Calculadora_Trato!$I$8:$I$13,MATCH(B8,Calculadora_Trato!$B$8:$B$13,0)),0) -> 869.928 | F8: =IFERROR(INDEX(Currais!$K$3:$K$8,MATCH(B8,Currais!$A$3:$A$8,0)),0) -> 0.52245 | G8: =E8*F8 -> 454.49388 | H8: =IF(C8=0,"",G8/C8) -> 2.7545084 | I8: =IF(D8="","",G8*D8) -> 21361.213 | J8: =SUMIFS(Trato_Diario!$J$4:$J$203,Trato_Diario!$B$4:$B$203,B8) -> 45923.355 | K8: =IF(C8=0,"",I8/C8) -> 129.46189 | L8: =SUMIFS(Cadastro_Animais!$N$3:$N$5001,Cadastro_Animais!$E$3:$E$5001,B8) -> 0 | M8: =IF(L8<=0,"",I8/L8)
B9: 4-TN | C9: =IFERROR(INDEX(Currais!$C$3:$C$8,MATCH(B9,Currais!$A$3:$A$8,0)),0) -> 29 | D9: =IFERROR(Parâmetros!$C$4-_xlfn.MINIFS(Cadastro_Animais!$F$3:$F$5001,Cadastro_Animais!$E$3:$E$5001,B9),"") -> 43 | E9: =IFERROR(INDEX(Calculadora_Trato!$I$8:$I$13,MATCH(B9,Calculadora_Trato!$B$8:$B$13,0)),0) -> 388.872 | F9: =IFERROR(INDEX(Currais!$K$3:$K$8,MATCH(B9,Currais!$A$3:$A$8,0)),0) -> 0.66905 | G9: =E9*F9 -> 260.17481 | H9: =IF(C9=0,"",G9/C9) -> 8.9715452 | I9: =IF(D9="","",G9*D9) -> 11187.517 | J9: =SUMIFS(Trato_Diario!$J$4:$J$203,Trato_Diario!$B$4:$B$203,B9) -> 20138.405 | K9: =IF(C9=0,"",I9/C9) -> 385.77644 | L9: =SUMIFS(Cadastro_Animais!$N$3:$N$5001,Cadastro_Animais!$E$3:$E$5001,B9) -> 96.848667 | M9: =IF(L9<=0,"",I9/L9) -> 115.51545
B10: (a definir) | C10: =IFERROR(INDEX(Currais!$C$3:$C$8,MATCH(B10,Currais!$A$3:$A$8,0)),0) -> 70 | D10: =IFERROR(Parâmetros!$C$4-_xlfn.MINIFS(Cadastro_Animais!$F$3:$F$5001,Cadastro_Animais!$E$3:$E$5001,B10),"") -> 21 | E10: =IFERROR(INDEX(Calculadora_Trato!$I$8:$I$13,MATCH(B10,Calculadora_Trato!$B$8:$B$13,0)),0) -> 574.608 | F10: =IFERROR(INDEX(Currais!$K$3:$K$8,MATCH(B10,Currais!$A$3:$A$8,0)),0) -> 0.66905 | G10: =E10*F10 -> 384.44148 | H10: =IF(C10=0,"",G10/C10) -> 5.4920212 | I10: =IF(D10="","",G10*D10) -> 8073.2711 | J10: =SUMIFS(Trato_Diario!$J$4:$J$203,Trato_Diario!$B$4:$B$203,B10) -> 0 | K10: =IF(C10=0,"",I10/C10) -> 115.33244 | L10: =SUMIFS(Cadastro_Animais!$N$3:$N$5001,Cadastro_Animais!$E$3:$E$5001,B10) -> 0 | M10: =IF(L10<=0,"",I10/L10)
B11: 5 | C11: =IFERROR(INDEX(Currais!$C$3:$C$8,MATCH(B11,Currais!$A$3:$A$8,0)),0) -> 37 | D11: =IFERROR(Parâmetros!$C$4-_xlfn.MINIFS(Cadastro_Animais!$F$3:$F$5001,Cadastro_Animais!$E$3:$E$5001,B11),"") -> 14 | E11: =IFERROR(INDEX(Calculadora_Trato!$I$8:$I$13,MATCH(B11,Calculadora_Trato!$B$8:$B$13,0)),0) -> 312.12 | F11: =IFERROR(INDEX(Currais!$K$3:$K$8,MATCH(B11,Currais!$A$3:$A$8,0)),0) -> 0.57515 | G11: =E11*F11 -> 179.51582 | H11: =IF(C11=0,"",G11/C11) -> 4.8517789 | I11: =IF(D11="","",G11*D11) -> 2513.2215 | J11: =SUMIFS(Trato_Diario!$J$4:$J$203,Trato_Diario!$B$4:$B$203,B11) -> 0 | K11: =IF(C11=0,"",I11/C11) -> 67.924904 | L11: =SUMIFS(Cadastro_Animais!$N$3:$N$5001,Cadastro_Animais!$E$3:$E$5001,B11) -> 0 | M11: =IF(L11<=0,"",I11/L11)
B12: TOTAL | C12: =SUM(C6:C11) -> 385 | G12: =SUM(G6:G11) -> 1772.2278 | H12: =IF(C12=0,"",G12/C12) -> 4.603189 | I12: =SUM(I6:I11) -> 64360.099 | J12: =SUM(J6:J11) -> 101992 | K12: =IF(C12=0,"",I12/C12) -> 167.16909 | L12: =SUM(L6:L11) -> 211.82333 | M12: =IF(L12<=0,"",I12/L12) -> 303.83857

Sheet Custo_Diario_Cab
A1: CUSTO MÉDIO DIÁRIO DE RAÇÃO POR CABEÇA — POR CURRAL (BG)
A2: Custo REAL de ração por cabeça por dia (custo do trato do dia ÷ nº de cabeças). A MÉDIA DIÁRIA = custo total do período ÷ (dias × cabeças) de cada curral. Atualiza conforme você lança tratos. Novilhas e Descarte aparecem quando você lançar os tratos deles.
B4: 2 — Bonsmara R1 | C4: 3 — Bonsmara R2 | D4: 4 — Bezerros | E4: 4-TN — Nelore | F4: Novilhas | G4: 5 — Descarte | H4: Rebanho
A5: Curral (ref.) | B5: 2 | C5: 3 | D5: 4 | E5: 4-TN | F5: (a definir) | G5: 5
A6: Nº cabeças | B6: =IFERROR(INDEX(Currais!$C$3:$C$8,MATCH(B$5,Currais!$A$3:$A$8,0)),0) -> 38 | C6: =IFERROR(INDEX(Currais!$C$3:$C$8,MATCH(C$5,Currais!$A$3:$A$8,0)),0) -> 46 | D6: =IFERROR(INDEX(Currais!$C$3:$C$8,MATCH(D$5,Currais!$A$3:$A$8,0)),0) -> 165 | E6: =IFERROR(INDEX(Currais!$C$3:$C$8,MATCH(E$5,Currais!$A$3:$A$8,0)),0) -> 29 | F6: =IFERROR(INDEX(Currais!$C$3:$C$8,MATCH(F$5,Currais!$A$3:$A$8,0)),0) -> 70 | G6: =IFERROR(INDEX(Currais!$C$3:$C$8,MATCH(G$5,Currais!$A$3:$A$8,0)),0) -> 37 | H6: =SUM(B6:G6) -> 385
A7: Dias com trato | B7: =COUNTIFS(Trato_Diario!$B$4:$B$203,B$5,Trato_Diario!$F$4:$F$203,"<>") -> 35 | C7: =COUNTIFS(Trato_Diario!$B$4:$B$203,C$5,Trato_Diario!$F$4:$F$203,"<>") -> 35 | D7: =COUNTIFS(Trato_Diario!$B$4:$B$203,D$5,Trato_Diario!$F$4:$F$203,"<>") -> 39 | E7: =COUNTIFS(Trato_Diario!$B$4:$B$203,E$5,Trato_Diario!$F$4:$F$203,"<>") -> 43 | F7: =COUNTIFS(Trato_Diario!$B$4:$B$203,F$5,Trato_Diario!$F$4:$F$203,"<>") -> 0 | G7: =COUNTIFS(Trato_Diario!$B$4:$B$203,G$5,Trato_Diario!$F$4:$F$203,"<>") -> 0
A8: MÉDIA DIÁRIA (R$/cab/dia) | B8: =IFERROR(SUMIFS(Trato_Diario!$J$4:$J$203,Trato_Diario!$B$4:$B$203,B$5)/SUMIFS(Trato_Diario!$G$4:$G$203,Trato_Diario!$B$4:$B$203,B$5),"") -> 14.109857 | C8: =IFERROR(SUMIFS(Trato_Diario!$J$4:$J$203,Trato_Diario!$B$4:$B$203,C$5)/SUMIFS(Trato_Diario!$G$4:$G$203,Trato_Diario!$B$4:$B$203,C$5),"") -> 10.660947 | D8: =IFERROR(SUMIFS(Trato_Diario!$J$4:$J$203,Trato_Diario!$B$4:$B$203,D$5)/SUMIFS(Trato_Diario!$G$4:$G$203,Trato_Diario!$B$4:$B$203,D$5),"") -> 7.1364965 | E8: =IFERROR(SUMIFS(Trato_Diario!$J$4:$J$203,Trato_Diario!$B$4:$B$203,E$5)/SUMIFS(Trato_Diario!$G$4:$G$203,Trato_Diario!$B$4:$B$203,E$5),"") -> 16.149483 | F8: =IFERROR(SUMIFS(Trato_Diario!$J$4:$J$203,Trato_Diario!$B$4:$B$203,F$5)/SUMIFS(Trato_Diario!$G$4:$G$203,Trato_Diario!$B$4:$B$203,F$5),"") | G8: =IFERROR(SUMIFS(Trato_Diario!$J$4:$J$203,Trato_Diario!$B$4:$B$203,G$5)/SUMIFS(Trato_Diario!$G$4:$G$203,Trato_Diario!$B$4:$B$203,G$5),"") | H8: =IFERROR(SUM(Trato_Diario!$J$4:$J$203)/SUM(Trato_Diario!$G$4:$G$203),"") -> 9.6019577
A10: DETALHE DIA A DIA — custo do dia por cabeça (R$/cab/dia)
A11: Data | B11: 2 — Bonsmara R1 | C11: 3 — Bonsmara R2 | D11: 4 — Bezerros | E11: 4-TN — Nelore | F11: Novilhas | G11: 5 — Descarte | H11: Rebanho
A12: 46199 | B12: =IF(OR($A12>MAX(Trato_Diario!$A$4:$A$203),SUMIFS(Trato_Diario!$G$4:$G$203,Trato_Diario!$B$4:$B$203,B$5,Trato_Diario!$A$4:$A$203,$A12)=0),"",SUMIFS(Trato_Diario!$J$4:$J$203,Trato_Diario!$B$4:$B$203,B$5,Trato_Diario!$A$4:$A$203,$A12)/SUMIFS(Trato_Diario!$G$4:$G$203,Trato_Diario!$B$4:$B$203,B$5,Trato_Diario!$A$4:$A$203,$A12)) | C12: =IF(OR($A12>MAX(Trato_Diario!$A$4:$A$203),SUMIFS(Trato_Diario!$G$4:$G$203,Trato_Diario!$B$4:$B$203,C$5,Trato_Diario!$A$4:$A$203,$A12)=0),"",SUMIFS(Trato_Diario!$J$4:$J$203,Trato_Diario!$B$4:$B$203,C$5,Trato_Diario!$A$4:$A$203,$A12)/SUMIFS(Trato_Diario!$G$4:$G$203,Trato_Diario!$B$4:$B$203,C$5,Trato_Diario!$A$4:$A$203,$A12)) | D12: =IF(OR($A12>MAX(Trato_Diario!$A$4:$A$203),SUMIFS(Trato_Diario!$G$4:$G$203,Trato_Diario!$B$4:$B$203,D$5,Trato_Diario!$A$4:$A$203,$A12)=0),"",SUMIFS(Trato_Diario!$J$4:$J$203,Trato_Diario!$B$4:$B$203,D$5,Trato_Diario!$A$4:$A$203,$A12)/SUMIFS(Trato_Diario!$G$4:$G$203,Trato_Diario!$B$4:$B$203,D$5,Trato_Diario!$A$4:$A$203,$A12)) -> 5.3828182 | E12: =IF(OR($A12>MAX(Trato_Diario!$A$4:$A$203),SUMIFS(Trato_Diario!$G$4:$G$203,Trato_Diario!$B$4:$B$203,E$5,Trato_Diario!$A$4:$A$203,$A12)=0),"",SUMIFS(Trato_Diario!$J$4:$J$203,Trato_Diario!$B$4:$B$203,E$5,Trato_Diario!$A$4:$A$203,$A12)/SUMIFS(Trato_Diario!$G$4:$G$203,Trato_Diario!$B$4:$B$203,E$5,Trato_Diario!$A$4:$A$203,$A12)) | F12: =IF(OR($A12>MAX(Trato_Diario!$A$4:$A$203),SUMIFS(Trato_Diario!$G$4:$G$203,Trato_Diario!$B$4:$B$203,F$5,Trato_Diario!$A$4:$A$203,$A12)=0),"",SUMIFS(Trato_Diario!$J$4:$J$203,Trato_Diario!$B$4:$B$203,F$5,Trato_Diario!$A$4:$A$203,$A12)/SUMIFS(Trato_Diario!$G$4:$G$203,Trato_Diario!$B$4:$B$203,F$5,Trato_Diario!$A$4:$A$203,$A12)) | G12: =IF(OR($A12>MAX(Trato_Diario!$A$4:$A$203),SUMIFS(Trato_Diario!$G$4:$G$203,Trato_Diario!$B$4:$B$203,G$5,Trato_Diario!$A$4:$A$203,$A12)=0),"",SUMIFS(Trato_Diario!$J$4:$J$203,Trato_Diario!$B$4:$B$203,G$5,Trato_Diario!$A$4:$A$203,$A12)/SUMIFS(Trato_Diario!$G$4:$G$203,Trato_Diario!$B$4:$B$203,G$5,Trato_Diario!$A$4:$A$203,$A12)) | H12: =IF(OR($A12>MAX(Trato_Diario!$A$4:$A$203),SUMIFS(Trato_Diario!$G$4:$G$203,Trato_Diario!$A$4:$A$203,$A12)=0),"",SUMIFS(Trato_Diario!$J$4:$J$203,Trato_Diario!$A$4:$A$203,$A12)/SUMIFS(Trato_Diario!$G$4:$G$203,Trato_Diario!$A$4:$A$203,$A12)) -> 5.3828182
A13: 46200 | B13: =IF(OR($A13>MAX(Trato_Diario!$A$4:$A$203),SUMIFS(Trato_Diario!$G$4:$G$203,Trato_Diario!$B$4:$B$203,B$5,Trato_Diario!$A$4:$A$203,$A13)=0),"",SUMIFS(Trato_Diario!$J$4:$J$203,Trato_Diario!$B$4:$B$203,B$5,Trato_Diario!$A$4:$A$203,$A13)/SUMIFS(Trato_Diario!$G$4:$G$203,Trato_Diario!$B$4:$B$203,B$5,Trato_Diario!$A$4:$A$203,$A13)) | C13: =IF(OR($A13>MAX(Trato_Diario!$A$4:$A$203),SUMIFS(Trato_Diario!$G$4:$G$203,Trato_Diario!$B$4:$B$203,C$5,Trato_Diario!$A$4:$A$203,$A13)=0),"",SUMIFS(Trato_Diario!$J$4:$J$203,Trato_Diario!$B$4:$B$203,C$5,Trato_Diario!$A$4:$A$203,$A13)/SUMIFS(Trato_Diario!$G$4:$G$203,Trato_Diario!$B$4:$B$203,C$5,Trato_Diario!$A$4:$A$203,$A13)) | D13: =IF(OR($A13>MAX(Trato_Diario!$A$4:$A$203),SUMIFS(Trato_Diario!$G$4:$G$203,Trato_Diario!$B$4:$B$203,D$5,Trato_Diario!$A$4:$A$203,$A13)=0),"",SUMIFS(Trato_Diario!$J$4:$J$203,Trato_Diario!$B$4:$B$203,D$5,Trato_Diario!$A$4:$A$203,$A13)/SUMIFS(Trato_Diario!$G$4:$G$203,Trato_Diario!$B$4:$B$203,D$5,Trato_Diario!$A$4:$A$203,$A13)) -> 5.3828182 | E13: =IF(OR($A13>MAX(Trato_Diario!$A$4:$A$203),SUMIFS(Trato_Diario!$G$4:$G$203,Trato_Diario!$B$4:$B$203,E$5,Trato_Diario!$A$4:$A$203,$A13)=0),"",SUMIFS(Trato_Diario!$J$4:$J$203,Trato_Diario!$B$4:$B$203,E$5,Trato_Diario!$A$4:$A$203,$A13)/SUMIFS(Trato_Diario!$G$4:$G$203,Trato_Diario!$B$4:$B$203,E$5,Trato_Diario!$A$4:$A$203,$A13)) | F13: =IF(OR($A13>MAX(Trato_Diario!$A$4:$A$203),SUMIFS(Trato_Diario!$G$4:$G$203,Trato_Diario!$B$4:$B$203,F$5,Trato_Diario!$A$4:$A$203,$A13)=0),"",SUMIFS(Trato_Diario!$J$4:$J$203,Trato_Diario!$B$4:$B$203,F$5,Trato_Diario!$A$4:$A$203,$A13)/SUMIFS(Trato_Diario!$G$4:$G$203,Trato_Diario!$B$4:$B$203,F$5,Trato_Diario!$A$4:$A$203,$A13)) | G13: =IF(OR($A13>MAX(Trato_Diario!$A$4:$A$203),SUMIFS(Trato_Diario!$G$4:$G$203,Trato_Diario!$B$4:$B$203,G$5,Trato_Diario!$A$4:$A$203,$A13)=0),"",SUMIFS(Trato_Diario!$J$4:$J$203,Trato_Diario!$B$4:$B$203,G$5,Trato_Diario!$A$4:$A$203,$A13)/SUMIFS(Trato_Diario!$G$4:$G$203,Trato_Diario!$B$4:$B$203,G$5,Trato_Diario!$A$4:$A$203,$A13)) | H13: =IF(OR($A13>MAX(Trato_Diario!$A$4:$A$203),SUMIFS(Trato_Diario!$G$4:$G$203,Trato_Diario!$A$4:$A$203,$A13)=0),"",SUMIFS(Trato_Diario!$J$4:$J$203,Trato_Diario!$A$4:$A$203,$A13)/SUMIFS(Trato_Diario!$G$4:$G$203,Trato_Diario!$A$4:$A$203,$A13)) -> 5.3828182
A14: 46201 | B14: =IF(OR($A14>MAX(Trato_Diario!$A$4:$A$203),SUMIFS(Trato_Diario!$G$4:$G$203,Trato_Diario!$B$4:$B$203,B$5,Trato_Diario!$A$4:$A$203,$A14)=0),"",SUMIFS(Trato_Diario!$J$4:$J$203,Trato_Diario!$B$4:$B$203,B$5,Trato_Diario!$A$4:$A$203,$A14)/SUMIFS(Trato_Diario!$G$4:$G$203,Trato_Diario!$B$4:$B$203,B$5,Trato_Diario!$A$4:$A$203,$A14)) | C14: =IF(OR($A14>MAX(Trato_Diario!$A$4:$A$203),SUMIFS(Trato_Diario!$G$4:$G$203,Trato_Diario!$B$4:$B$203,C$5,Trato_Diario!$A$4:$A$203,$A14)=0),"",SUMIFS(Trato_Diario!$J$4:$J$203,Trato_Diario!$B$4:$B$203,C$5,Trato_Diario!$A$4:$A$203,$A14)/SUMIFS(Trato_Diario!$G$4:$G$203,Trato_Diario!$B$4:$B$203,C$5,Trato_Diario!$A$4:$A$203,$A14)) | D14: =IF(OR($A14>MAX(Trato_Diario!$A$4:$A$203),SUMIFS(Trato_Diario!$G$4:$G$203,Trato_Diario!$B$4:$B$203,D$5,Trato_Diario!$A$4:$A$203,$A14)=0),"",SUMIFS(Trato_Diario!$J$4:$J$203,Trato_Diario!$B$4:$B$203,D$5,Trato_Diario!$A$4:$A$203,$A14)/SUMIFS(Trato_Diario!$G$4:$G$203,Trato_Diario!$B$4:$B$203,D$5,Trato_Diario!$A$4:$A$203,$A14)) -> 5.3828182 | E14: =IF(OR($A14>MAX(Trato_Diario!$A$4:$A$203),SUMIFS(Trato_Diario!$G$4:$G$203,Trato_Diario!$B$4:$B$203,E$5,Trato_Diario!$A$4:$A$203,$A14)=0),"",SUMIFS(Trato_Diario!$J$4:$J$203,Trato_Diario!$B$4:$B$203,E$5,Trato_Diario!$A$4:$A$203,$A14)/SUMIFS(Trato_Diario!$G$4:$G$203,Trato_Diario!$B$4:$B$203,E$5,Trato_Diario!$A$4:$A$203,$A14)) | F14: =IF(OR($A14>MAX(Trato_Diario!$A$4:$A$203),SUMIFS(Trato_Diario!$G$4:$G$203,Trato_Diario!$B$4:$B$203,F$5,Trato_Diario!$A$4:$A$203,$A14)=0),"",SUMIFS(Trato_Diario!$J$4:$J$203,Trato_Diario!$B$4:$B$203,F$5,Trato_Diario!$A$4:$A$203,$A14)/SUMIFS(Trato_Diario!$G$4:$G$203,Trato_Diario!$B$4:$B$203,F$5,Trato_Diario!$A$4:$A$203,$A14)) | G14: =IF(OR($A14>MAX(Trato_Diario!$A$4:$A$203),SUMIFS(Trato_Diario!$G$4:$G$203,Trato_Diario!$B$4:$B$203,G$5,Trato_Diario!$A$4:$A$203,$A14)=0),"",SUMIFS(Trato_Diario!$J$4:$J$203,Trato_Diario!$B$4:$B$203,G$5,Trato_Diario!$A$4:$A$203,$A14)/SUMIFS(Trato_Diario!$G$4:$G$203,Trato_Diario!$B$4:$B$203,G$5,Trato_Diario!$A$4:$A$203,$A14)) | H14: =IF(OR($A14>MAX(Trato_Diario!$A$4:$A$203),SUMIFS(Trato_Diario!$G$4:$G$203,Trato_Diario!$A$4:$A$203,$A14)=0),"",SUMIFS(Trato_Diario!$J$4:$J$203,Trato_Diario!$A$4:$A$203,$A14)/SUMIFS(Trato_Diario!$G$4:$G$203,Trato_Diario!$A$4:$A$203,$A14)) -> 5.3828182
A15: 46202 | B15: =IF(OR($A15>MAX(Trato_Diario!$A$4:$A$203),SUMIFS(Trato_Diario!$G$4:$G$203,Trato_Diario!$B$4:$B$203,B$5,Trato_Diario!$A$4:$A$203,$A15)=0),"",SUMIFS(Trato_Diario!$J$4:$J$203,Trato_Diario!$B$4:$B$203,B$5,Trato_Diario!$A$4:$A$203,$A15)/SUMIFS(Trato_Diario!$G$4:$G$203,Trato_Diario!$B$4:$B$203,B$5,Trato_Diario!$A$4:$A$203,$A15)) | C15: =IF(OR($A15>MAX(Trato_Diario!$A$4:$A$203),SUMIFS(Trato_Diario!$G$4:$G$203,Trato_Diario!$B$4:$B$203,C$5,Trato_Diario!$A$4:$A$203,$A15)=0),"",SUMIFS(Trato_Diario!$J$4:$J$203,Trato_Diario!$B$4:$B$203,C$5,Trato_Diario!$A$4:$A$203,$A15)/SUMIFS(Trato_Diario!$G$4:$G$203,Trato_Diario!$B$4:$B$203,C$5,Trato_Diario!$A$4:$A$203,$A15)) | D15: =IF(OR($A15>MAX(Trato_Diario!$A$4:$A$203),SUMIFS(Trato_Diario!$G$4:$G$203,Trato_Diario!$B$4:$B$203,D$5,Trato_Diario!$A$4:$A$203,$A15)=0),"",SUMIFS(Trato_Diario!$J$4:$J$203,Trato_Diario!$B$4:$B$203,D$5,Trato_Diario!$A$4:$A$203,$A15)/SUMIFS(Trato_Diario!$G$4:$G$203,Trato_Diario!$B$4:$B$203,D$5,Trato_Diario!$A$4:$A$203,$A15)) -> 5.6994545 | E15: =IF(OR($A15>MAX(Trato_Diario!$A$4:$A$203),SUMIFS(Trato_Diario!$G$4:$G$203,Trato_Diario!$B$4:$B$203,E$5,Trato_Diario!$A$4:$A$203,$A15)=0),"",SUMIFS(Trato_Diario!$J$4:$J$203,Trato_Diario!$B$4:$B$203,E$5,Trato_Diario!$A$4:$A$203,$A15)/SUMIFS(Trato_Diario!$G$4:$G$203,Trato_Diario!$B$4:$B$203,E$5,Trato_Diario!$A$4:$A$203,$A15)) | F15: =IF(OR($A15>MAX(Trato_Diario!$A$4:$A$203),SUMIFS(Trato_Diario!$G$4:$G$203,Trato_Diario!$B$4:$B$203,F$5,Trato_Diario!$A$4:$A$203,$A15)=0),"",SUMIFS(Trato_Diario!$J$4:$J$203,Trato_Diario!$B$4:$B$203,F$5,Trato_Diario!$A$4:$A$203,$A15)/SUMIFS(Trato_Diario!$G$4:$G$203,Trato_Diario!$B$4:$B$203,F$5,Trato_Diario!$A$4:$A$203,$A15)) | G15: =IF(OR($A15>MAX(Trato_Diario!$A$4:$A$203),SUMIFS(Trato_Diario!$G$4:$G$203,Trato_Diario!$B$4:$B$203,G$5,Trato_Diario!$A$4:$A$203,$A15)=0),"",SUMIFS(Trato_Diario!$J$4:$J$203,Trato_Diario!$B$4:$B$203,G$5,Trato_Diario!$A$4:$A$203,$A15)/SUMIFS(Trato_Diario!$G$4:$G$203,Trato_Diario!$B$4:$B$203,G$5,Trato_Diario!$A$4:$A$203,$A15)) | H15: =IF(OR($A15>MAX(Trato_Diario!$A$4:$A$203),SUMIFS(Trato_Diario!$G$4:$G$203,Trato_Diario!$A$4:$A$203,$A15)=0),"",SUMIFS(Trato_Diario!$J$4:$J$203,Trato_Diario!$A$4:$A$203,$A15)/SUMIFS(Trato_Diario!$G$4:$G$203,Trato_Diario!$A$4:$A$203,$A15)) -> 5.6994545
A16: 46203 | B16: =IF(OR($A16>MAX(Trato_Diario!$A$4:$A$203),SUMIFS(Trato_Diario!$G$4:$G$203,Trato_Diario!$B$4:$B$203,B$5,Trato_Diario!$A$4:$A$203,$A16)=0),"",SUMIFS(Trato_Diario!$J$4:$J$203,Trato_Diario!$B$4:$B$203,B$5,Trato_Diario!$A$4:$A$203,$A16)/SUMIFS(Trato_Diario!$G$4:$G$203,Trato_Diario!$B$4:$B$203,B$5,Trato_Diario!$A$4:$A$203,$A16)) -> 9.636 | C16: =IF(OR($A16>MAX(Trato_Diario!$A$4:$A$203),SUMIFS(Trato_Diario!$G$4:$G$203,Trato_Diario!$B$4:$B$203,C$5,Trato_Diario!$A$4:$A$203,$A16)=0),"",SUMIFS(Trato_Diario!$J$4:$J$203,Trato_Diario!$B$4:$B$203,C$5,Trato_Diario!$A$4:$A$203,$A16)/SUMIFS(Trato_Diario!$G$4:$G$203,Trato_Diario!$B$4:$B$203,C$5,Trato_Diario!$A$4:$A$203,$A16)) -> 6.9651522 | D16: =IF(OR($A16>MAX(Trato_Diario!$A$4:$A$203),SUMIFS(Trato_Diario!$G$4:$G$203,Trato_Diario!$B$4:$B$203,D$5,Trato_Diario!$A$4:$A$203,$A16)=0),"",SUMIFS(Trato_Diario!$J$4:$J$203,Trato_Diario!$B$4:$B$203,D$5,Trato_Diario!$A$4:$A$203,$A16)/SUMIFS(Trato_Diario!$G$4:$G$203,Trato_Diario!$B$4:$B$203,D$5,Trato_Diario!$A$4:$A$203,$A16)) -> 5.6994545 | E16: =IF(OR($A16>MAX(Trato_Diario!$A$4:$A$203),SUMIFS(Trato_Diario!$G$4:$G$203,Trato_Diario!$B$4:$B$203,E$5,Trato_Diario!$A$4:$A$203,$A16)=0),"",SUMIFS(Trato_Diario!$J$4:$J$203,Trato_Diario!$B$4:$B$203,E$5,Trato_Diario!$A$4:$A$203,$A16)/SUMIFS(Trato_Diario!$G$4:$G$203,Trato_Diario!$B$4:$B$203,E$5,Trato_Diario!$A$4:$A$203,$A16)) -> 16.149483 | F16: =IF(OR($A16>MAX(Trato_Diario!$A$4:$A$203),SUMIFS(Trato_Diario!$G$4:$G$203,Trato_Diario!$B$4:$B$203,F$5,Trato_Diario!$A$4:$A$203,$A16)=0),"",SUMIFS(Trato_Diario!$J$4:$J$203,Trato_Diario!$B$4:$B$203,F$5,Trato_Diario!$A$4:$A$203,$A16)/SUMIFS(Trato_Diario!$G$4:$G$203,Trato_Diario!$B$4:$B$203,F$5,Trato_Diario!$A$4:$A$203,$A16)) | G16: =IF(OR($A16>MAX(Trato_Diario!$A$4:$A$203),SUMIFS(Trato_Diario!$G$4:$G$203,Trato_Diario!$B$4:$B$203,G$5,Trato_Diario!$A$4:$A$203,$A16)=0),"",SUMIFS(Trato_Diario!$J$4:$J$203,Trato_Diario!$B$4:$B$203,G$5,Trato_Diario!$A$4:$A$203,$A16)/SUMIFS(Trato_Diario!$G$4:$G$203,Trato_Diario!$B$4:$B$203,G$5,Trato_Diario!$A$4:$A$203,$A16)) | H16: =IF(OR($A16>MAX(Trato_Diario!$A$4:$A$203),SUMIFS(Trato_Diario!$G$4:$G$203,Trato_Diario!$A$4:$A$203,$A16)=0),"",SUMIFS(Trato_Diario!$J$4:$J$203,Trato_Diario!$A$4:$A$203,$A16)/SUMIFS(Trato_Diario!$G$4:$G$203,Trato_Diario!$A$4:$A$203,$A16)) -> 7.5370863
A17: 46204 | B17: =IF(OR($A17>MAX(Trato_Diario!$A$4:$A$203),SUMIFS(Trato_Diario!$G$4:$G$203,Trato_Diario!$B$4:$B$203,B$5,Trato_Diario!$A$4:$A$203,$A17)=0),"",SUMIFS(Trato_Diario!$J$4:$J$203,Trato_Diario!$B$4:$B$203,B$5,Trato_Diario!$A$4:$A$203,$A17)/SUMIFS(Trato_Diario!$G$4:$G$203,Trato_Diario!$B$4:$B$203,B$5,Trato_Diario!$A$4:$A$203,$A17)) -> 9.636 | C17: =IF(OR($A17>MAX(Trato_Diario!$A$4:$A$203),SUMIFS(Trato_Diario!$G$4:$G$203,Trato_Diario!$B$4:$B$203,C$5,Trato_Diario!$A$4:$A$203,$A17)=0),"",SUMIFS(Trato_Diario!$J$4:$J$203,Trato_Diario!$B$4:$B$203,C$5,Trato_Diario!$A$4:$A$203,$A17)/SUMIFS(Trato_Diario!$G$4:$G$203,Trato_Diario!$B$4:$B$203,C$5,Trato_Diario!$A$4:$A$203,$A17)) -> 6.9651522 | D17: =IF(OR($A17>MAX(Trato_Diario!$A$4:$A$203),SUMIFS(Trato_Diario!$G$4:$G$203,Trato_Diario!$B$4:$B$203,D$5,Trato_Diario!$A$4:$A$203,$A17)=0),"",SUMIFS(Trato_Diario!$J$4:$J$203,Trato_Diario!$B$4:$B$203,D$5,Trato_Diario!$A$4:$A$203,$A17)/SUMIFS(Trato_Diario!$G$4:$G$203,Trato_Diario!$B$4:$B$203,D$5,Trato_Diario!$A$4:$A$203,$A17)) -> 5.6994545 | E17: =IF(OR($A17>MAX(Trato_Diario!$A$4:$A$203),SUMIFS(Trato_Diario!$G$4:$G$203,Trato_Diario!$B$4:$B$203,E$5,Trato_Diario!$A$4:$A$203,$A17)=0),"",SUMIFS(Trato_Diario!$J$4:$J$203,Trato_Diario!$B$4:$B$203,E$5,Trato_Diario!$A$4:$A$203,$A17)/SUMIFS(Trato_Diario!$G$4:$G$203,Trato_Diario!$B$4:$B$203,E$5,Trato_Diario!$A$4:$A$203,$A17)) -> 16.149483 | F17: =IF(OR($A17>MAX(Trato_Diario!$A$4:$A$203),SUMIFS(Trato_Diario!$G$4:$G$203,Trato_Diario!$B$4:$B$203,F$5,Trato_Diario!$A$4:$A$203,$A17)=0),"",SUMIFS(Trato_Diario!$J$4:$J$203,Trato_Diario!$B$4:$B$203,F$5,Trato_Diario!$A$4:$A$203,$A17)/SUMIFS(Trato_Diario!$G$4:$G$203,Trato_Diario!$B$4:$B$203,F$5,Trato_Diario!$A$4:$A$203,$A17)) | G17: =IF(OR($A17>MAX(Trato_Diario!$A$4:$A$203),SUMIFS(Trato_Diario!$G$4:$G$203,Trato_Diario!$B$4:$B$203,G$5,Trato_Diario!$A$4:$A$203,$A17)=0),"",SUMIFS(Trato_Diario!$J$4:$J$203,Trato_Diario!$B$4:$B$203,G$5,Trato_Diario!$A$4:$A$203,$A17)/SUMIFS(Trato_Diario!$G$4:$G$203,Trato_Diario!$B$4:$B$203,G$5,Trato_Diario!$A$4:$A$203,$A17)) | H17: =IF(OR($A17>MAX(Trato_Diario!$A$4:$A$203),SUMIFS(Trato_Diario!$G$4:$G$203,Trato_Diario!$A$4:$A$203,$A17)=0),"",SUMIFS(Trato_Diario!$J$4:$J$203,Trato_Diario!$A$4:$A$203,$A17)/SUMIFS(Trato_Diario!$G$4:$G$203,Trato_Diario!$A$4:$A$203,$A17)) -> 7.5370863
A18: 46205 | B18: =IF(OR($A18>MAX(Trato_Diario!$A$4:$A$203),SUMIFS(Trato_Diario!$G$4:$G$203,Trato_Diario!$B$4:$B$203,B$5,Trato_Diario!$A$4:$A$203,$A18)=0),"",SUMIFS(Trato_Diario!$J$4:$J$203,Trato_Diario!$B$4:$B$203,B$5,Trato_Diario!$A$4:$A$203,$A18)/SUMIFS(Trato_Diario!$G$4:$G$203,Trato_Diario!$B$4:$B$203,B$5,Trato_Diario!$A$4:$A$203,$A18)) -> 9.636 | C18: =IF(OR($A18>MAX(Trato_Diario!$A$4:$A$203),SUMIFS(Trato_Diario!$G$4:$G$203,Trato_Diario!$B$4:$B$203,C$5,Trato_Diario!$A$4:$A$203,$A18)=0),"",SUMIFS(Trato_Diario!$J$4:$J$203,Trato_Diario!$B$4:$B$203,C$5,Trato_Diario!$A$4:$A$203,$A18)/SUMIFS(Trato_Diario!$G$4:$G$203,Trato_Diario!$B$4:$B$203,C$5,Trato_Diario!$A$4:$A$203,$A18)) -> 6.9651522 | D18: =IF(OR($A18>MAX(Trato_Diario!$A$4:$A$203),SUMIFS(Trato_Diario!$G$4:$G$203,Trato_Diario!$B$4:$B$203,D$5,Trato_Diario!$A$4:$A$203,$A18)=0),"",SUMIFS(Trato_Diario!$J$4:$J$203,Trato_Diario!$B$4:$B$203,D$5,Trato_Diario!$A$4:$A$203,$A18)/SUMIFS(Trato_Diario!$G$4:$G$203,Trato_Diario!$B$4:$B$203,D$5,Trato_Diario!$A$4:$A$203,$A18)) -> 6.0160909 | E18: =IF(OR($A18>MAX(Trato_Diario!$A$4:$A$203),SUMIFS(Trato_Diario!$G$4:$G$203,Trato_Diario!$B$4:$B$203,E$5,Trato_Diario!$A$4:$A$203,$A18)=0),"",SUMIFS(Trato_Diario!$J$4:$J$203,Trato_Diario!$B$4:$B$203,E$5,Trato_Diario!$A$4:$A$203,$A18)/SUMIFS(Trato_Diario!$G$4:$G$203,Trato_Diario!$B$4:$B$203,E$5,Trato_Diario!$A$4:$A$203,$A18)) -> 16.149483 | F18: =IF(OR($A18>MAX(Trato_Diario!$A$4:$A$203),SUMIFS(Trato_Diario!$G$4:$G$203,Trato_Diario!$B$4:$B$203,F$5,Trato_Diario!$A$4:$A$203,$A18)=0),"",SUMIFS(Trato_Diario!$J$4:$J$203,Trato_Diario!$B$4:$B$203,F$5,Trato_Diario!$A$4:$A$203,$A18)/SUMIFS(Trato_Diario!$G$4:$G$203,Trato_Diario!$B$4:$B$203,F$5,Trato_Diario!$A$4:$A$203,$A18)) | G18: =IF(OR($A18>MAX(Trato_Diario!$A$4:$A$203),SUMIFS(Trato_Diario!$G$4:$G$203,Trato_Diario!$B$4:$B$203,G$5,Trato_Diario!$A$4:$A$203,$A18)=0),"",SUMIFS(Trato_Diario!$J$4:$J$203,Trato_Diario!$B$4:$B$203,G$5,Trato_Diario!$A$4:$A$203,$A18)/SUMIFS(Trato_Diario!$G$4:$G$203,Trato_Diario!$B$4:$B$203,G$5,Trato_Diario!$A$4:$A$203,$A18)) | H18: =IF(OR($A18>MAX(Trato_Diario!$A$4:$A$203),SUMIFS(Trato_Diario!$G$4:$G$203,Trato_Diario!$A$4:$A$203,$A18)=0),"",SUMIFS(Trato_Diario!$J$4:$J$203,Trato_Diario!$A$4:$A$203,$A18)/SUMIFS(Trato_Diario!$G$4:$G$203,Trato_Diario!$A$4:$A$203,$A18)) -> 7.725018
A19: 46206 | B19: =IF(OR($A19>MAX(Trato_Diario!$A$4:$A$203),SUMIFS(Trato_Diario!$G$4:$G$203,Trato_Diario!$B$4:$B$203,B$5,Trato_Diario!$A$4:$A$203,$A19)=0),"",SUMIFS(Trato_Diario!$J$4:$J$203,Trato_Diario!$B$4:$B$203,B$5,Trato_Diario!$A$4:$A$203,$A19)/SUMIFS(Trato_Diario!$G$4:$G$203,Trato_Diario!$B$4:$B$203,B$5,Trato_Diario!$A$4:$A$203,$A19)) -> 10.8405 | C19: =IF(OR($A19>MAX(Trato_Diario!$A$4:$A$203),SUMIFS(Trato_Diario!$G$4:$G$203,Trato_Diario!$B$4:$B$203,C$5,Trato_Diario!$A$4:$A$203,$A19)=0),"",SUMIFS(Trato_Diario!$J$4:$J$203,Trato_Diario!$B$4:$B$203,C$5,Trato_Diario!$A$4:$A$203,$A19)/SUMIFS(Trato_Diario!$G$4:$G$203,Trato_Diario!$B$4:$B$203,C$5,Trato_Diario!$A$4:$A$203,$A19)) -> 7.9601739 | D19: =IF(OR($A19>MAX(Trato_Diario!$A$4:$A$203),SUMIFS(Trato_Diario!$G$4:$G$203,Trato_Diario!$B$4:$B$203,D$5,Trato_Diario!$A$4:$A$203,$A19)=0),"",SUMIFS(Trato_Diario!$J$4:$J$203,Trato_Diario!$B$4:$B$203,D$5,Trato_Diario!$A$4:$A$203,$A19)/SUMIFS(Trato_Diario!$G$4:$G$203,Trato_Diario!$B$4:$B$203,D$5,Trato_Diario!$A$4:$A$203,$A19)) -> 6.0160909 | E19: =IF(OR($A19>MAX(Trato_Diario!$A$4:$A$203),SUMIFS(Trato_Diario!$G$4:$G$203,Trato_Diario!$B$4:$B$203,E$5,Trato_Diario!$A$4:$A$203,$A19)=0),"",SUMIFS(Trato_Diario!$J$4:$J$203,Trato_Diario!$B$4:$B$203,E$5,Trato_Diario!$A$4:$A$203,$A19)/SUMIFS(Trato_Diario!$G$4:$G$203,Trato_Diario!$B$4:$B$203,E$5,Trato_Diario!$A$4:$A$203,$A19)) -> 16.149483 | F19: =IF(OR($A19>MAX(Trato_Diario!$A$4:$A$203),SUMIFS(Trato_Diario!$G$4:$G$203,Trato_Diario!$B$4:$B$203,F$5,Trato_Diario!$A$4:$A$203,$A19)=0),"",SUMIFS(Trato_Diario!$J$4:$J$203,Trato_Diario!$B$4:$B$203,F$5,Trato_Diario!$A$4:$A$203,$A19)/SUMIFS(Trato_Diario!$G$4:$G$203,Trato_Diario!$B$4:$B$203,F$5,Trato_Diario!$A$4:$A$203,$A19)) | G19: =IF(OR($A19>MAX(Trato_Diario!$A$4:$A$203),SUMIFS(Trato_Diario!$G$4:$G$203,Trato_Diario!$B$4:$B$203,G$5,Trato_Diario!$A$4:$A$203,$A19)=0),"",SUMIFS(Trato_Diario!$J$4:$J$203,Trato_Diario!$B$4:$B$203,G$5,Trato_Diario!$A$4:$A$203,$A19)/SUMIFS(Trato_Diario!$G$4:$G$203,Trato_Diario!$B$4:$B$203,G$5,Trato_Diario!$A$4:$A$203,$A19)) | H19: =IF(OR($A19>MAX(Trato_Diario!$A$4:$A$203),SUMIFS(Trato_Diario!$G$4:$G$203,Trato_Diario!$A$4:$A$203,$A19)=0),"",SUMIFS(Trato_Diario!$J$4:$J$203,Trato_Diario!$A$4:$A$203,$A19)/SUMIFS(Trato_Diario!$G$4:$G$203,Trato_Diario!$A$4:$A$203,$A19)) -> 8.0543058
A20: 46207 | B20: =IF(OR($A20>MAX(Trato_Diario!$A$4:$A$203),SUMIFS(Trato_Diario!$G$4:$G$203,Trato_Diario!$B$4:$B$203,B$5,Trato_Diario!$A$4:$A$203,$A20)=0),"",SUMIFS(Trato_Diario!$J$4:$J$203,Trato_Diario!$B$4:$B$203,B$5,Trato_Diario!$A$4:$A$203,$A20)/SUMIFS(Trato_Diario!$G$4:$G$203,Trato_Diario!$B$4:$B$203,B$5,Trato_Diario!$A$4:$A$203,$A20)) -> 10.8405 | C20: =IF(OR($A20>MAX(Trato_Diario!$A$4:$A$203),SUMIFS(Trato_Diario!$G$4:$G$203,Trato_Diario!$B$4:$B$203,C$5,Trato_Diario!$A$4:$A$203,$A20)=0),"",SUMIFS(Trato_Diario!$J$4:$J$203,Trato_Diario!$B$4:$B$203,C$5,Trato_Diario!$A$4:$A$203,$A20)/SUMIFS(Trato_Diario!$G$4:$G$203,Trato_Diario!$B$4:$B$203,C$5,Trato_Diario!$A$4:$A$203,$A20)) -> 7.9601739 | D20: =IF(OR($A20>MAX(Trato_Diario!$A$4:$A$203),SUMIFS(Trato_Diario!$G$4:$G$203,Trato_Diario!$B$4:$B$203,D$5,Trato_Diario!$A$4:$A$203,$A20)=0),"",SUMIFS(Trato_Diario!$J$4:$J$203,Trato_Diario!$B$4:$B$203,D$5,Trato_Diario!$A$4:$A$203,$A20)/SUMIFS(Trato_Diario!$G$4:$G$203,Trato_Diario!$B$4:$B$203,D$5,Trato_Diario!$A$4:$A$203,$A20)) -> 6.0160909 | E20: =IF(OR($A20>MAX(Trato_Diario!$A$4:$A$203),SUMIFS(Trato_Diario!$G$4:$G$203,Trato_Diario!$B$4:$B$203,E$5,Trato_Diario!$A$4:$A$203,$A20)=0),"",SUMIFS(Trato_Diario!$J$4:$J$203,Trato_Diario!$B$4:$B$203,E$5,Trato_Diario!$A$4:$A$203,$A20)/SUMIFS(Trato_Diario!$G$4:$G$203,Trato_Diario!$B$4:$B$203,E$5,Trato_Diario!$A$4:$A$203,$A20)) -> 16.149483 | F20: =IF(OR($A20>MAX(Trato_Diario!$A$4:$A$203),SUMIFS(Trato_Diario!$G$4:$G$203,Trato_Diario!$B$4:$B$203,F$5,Trato_Diario!$A$4:$A$203,$A20)=0),"",SUMIFS(Trato_Diario!$J$4:$J$203,Trato_Diario!$B$4:$B$203,F$5,Trato_Diario!$A$4:$A$203,$A20)/SUMIFS(Trato_Diario!$G$4:$G$203,Trato_Diario!$B$4:$B$203,F$5,Trato_Diario!$A$4:$A$203,$A20)) | G20: =IF(OR($A20>MAX(Trato_Diario!$A$4:$A$203),SUMIFS(Trato_Diario!$G$4:$G$203,Trato_Diario!$B$4:$B$203,G$5,Trato_Diario!$A$4:$A$203,$A20)=0),"",SUMIFS(Trato_Diario!$J$4:$J$203,Trato_Diario!$B$4:$B$203,G$5,Trato_Diario!$A$4:$A$203,$A20)/SUMIFS(Trato_Diario!$G$4:$G$203,Trato_Diario!$B$4:$B$203,G$5,Trato_Diario!$A$4:$A$203,$A20)) | H20: =IF(OR($A20>MAX(Trato_Diario!$A$4:$A$203),SUMIFS(Trato_Diario!$G$4:$G$203,Trato_Diario!$A$4:$A$203,$A20)=0),"",SUMIFS(Trato_Diario!$J$4:$J$203,Trato_Diario!$A$4:$A$203,$A20)/SUMIFS(Trato_Diario!$G$4:$G$203,Trato_Diario!$A$4:$A$203,$A20)) -> 8.0543058
