Workbook

Sheet Dashboard
B2: DASHBOARD — VISÃO GERAL DO CONFINAMENTO PD
B4: REBANHO | E4: ECONÔMICO / NUTRIÇÃO
B5: Total de animais | C5: =COUNTA(Cadastro_Animais!$B$3:$B$5001) -> 646 | E5: Preço da arroba (R$/@) | F5: =Parâmetros!$C$5 -> 320
B6: Bois (currais 1–9) | C6: =COUNTIF(Cadastro_Animais!$C$3:$C$5001,"Boi") -> 613 | E6: Valor do rebanho (R$) | F6: =SUM(Cadastro_Animais!$O$3:$O$5001) -> 2925419.1
B7: F1 Cruz. Industrial (curral 10) | C7: =COUNTIF(Cadastro_Animais!$C$3:$C$5001,"F Cruz.Ind.") -> 33 | E7: Custo da dieta (R$/kg MN) | F7: =Parâmetros!$C$6 -> 0.8227
B8: Peso vivo total atual (kg) | C8: =SUM(Cadastro_Animais!$I$3:$I$5001) -> 258734 | E8: Consumo planejado/dia (kg MN) | F8: =Calculadora_Trato!$G$18 -> 11800
B9: Peso médio atual (kg) | C9: =IFERROR(AVERAGE(Cadastro_Animais!$I$3:$I$5001),"") -> 400.51703 | E9: Custo total ração/dia (R$) | F9: =Calculadora_Trato!$M$18 -> 9707.86
B10: @ totais em estoque | C10: =SUM(Cadastro_Animais!$M$3:$M$5001) -> 9141.9347 | E10: Custo ração/cab/dia (R$) | F10: =IFERROR(Calculadora_Trato!$M$18/COUNTA(Cadastro_Animais!$B$3:$B$5001),"") -> 15.027647
B12: DESEMPENHO (onde há 2+ pesagens) | E12: CUSTO ACUMULADO / @
B13: GMD médio do rebanho (kg/dia) | C13: =IFERROR(AVERAGE(Cadastro_Animais!$L$3:$L$5001),"") | E13: Custo nutrição estim. acum. (R$) | F13: =Custo_Nutricao_Lote!$I$16 -> 153111.05
B14: Ganho total acumulado (kg) | C14: =SUM(Cadastro_Animais!$K$3:$K$5001) -> 0 | E14: Custo nutrição real acum. (R$) | F14: =Custo_Nutricao_Lote!$J$16 -> 166976.79
B15: @ produzidas (ganho) | C15: =SUM(Cadastro_Animais!$N$3:$N$5001) -> 0 | E15: Custo estim./@ produzida (R$) | F15: =IF(Custo_Nutricao_Lote!$L$16<=0,"",Custo_Nutricao_Lote!$I$16/Custo_Nutricao_Lote!$L$16)
B16: GMD meta (kg/dia) | C16: =Parâmetros!$C$10 -> 1.5 | E16: Obs.: custo/@ produzida aparece quando houver ganho (2+ pesagens).

Sheet Parâmetros
B2: PARÂMETROS (edite as células amarelas)
B3: Parâmetro | C3: Valor | D3: Observação
B4: Data de referência | C4: 46238 | D4: Data usada para calcular os dias de confinamento.
B5: Preço da arroba (R$/@) | C5: 320 | D5: PLACEHOLDER — ajuste ao preço do boi gordo (ver arquivo CEPEA).
B6: Custo da ração (R$/kg matéria natural) | C6: =IFERROR(LOOKUP($C$4,Ingredientes_Dieta!$C$17:$C$18,Ingredientes_Dieta!$D$17:$D$18),Ingredientes_Dieta!$F$11) -> 0.8227 | D6: Automático: usa a dieta vigente na Data de referência (tabela de vigência em Ingredientes_Dieta).
B7: % Matéria seca da dieta | C7: 0.55 | D7: PLACEHOLDER — teor de MS da dieta de silagem. Ajuste ao valor real.
B8: Rendimento de carcaça (%) | C8: 0.53 | D8: Rendimento de carcaça para converter peso vivo em @.
B9: Custo fixo diário (R$/cab/dia) | C9: 2.5 | D9: PLACEHOLDER — sanidade + mão de obra (não entra no custo só-ração).
B10: GMD meta (kg/dia) | C10: 1.5 | D10: Meta de ganho médio diário (pós-adaptação).
B11: Peso de abate alvo (kg) | C11: 530 | D11: Peso vivo alvo para projeções.

Sheet Precos_Insumos
A1: COMPRAS / PREÇOS DE INSUMOS (por data)
A2: Registre CADA compra: Data, Insumo, Preço R$/kg e Qtd. O custo da dieta usa sempre o preço da COMPRA MAIS RECENTE de cada insumo. Células amarelas = você edita.
A3: Data | B3: Insumo | C3: Preço (R$/kg) | D3: Qtd Comprada (kg) | E3: Valor Total (R$) | F3: Fornecedor | G3: Obs
A4: 46218 | B4: Silagem de Capim | C4: 0.1 | E4: =IF(D4="","",C4*D4) | F4: Produção própria | G4: Custo estimado de produção
A5: 46218 | B5: Farelo de Soja | C5: 2 | E5: =IF(D5="","",C5*D5)
A6: 46218 | B6: Milho Moído | C6: 1.05 | E6: =IF(D6="","",C6*D6)
A7: 46218 | B7: Ureia | C7: 4.5 | E7: =IF(D7="","",C7*D7)
A8: 46218 | B8: Núcleo Flex (Minerthal) | C8: 3.83 | E8: =IF(D8="","",C8*D8) | F8: Minerthal
A9: 46230 | B9: Milho Moído | C9: 1.05 | D9: 38200 | E9: =IF(D9="","",C9*D9) -> 40110 | G9: Compra informada — entrada de estoque
A10: 46238 | B10: Farelo de Soja | C10: 2 | D10: 5000 | E10: =IF(D10="","",C10*D10) -> 10000
A11: 46240 | B11: Milho Moído | C11: 1.1 | D11: 45040 | E11: =IF(D11="","",C11*D11) -> 49544
A12: 46241 | B12: Farelo de Soja | C12: 2.53 | D12: 20000 | E12: =IF(D12="","",C12*D12) -> 50600
B13: , | E13: =IF(D13="","",C13*D13)
E14: =IF(D14="","",C14*D14)
E15: =IF(D15="","",C15*D15)
E16: =IF(D16="","",C16*D16)
E17: =IF(D17="","",C17*D17)
E18: =IF(D18="","",C18*D18)
E19: =IF(D19="","",C19*D19)
E20: =IF(D20="","",C20*D20)
E21: =IF(D21="","",C21*D21)
E22: =IF(D22="","",C22*D22)
E23: =IF(D23="","",C23*D23)
E24: =IF(D24="","",C24*D24)
E25: =IF(D25="","",C25*D25)
... E203: =IF(D203="","",C203*D203)

Sheet Estoque_Insumos
B2: ESTOQUE DE INSUMOS (estimativa)
B3: Informe o Estoque na data-base e a Data-base de cada insumo (amarelo). O consumo é calculado pelos tratos, respeitando a % de cada dieta vigente por data. Estoque Atual = Estoque na data-base + Compras após − Consumo após.
B5: Insumo | C5: Estoque na data-base (kg) | D5: Data-base | E5: Compras após (kg) | F5: Consumo após (kg) | G5: Estoque Atual (kg) | H5: Consumo/dia dieta atual (kg) | I5: Dias de estoque | J5: % dieta atual
B6: Silagem de Capim | E6: =IF($D6="","",SUMIFS(Precos_Insumos!$D$4:$D$203,Precos_Insumos!$B$4:$B$203,$B6,Precos_Insumos!$A$4:$A$203,">"&$D6)) | F6: =IF($D6="","",SUMIFS(Trato_Diario!$F$4:$F$300,Trato_Diario!$A$4:$A$300,">="&$D6,Trato_Diario!$A$4:$A$300,"<"&Ingredientes_Dieta!$C$18)*INDEX(Ingredientes_Dieta!$E$6:$E$10,MATCH($B6,Ingredientes_Dieta!$B$6:$B$10,0))+SUMIFS(Trato_Diario!$F$4:$F$300,Trato_Diario!$A$4:$A$300,">="&MAX($D6,Ingredientes_Dieta!$C$18))*INDEX(Ingredientes_Dieta!$G$6:$G$10,MATCH($B6,Ingredientes_Dieta!$B$6:$B$10,0))) | G6: =IF($C6="","",$C6+N(E6)-N(F6)) | H6: =Calculadora_Trato!$G$18*INDEX(Ingredientes_Dieta!$G$6:$G$10,MATCH($B6,Ingredientes_Dieta!$B$6:$B$10,0)) -> 5900 | I6: =IF(OR(G6="",H6=0),"",G6/H6) | J6: =IFERROR(INDEX(Ingredientes_Dieta!$G$6:$G$10,MATCH($B6,Ingredientes_Dieta!$B$6:$B$10,0)),"") -> 0.5
B7: Farelo de Soja | C7: 5000 | D7: 46238 | E7: =IF($D7="","",SUMIFS(Precos_Insumos!$D$4:$D$203,Precos_Insumos!$B$4:$B$203,$B7,Precos_Insumos!$A$4:$A$203,">"&$D7)) -> 20000 | F7: =IF($D7="","",SUMIFS(Trato_Diario!$F$4:$F$300,Trato_Diario!$A$4:$A$300,">="&$D7,Trato_Diario!$A$4:$A$300,"<"&Ingredientes_Dieta!$C$18)*INDEX(Ingredientes_Dieta!$E$6:$E$10,MATCH($B7,Ingredientes_Dieta!$B$6:$B$10,0))+SUMIFS(Trato_Diario!$F$4:$F$300,Trato_Diario!$A$4:$A$300,">="&MAX($D7,Ingredientes_Dieta!$C$18))*INDEX(Ingredientes_Dieta!$G$6:$G$10,MATCH($B7,Ingredientes_Dieta!$B$6:$B$10,0))) -> 8754.768 | G7: =IF($C7="","",$C7+N(E7)-N(F7)) -> 16245.232 | H7: =Calculadora_Trato!$G$18*INDEX(Ingredientes_Dieta!$G$6:$G$10,MATCH($B7,Ingredientes_Dieta!$B$6:$B$10,0)) -> 1416 | I7: =IF(OR(G7="",H7=0),"",G7/H7) -> 11.472621 | J7: =IFERROR(INDEX(Ingredientes_Dieta!$G$6:$G$10,MATCH($B7,Ingredientes_Dieta!$B$6:$B$10,0)),"") -> 0.12
B8: Milho Moído | C8: 38200 | D8: 46230 | E8: =IF($D8="","",SUMIFS(Precos_Insumos!$D$4:$D$203,Precos_Insumos!$B$4:$B$203,$B8,Precos_Insumos!$A$4:$A$203,">"&$D8)) -> 45040 | F8: =IF($D8="","",SUMIFS(Trato_Diario!$F$4:$F$300,Trato_Diario!$A$4:$A$300,">="&$D8,Trato_Diario!$A$4:$A$300,"<"&Ingredientes_Dieta!$C$18)*INDEX(Ingredientes_Dieta!$E$6:$E$10,MATCH($B8,Ingredientes_Dieta!$B$6:$B$10,0))+SUMIFS(Trato_Diario!$F$4:$F$300,Trato_Diario!$A$4:$A$300,">="&MAX($D8,Ingredientes_Dieta!$C$18))*INDEX(Ingredientes_Dieta!$G$6:$G$10,MATCH($B8,Ingredientes_Dieta!$B$6:$B$10,0))) -> 47690.007 | G8: =IF($C8="","",$C8+N(E8)-N(F8)) -> 35549.993 | H8: =Calculadora_Trato!$G$18*INDEX(Ingredientes_Dieta!$G$6:$G$10,MATCH($B8,Ingredientes_Dieta!$B$6:$B$10,0)) -> 4283.4 | I8: =IF(OR(G8="",H8=0),"",G8/H8) -> 8.29948 | J8: =IFERROR(INDEX(Ingredientes_Dieta!$G$6:$G$10,MATCH($B8,Ingredientes_Dieta!$B$6:$B$10,0)),"") -> 0.363
B9: Ureia | E9: =IF($D9="","",SUMIFS(Precos_Insumos!$D$4:$D$203,Precos_Insumos!$B$4:$B$203,$B9,Precos_Insumos!$A$4:$A$203,">"&$D9)) | F9: =IF($D9="","",SUMIFS(Trato_Diario!$F$4:$F$300,Trato_Diario!$A$4:$A$300,">="&$D9,Trato_Diario!$A$4:$A$300,"<"&Ingredientes_Dieta!$C$18)*INDEX(Ingredientes_Dieta!$E$6:$E$10,MATCH($B9,Ingredientes_Dieta!$B$6:$B$10,0))+SUMIFS(Trato_Diario!$F$4:$F$300,Trato_Diario!$A$4:$A$300,">="&MAX($D9,Ingredientes_Dieta!$C$18))*INDEX(Ingredientes_Dieta!$G$6:$G$10,MATCH($B9,Ingredientes_Dieta!$B$6:$B$10,0))) | G9: =IF($C9="","",$C9+N(E9)-N(F9)) | H9: =Calculadora_Trato!$G$18*INDEX(Ingredientes_Dieta!$G$6:$G$10,MATCH($B9,Ingredientes_Dieta!$B$6:$B$10,0)) -> 82.6 | I9: =IF(OR(G9="",H9=0),"",G9/H9) | J9: =IFERROR(INDEX(Ingredientes_Dieta!$G$6:$G$10,MATCH($B9,Ingredientes_Dieta!$B$6:$B$10,0)),"") -> 0.007
B10: Núcleo Flex (Minerthal) | E10: =IF($D10="","",SUMIFS(Precos_Insumos!$D$4:$D$203,Precos_Insumos!$B$4:$B$203,$B10,Precos_Insumos!$A$4:$A$203,">"&$D10)) | F10: =IF($D10="","",SUMIFS(Trato_Diario!$F$4:$F$300,Trato_Diario!$A$4:$A$300,">="&$D10,Trato_Diario!$A$4:$A$300,"<"&Ingredientes_Dieta!$C$18)*INDEX(Ingredientes_Dieta!$E$6:$E$10,MATCH($B10,Ingredientes_Dieta!$B$6:$B$10,0))+SUMIFS(Trato_Diario!$F$4:$F$300,Trato_Diario!$A$4:$A$300,">="&MAX($D10,Ingredientes_Dieta!$C$18))*INDEX(Ingredientes_Dieta!$G$6:$G$10,MATCH($B10,Ingredientes_Dieta!$B$6:$B$10,0))) | G10: =IF($C10="","",$C10+N(E10)-N(F10)) | H10: =Calculadora_Trato!$G$18*INDEX(Ingredientes_Dieta!$G$6:$G$10,MATCH($B10,Ingredientes_Dieta!$B$6:$B$10,0)) -> 118 | I10: =IF(OR(G10="",H10=0),"",G10/H10) | J10: =IFERROR(INDEX(Ingredientes_Dieta!$G$6:$G$10,MATCH($B10,Ingredientes_Dieta!$B$6:$B$10,0)),"") -> 0.01
B12: Obs.: para o milho, considerou-se os 38.200 kg como estoque em 27/07 (sem sobra anterior). Se havia sobra do lote antigo, aumente o 'Estoque na data-base'. 'Dias de estoque' usa o consumo diário na dieta atual (crescimento).
F15: 46240 | G15: 8
F16: =F15+G15 -> 46248

Sheet Ingredientes_Dieta
B2: INGREDIENTES DA DIETA — CRESCIMENTO PAU D'ARCO
B3: Preço vem AUTOMÁTICO da última compra (Precos_Insumos). Edite só as % de inclusão (amarelo) de cada dieta. O custo por data usa a DIETA VIGENTE (tabela de vigência abaixo).
B5: Ingrediente | C5: Preço atual (R$/kg) | D5: Última compra | E5: % Adaptação | F5: Custo Adapt. (R$/kg) | G5: % Crescimento | H5: Custo Cresc. (R$/kg) | J5: 2000
B6: Silagem de Capim | C6: =IFERROR(AVERAGEIFS(Precos_Insumos!$C$4:$C$203,Precos_Insumos!$B$4:$B$203,B6,Precos_Insumos!$A$4:$A$203,D6),0) -> 0.1 | D6: =IFERROR(_xlfn.MAXIFS(Precos_Insumos!$A$4:$A$203,Precos_Insumos!$B$4:$B$203,B6),"") -> 46218 | E6: 0.683 | F6: =C6*E6 -> 0.0683 | G6: 0.5 | H6: =C6*G6 -> 0.05 | J6: =J5*G6 -> 1000
B7: Farelo de Soja | C7: =IFERROR(AVERAGEIFS(Precos_Insumos!$C$4:$C$203,Precos_Insumos!$B$4:$B$203,B7,Precos_Insumos!$A$4:$A$203,D7),0) -> 2.53 | D7: =IFERROR(_xlfn.MAXIFS(Precos_Insumos!$A$4:$A$203,Precos_Insumos!$B$4:$B$203,B7),"") -> 46241 | E7: 0.08 | F7: =C7*E7 -> 0.2024 | G7: 0.12 | H7: =C7*G7 -> 0.3036 | J7: =J5*G7 -> 240
B8: Milho Moído | C8: =IFERROR(AVERAGEIFS(Precos_Insumos!$C$4:$C$203,Precos_Insumos!$B$4:$B$203,B8,Precos_Insumos!$A$4:$A$203,D8),0) -> 1.1 | D8: =IFERROR(_xlfn.MAXIFS(Precos_Insumos!$A$4:$A$203,Precos_Insumos!$B$4:$B$203,B8),"") -> 46240 | E8: 0.22 | F8: =C8*E8 -> 0.242 | G8: 0.363 | H8: =C8*G8 -> 0.3993 | J8: =J5*G8 -> 726
B9: Ureia | C9: =IFERROR(AVERAGEIFS(Precos_Insumos!$C$4:$C$203,Precos_Insumos!$B$4:$B$203,B9,Precos_Insumos!$A$4:$A$203,D9),0) -> 4.5 | D9: =IFERROR(_xlfn.MAXIFS(Precos_Insumos!$A$4:$A$203,Precos_Insumos!$B$4:$B$203,B9),"") -> 46218 | E9: 0.007 | F9: =C9*E9 -> 0.0315 | G9: 0.007 | H9: =C9*G9 -> 0.0315 | J9: =J5*G9 -> 14
B10: Núcleo Flex (Minerthal) | C10: =IFERROR(AVERAGEIFS(Precos_Insumos!$C$4:$C$203,Precos_Insumos!$B$4:$B$203,B10,Precos_Insumos!$A$4:$A$203,D10),0) -> 3.83 | D10: =IFERROR(_xlfn.MAXIFS(Precos_Insumos!$A$4:$A$203,Precos_Insumos!$B$4:$B$203,B10),"") -> 46218 | E10: 0.01 | F10: =C10*E10 -> 0.0383 | G10: 0.01 | H10: =C10*G10 -> 0.0383 | J10: =J5*G10 -> 20
B11: TOTAL / Custo da dieta | E11: =SUM(E6:E10) -> 1 | F11: =SUM(F6:F10) -> 0.5825 | G11: =SUM(G6:G10) -> 1 | H11: =SUM(H6:H10) -> 0.8227
B13: Conferência % (Adapt / Cresc, devem dar 100%): | E13: =E11 -> 1 | G13: =G11 -> 1
B15: DIETAS — VIGÊNCIA (o custo por data usa a dieta vigente)
B16: Dieta | C16: Início (vigência) | D16: Custo (R$/kg)
B17: Adaptação | C17: 46220 | D17: =F11 -> 0.5825
B18: Crescimento | C18: 46238 | D18: =H11 -> 0.8227
B20: Para trocar de dieta: acrescente uma linha nesta tabela com a data de início e a dieta passa a valer a partir dela (mantenha as datas em ordem crescente).

Sheet Calculadora_Trato
A1: z'
B2: CALCULADORA DE TRATO POR CURRAL
B3: Edite o consumo BASE (kg MN/dia) e o AJUSTE % de cada curral (amarelo). O ajuste aumenta/reduz o trato. Split manhã/almoço/tarde editável abaixo. Base inicial = Calculadora de Trato (dieta adaptação).
B5: Split do trato (%): | D5: Manhã | E5: 0.4 | F5: Almoço | G5: 0.2 | H5: Tarde | I5: 0.4 | K5: Custo dieta (R$/kg): | M5: =Parâmetros!$C$6 -> 0.8227
B7: Curral | C7: Nº Cab | D7: Peso Médio (kg) | E7: Base Total (kg MN/dia) | F7: Ajuste % | G7: Consumo Ajustado (kg MN/dia) | H7: kg MN/cab | I7: Trato Manhã (kg) | J7: Trato Almoço (kg) | K7: Trato Tarde (kg) | L7: Custo Dieta (R$/kg) | M7: Custo Planejado/dia (R$) | N7: Custo/cab/dia (R$)
B8: 1 | C8: =IFERROR(INDEX(Currais!$C:$C,MATCH(B8,Currais!$A:$A,0)),0) -> 76 | D8: =IFERROR(INDEX(Currais!$E:$E,MATCH(B8,Currais!$A:$A,0)),0) -> 452.85526 | E8: 1598 | F8: 0 | G8: =E8*(1+F8) -> 1598 | H8: =IF(C8=0,"",G8/C8) -> 21.026316 | I8: =G8*$E$5 -> 639.2 | J8: =G8*$G$5 -> 319.6 | K8: =G8*$I$5 -> 639.2 | L8: =$M$5 -> 0.8227 | M8: =G8*L8 -> 1314.6746 | N8: =IF(C8=0,"",M8/C8) -> 17.29835
B9: 2 | C9: =IFERROR(INDEX(Currais!$C:$C,MATCH(B9,Currais!$A:$A,0)),0) -> 22 | D9: =IFERROR(INDEX(Currais!$E:$E,MATCH(B9,Currais!$A:$A,0)),0) -> 501.40909 | E9: 487 | F9: 0 | G9: =E9*(1+F9) -> 487 | H9: =IF(C9=0,"",G9/C9) -> 22.136364 | I9: =G9*$E$5 -> 194.8 | J9: =G9*$G$5 -> 97.4 | K9: =G9*$I$5 -> 194.8 | L9: =$M$5 -> 0.8227 | M9: =G9*L9 -> 400.6549 | N9: =IF(C9=0,"",M9/C9) -> 18.211586
B10: 3 | C10: =IFERROR(INDEX(Currais!$C:$C,MATCH(B10,Currais!$A:$A,0)),0) -> 85 | D10: =IFERROR(INDEX(Currais!$E:$E,MATCH(B10,Currais!$A:$A,0)),0) -> 410.05882 | E10: 1618 | F10: 0 | G10: =E10*(1+F10) -> 1618 | H10: =IF(C10=0,"",G10/C10) -> 19.035294 | I10: =G10*$E$5 -> 647.2 | J10: =G10*$G$5 -> 323.6 | K10: =G10*$I$5 -> 647.2 | L10: =$M$5 -> 0.8227 | M10: =G10*L10 -> 1331.1286 | N10: =IF(C10=0,"",M10/C10) -> 15.660336
B11: 4 | C11: =IFERROR(INDEX(Currais!$C:$C,MATCH(B11,Currais!$A:$A,0)),0) -> 90 | D11: =IFERROR(INDEX(Currais!$E:$E,MATCH(B11,Currais!$A:$A,0)),0) -> 381.83333 | E11: 1596 | F11: 0 | G11: =E11*(1+F11) -> 1596 | H11: =IF(C11=0,"",G11/C11) -> 17.733333 | I11: =G11*$E$5 -> 638.4 | J11: =G11*$G$5 -> 319.2 | K11: =G11*$I$5 -> 638.4 | L11: =$M$5 -> 0.8227 | M11: =G11*L11 -> 1313.0292 | N11: =IF(C11=0,"",M11/C11) -> 14.589213
B12: 5 | C12: =IFERROR(INDEX(Currais!$C:$C,MATCH(B12,Currais!$A:$A,0)),0) -> 88 | D12: =IFERROR(INDEX(Currais!$E:$E,MATCH(B12,Currais!$A:$A,0)),0) -> 361.80682 | E12: 1477 | F12: 0 | G12: =E12*(1+F12) -> 1477 | H12: =IF(C12=0,"",G12/C12) -> 16.784091 | I12: =G12*$E$5 -> 590.8 | J12: =G12*$G$5 -> 295.4 | K12: =G12*$I$5 -> 590.8 | L12: =$M$5 -> 0.8227 | M12: =G12*L12 -> 1215.1279 | N12: =IF(C12=0,"",M12/C12) -> 13.808272
B13: 6 | C13: =IFERROR(INDEX(Currais!$C:$C,MATCH(B13,Currais!$A:$A,0)),0) -> 85 | D13: =IFERROR(INDEX(Currais!$E:$E,MATCH(B13,Currais!$A:$A,0)),0) -> 385.96471 | E13: 1451 | F13: 0 | G13: =E13*(1+F13) -> 1451 | H13: =IF(C13=0,"",G13/C13) -> 17.070588 | I13: =G13*$E$5 -> 580.4 | J13: =G13*$G$5 -> 290.2 | K13: =G13*$I$5 -> 580.4 | L13: =$M$5 -> 0.8227 | M13: =G13*L13 -> 1193.7377 | N13: =IF(C13=0,"",M13/C13) -> 14.043973
B14: 7 | C14: =IFERROR(INDEX(Currais!$C:$C,MATCH(B14,Currais!$A:$A,0)),0) -> 85 | D14: =IFERROR(INDEX(Currais!$E:$E,MATCH(B14,Currais!$A:$A,0)),0) -> 415.10588 | E14: 1560 | F14: 0 | G14: =E14*(1+F14) -> 1560 | H14: =IF(C14=0,"",G14/C14) -> 18.352941 | I14: =G14*$E$5 -> 624 | J14: =G14*$G$5 -> 312 | K14: =G14*$I$5 -> 624 | L14: =$M$5 -> 0.8227 | M14: =G14*L14 -> 1283.412 | N14: =IF(C14=0,"",M14/C14) -> 15.098965
B15: 8 | C15: =IFERROR(INDEX(Currais!$C:$C,MATCH(B15,Currais!$A:$A,0)),0) -> 68 | D15: =IFERROR(INDEX(Currais!$E:$E,MATCH(B15,Currais!$A:$A,0)),0) -> 394.95588 | E15: 1247 | F15: 0 | G15: =E15*(1+F15) -> 1247 | H15: =IF(C15=0,"",G15/C15) -> 18.338235 | I15: =G15*$E$5 -> 498.8 | J15: =G15*$G$5 -> 249.4 | K15: =G15*$I$5 -> 498.8 | L15: =$M$5 -> 0.8227 | M15: =G15*L15 -> 1025.9069 | N15: =IF(C15=0,"",M15/C15) -> 15.086866
B16: 9 | C16: =IFERROR(INDEX(Currais!$C:$C,MATCH(B16,Currais!$A:$A,0)),0) -> 14 | D16: =IFERROR(INDEX(Currais!$E:$E,MATCH(B16,Currais!$A:$A,0)),0) -> 338.5 | E16: 211 | F16: 0 | G16: =E16*(1+F16) -> 211 | H16: =IF(C16=0,"",G16/C16) -> 15.071429 | I16: =G16*$E$5 -> 84.4 | J16: =G16*$G$5 -> 42.2 | K16: =G16*$I$5 -> 84.4 | L16: =$M$5 -> 0.8227 | M16: =G16*L16 -> 173.5897 | N16: =IF(C16=0,"",M16/C16) -> 12.399264
B17: 10 | C17: =IFERROR(INDEX(Currais!$C:$C,MATCH(B17,Currais!$A:$A,0)),0) -> 33 | D17: =IFERROR(INDEX(Currais!$E:$E,MATCH(B17,Currais!$A:$A,0)),0) -> 380 | E17: 555 | F17: 0 | G17: =E17*(1+F17) -> 555 | H17: =IF(C17=0,"",G17/C17) -> 16.818182 | I17: =G17*$E$5 -> 222 | J17: =G17*$G$5 -> 111 | K17: =G17*$I$5 -> 222 | L17: =$M$5 -> 0.8227 | M17: =G17*L17 -> 456.5985 | N17: =IF(C17=0,"",M17/C17) -> 13.836318
B18: TOTAL | C18: =SUM(C8:C17) -> 646 | D18: =IFERROR(SUMPRODUCT(C8:C17,D8:D17)/C18,"") -> 400.51703 | E18: =SUM(E8:E17) -> 11800 | G18: =SUM(G8:G17) -> 11800 | I18: =SUM(I8:I17) -> 4720 | J18: =SUM(J8:J17) -> 2360 | K18: =SUM(K8:K17) -> 4720 | M18: =SUM(M8:M17) -> 9707.86 | N18: =IF(C18=0,"",M18/C18) -> 15.027647

Sheet Trato_Diario
A1: LANÇAMENTO DIÁRIO DE TRATO (REAL) POR CURRAL
A2: Lance o que foi REALMENTE fornecido por dia/curral (amarelo). O custo alimenta o 'Custo Real' por lote. Total e custo são calculados.
A3: Data | B3: Curral | C3: Trato Manhã (kg MN) | D3: Trato Almoço (kg MN) | E3: Trato Tarde (kg MN) | F3: Total Dia (kg MN) | G3: Nº Cab | H3: kg MN/cab | I3: Custo Dieta (R$/kg) | J3: Custo Total (R$) | K3: Obs
A4: 46220 | B4: 1 | C4: 599.9 | D4: 300 | E4: 599.9 | F4: =IF(AND(C4="",D4="",E4=""),"",N(C4)+N(D4)+N(E4)) -> 1499.8 | G4: =IF(B4="","",IFERROR(INDEX(Currais!$C:$C,MATCH(B4,Currais!$A:$A,0)),"")) -> 76 | H4: =IF(OR(F4="",G4="",G4=0),"",F4/G4) -> 19.734211 | I4: =IF(F4="","",IFERROR(LOOKUP(A4,Ingredientes_Dieta!$C$17:$C$18,Ingredientes_Dieta!$D$17:$D$18),Ingredientes_Dieta!$F$11)) -> 0.5825 | J4: =IF(F4="","",F4*I4) -> 873.6335 | K4: Dieta -10%
A5: 46221 | B5: 1 | C5: 599.9 | D5: 300 | E5: 599.9 | F5: =IF(AND(C5="",D5="",E5=""),"",N(C5)+N(D5)+N(E5)) -> 1499.8 | G5: =IF(B5="","",IFERROR(INDEX(Currais!$C:$C,MATCH(B5,Currais!$A:$A,0)),"")) -> 76 | H5: =IF(OR(F5="",G5="",G5=0),"",F5/G5) -> 19.734211 | I5: =IF(F5="","",IFERROR(LOOKUP(A5,Ingredientes_Dieta!$C$17:$C$18,Ingredientes_Dieta!$D$17:$D$18),Ingredientes_Dieta!$F$11)) -> 0.5825 | J5: =IF(F5="","",F5*I5) -> 873.6335 | K5: Dieta -10%
A6: 46222 | B6: 1 | C6: 599.9 | D6: 300 | E6: 599.9 | F6: =IF(AND(C6="",D6="",E6=""),"",N(C6)+N(D6)+N(E6)) -> 1499.8 | G6: =IF(B6="","",IFERROR(INDEX(Currais!$C:$C,MATCH(B6,Currais!$A:$A,0)),"")) -> 76 | H6: =IF(OR(F6="",G6="",G6=0),"",F6/G6) -> 19.734211 | I6: =IF(F6="","",IFERROR(LOOKUP(A6,Ingredientes_Dieta!$C$17:$C$18,Ingredientes_Dieta!$D$17:$D$18),Ingredientes_Dieta!$F$11)) -> 0.5825 | J6: =IF(F6="","",F6*I6) -> 873.6335 | K6: Dieta -10%
A7: 46223 | B7: 1 | C7: 599.9 | D7: 300 | E7: 599.9 | F7: =IF(AND(C7="",D7="",E7=""),"",N(C7)+N(D7)+N(E7)) -> 1499.8 | G7: =IF(B7="","",IFERROR(INDEX(Currais!$C:$C,MATCH(B7,Currais!$A:$A,0)),"")) -> 76 | H7: =IF(OR(F7="",G7="",G7=0),"",F7/G7) -> 19.734211 | I7: =IF(F7="","",IFERROR(LOOKUP(A7,Ingredientes_Dieta!$C$17:$C$18,Ingredientes_Dieta!$D$17:$D$18),Ingredientes_Dieta!$F$11)) -> 0.5825 | J7: =IF(F7="","",F7*I7) -> 873.6335 | K7: Dieta -10%
A8: 46224 | B8: 1 | C8: 599.9 | D8: 300 | E8: 599.9 | F8: =IF(AND(C8="",D8="",E8=""),"",N(C8)+N(D8)+N(E8)) -> 1499.8 | G8: =IF(B8="","",IFERROR(INDEX(Currais!$C:$C,MATCH(B8,Currais!$A:$A,0)),"")) -> 76 | H8: =IF(OR(F8="",G8="",G8=0),"",F8/G8) -> 19.734211 | I8: =IF(F8="","",IFERROR(LOOKUP(A8,Ingredientes_Dieta!$C$17:$C$18,Ingredientes_Dieta!$D$17:$D$18),Ingredientes_Dieta!$F$11)) -> 0.5825 | J8: =IF(F8="","",F8*I8) -> 873.6335 | K8: Dieta -10%
A9: 46225 | B9: 1 | C9: 599.9 | D9: 300 | E9: 599.9 | F9: =IF(AND(C9="",D9="",E9=""),"",N(C9)+N(D9)+N(E9)) -> 1499.8 | G9: =IF(B9="","",IFERROR(INDEX(Currais!$C:$C,MATCH(B9,Currais!$A:$A,0)),"")) -> 76 | H9: =IF(OR(F9="",G9="",G9=0),"",F9/G9) -> 19.734211 | I9: =IF(F9="","",IFERROR(LOOKUP(A9,Ingredientes_Dieta!$C$17:$C$18,Ingredientes_Dieta!$D$17:$D$18),Ingredientes_Dieta!$F$11)) -> 0.5825 | J9: =IF(F9="","",F9*I9) -> 873.6335 | K9: Dieta -10%
A10: 46226 | B10: 1 | C10: 599.9 | D10: 300 | E10: 599.9 | F10: =IF(AND(C10="",D10="",E10=""),"",N(C10)+N(D10)+N(E10)) -> 1499.8 | G10: =IF(B10="","",IFERROR(INDEX(Currais!$C:$C,MATCH(B10,Currais!$A:$A,0)),"")) -> 76 | H10: =IF(OR(F10="",G10="",G10=0),"",F10/G10) -> 19.734211 | I10: =IF(F10="","",IFERROR(LOOKUP(A10,Ingredientes_Dieta!$C$17:$C$18,Ingredientes_Dieta!$D$17:$D$18),Ingredientes_Dieta!$F$11)) -> 0.5825 | J10: =IF(F10="","",F10*I10) -> 873.6335 | K10: Dieta -10%
A11: 46227 | B11: 1 | C11: 599.9 | D11: 300 | E11: 599.9 | F11: =IF(AND(C11="",D11="",E11=""),"",N(C11)+N(D11)+N(E11)) -> 1499.8 | G11: =IF(B11="","",IFERROR(INDEX(Currais!$C:$C,MATCH(B11,Currais!$A:$A,0)),"")) -> 76 | H11: =IF(OR(F11="",G11="",G11=0),"",F11/G11) -> 19.734211 | I11: =IF(F11="","",IFERROR(LOOKUP(A11,Ingredientes_Dieta!$C$17:$C$18,Ingredientes_Dieta!$D$17:$D$18),Ingredientes_Dieta!$F$11)) -> 0.5825 | J11: =IF(F11="","",F11*I11) -> 873.6335 | K11: Dieta -10%
A12: 46228 | B12: 1 | C12: 599.9 | D12: 300 | E12: 599.9 | F12: =IF(AND(C12="",D12="",E12=""),"",N(C12)+N(D12)+N(E12)) -> 1499.8 | G12: =IF(B12="","",IFERROR(INDEX(Currais!$C:$C,MATCH(B12,Currais!$A:$A,0)),"")) -> 76 | H12: =IF(OR(F12="",G12="",G12=0),"",F12/G12) -> 19.734211 | I12: =IF(F12="","",IFERROR(LOOKUP(A12,Ingredientes_Dieta!$C$17:$C$18,Ingredientes_Dieta!$D$17:$D$18),Ingredientes_Dieta!$F$11)) -> 0.5825 | J12: =IF(F12="","",F12*I12) -> 873.6335 | K12: Dieta -10%
A13: 46229 | B13: 1 | C13: 599.9 | D13: 300 | E13: 599.9 | F13: =IF(AND(C13="",D13="",E13=""),"",N(C13)+N(D13)+N(E13)) -> 1499.8 | G13: =IF(B13="","",IFERROR(INDEX(Currais!$C:$C,MATCH(B13,Currais!$A:$A,0)),"")) -> 76 | H13: =IF(OR(F13="",G13="",G13=0),"",F13/G13) -> 19.734211 | I13: =IF(F13="","",IFERROR(LOOKUP(A13,Ingredientes_Dieta!$C$17:$C$18,Ingredientes_Dieta!$D$17:$D$18),Ingredientes_Dieta!$F$11)) -> 0.5825 | J13: =IF(F13="","",F13*I13) -> 873.6335 | K13: Dieta -10%
A14: 46230 | B14: 1 | C14: 599.9 | D14: 300 | E14: 599.9 | F14: =IF(AND(C14="",D14="",E14=""),"",N(C14)+N(D14)+N(E14)) -> 1499.8 | G14: =IF(B14="","",IFERROR(INDEX(Currais!$C:$C,MATCH(B14,Currais!$A:$A,0)),"")) -> 76 | H14: =IF(OR(F14="",G14="",G14=0),"",F14/G14) -> 19.734211 | I14: =IF(F14="","",IFERROR(LOOKUP(A14,Ingredientes_Dieta!$C$17:$C$18,Ingredientes_Dieta!$D$17:$D$18),Ingredientes_Dieta!$F$11)) -> 0.5825 | J14: =IF(F14="","",F14*I14) -> 873.6335 | K14: Dieta -10%
A15: 46231 | B15: 1 | C15: 599.9 | D15: 300 | E15: 599.9 | F15: =IF(AND(C15="",D15="",E15=""),"",N(C15)+N(D15)+N(E15)) -> 1499.8 | G15: =IF(B15="","",IFERROR(INDEX(Currais!$C:$C,MATCH(B15,Currais!$A:$A,0)),"")) -> 76 | H15: =IF(OR(F15="",G15="",G15=0),"",F15/G15) -> 19.734211 | I15: =IF(F15="","",IFERROR(LOOKUP(A15,Ingredientes_Dieta!$C$17:$C$18,Ingredientes_Dieta!$D$17:$D$18),Ingredientes_Dieta!$F$11)) -> 0.5825 | J15: =IF(F15="","",F15*I15) -> 873.6335 | K15: Dieta -10%
... A216: 46243 | B216: 10 | C216: 222 | D216: 111 | E216: 222 | F216: =IF(AND(C216="",D216="",E216=""),"",N(C216)+N(D216)+N(E216)) -> 555 | G216: =IF(B216="","",IFERROR(INDEX(Currais!$C:$C,MATCH(B216,Currais!$A:$A,0)),"")) -> 33 | H216: =IF(OR(F216="",G216="",G216=0),"",F216/G216) -> 16.818182 | I216: =IF(F216="","",IFERROR(LOOKUP(A216,Ingredientes_Dieta!$C$17:$C$18,Ingredientes_Dieta!$D$17:$D$18),Ingredientes_Dieta!$F$11)) -> 0.8227 | J216: =IF(F216="","",F216*I216) -> 456.5985 | K216: Novo consumo (07/08)

Sheet Custo_Nutricao_Lote
B2: CUSTO DE NUTRIÇÃO POR LOTE (CURRAL)
B3: Estimativa = consumo planejado/dia (Calculadora_Trato) × dias de confinamento × custo da dieta. Real = soma dos lançamentos do Trato_Diario. @ produzidas vêm das pesagens.
B5: Lote (Curral) | C5: Nº Cab | D5: Dias Conf | E5: Consumo Planej./dia (kg MN) | F5: Custo Dieta (R$/kg) | G5: Custo Ração/dia (R$) | H5: Custo/cab/dia (R$) | I5: Custo Estim. Acum. (R$) | J5: Custo Real Acum. (R$) | K5: Custo/cab Acum. (R$) | L5: @ Produzidas | M5: Custo Estim./@ (R$)
B6: 1 | C6: =IFERROR(INDEX(Currais!$C:$C,MATCH(B6,Currais!$A:$A,0)),0) -> 76 | D6: =IFERROR(Parâmetros!$C$4-_xlfn.MINIFS(Cadastro_Animais!$F$3:$F$5001,Cadastro_Animais!$E$3:$E$5001,B6),"") -> 18 | E6: =IFERROR(INDEX(Calculadora_Trato!$G$8:$G$17,MATCH(B6,Calculadora_Trato!$B$8:$B$17,0)),0) -> 1598 | F6: =Parâmetros!$C$6 -> 0.8227 | G6: =E6*F6 -> 1314.6746 | H6: =IF(C6=0,"",G6/C6) -> 17.29835 | I6: =IF(D6="","",G6*D6) -> 23664.143 | J6: =SUMIFS(Trato_Diario!$J$4:$J$300,Trato_Diario!$B$4:$B$300,B6) -> 24268.029 | K6: =IF(C6=0,"",I6/C6) -> 311.3703 | L6: =SUMIFS(Cadastro_Animais!$N$3:$N$5001,Cadastro_Animais!$E$3:$E$5001,B6) -> 0 | M6: =IF(L6<=0,"",I6/L6)
B7: 2 | C7: =IFERROR(INDEX(Currais!$C:$C,MATCH(B7,Currais!$A:$A,0)),0) -> 22 | D7: =IFERROR(Parâmetros!$C$4-_xlfn.MINIFS(Cadastro_Animais!$F$3:$F$5001,Cadastro_Animais!$E$3:$E$5001,B7),"") -> 18 | E7: =IFERROR(INDEX(Calculadora_Trato!$G$8:$G$17,MATCH(B7,Calculadora_Trato!$B$8:$B$17,0)),0) -> 487 | F7: =Parâmetros!$C$6 -> 0.8227 | G7: =E7*F7 -> 400.6549 | H7: =IF(C7=0,"",G7/C7) -> 18.211586 | I7: =IF(D7="","",G7*D7) -> 7211.7882 | J7: =SUMIFS(Trato_Diario!$J$4:$J$300,Trato_Diario!$B$4:$B$300,B7) -> 7708.8293 | K7: =IF(C7=0,"",I7/C7) -> 327.80855 | L7: =SUMIFS(Cadastro_Animais!$N$3:$N$5001,Cadastro_Animais!$E$3:$E$5001,B7) -> 0 | M7: =IF(L7<=0,"",I7/L7)
B8: 3 | C8: =IFERROR(INDEX(Currais!$C:$C,MATCH(B8,Currais!$A:$A,0)),0) -> 85 | D8: =IFERROR(Parâmetros!$C$4-_xlfn.MINIFS(Cadastro_Animais!$F$3:$F$5001,Cadastro_Animais!$E$3:$E$5001,B8),"") -> 18 | E8: =IFERROR(INDEX(Calculadora_Trato!$G$8:$G$17,MATCH(B8,Calculadora_Trato!$B$8:$B$17,0)),0) -> 1618 | F8: =Parâmetros!$C$6 -> 0.8227 | G8: =E8*F8 -> 1331.1286 | H8: =IF(C8=0,"",G8/C8) -> 15.660336 | I8: =IF(D8="","",G8*D8) -> 23960.315 | J8: =SUMIFS(Trato_Diario!$J$4:$J$300,Trato_Diario!$B$4:$B$300,B8) -> 24586.457 | K8: =IF(C8=0,"",I8/C8) -> 281.88606 | L8: =SUMIFS(Cadastro_Animais!$N$3:$N$5001,Cadastro_Animais!$E$3:$E$5001,B8) -> 0 | M8: =IF(L8<=0,"",I8/L8)
B9: 4 | C9: =IFERROR(INDEX(Currais!$C:$C,MATCH(B9,Currais!$A:$A,0)),0) -> 90 | D9: =IFERROR(Parâmetros!$C$4-_xlfn.MINIFS(Cadastro_Animais!$F$3:$F$5001,Cadastro_Animais!$E$3:$E$5001,B9),"") -> 17 | E9: =IFERROR(INDEX(Calculadora_Trato!$G$8:$G$17,MATCH(B9,Calculadora_Trato!$B$8:$B$17,0)),0) -> 1596 | F9: =Parâmetros!$C$6 -> 0.8227 | G9: =E9*F9 -> 1313.0292 | H9: =IF(C9=0,"",G9/C9) -> 14.589213 | I9: =IF(D9="","",G9*D9) -> 22321.496 | J9: =SUMIFS(Trato_Diario!$J$4:$J$300,Trato_Diario!$B$4:$B$300,B9) -> 23358.855 | K9: =IF(C9=0,"",I9/C9) -> 248.01663 | L9: =SUMIFS(Cadastro_Animais!$N$3:$N$5001,Cadastro_Animais!$E$3:$E$5001,B9) -> 0 | M9: =IF(L9<=0,"",I9/L9)
B10: 5 | C10: =IFERROR(INDEX(Currais!$C:$C,MATCH(B10,Currais!$A:$A,0)),0) -> 88 | D10: =IFERROR(Parâmetros!$C$4-_xlfn.MINIFS(Cadastro_Animais!$F$3:$F$5001,Cadastro_Animais!$E$3:$E$5001,B10),"") -> 17 | E10: =IFERROR(INDEX(Calculadora_Trato!$G$8:$G$17,MATCH(B10,Calculadora_Trato!$B$8:$B$17,0)),0) -> 1477 | F10: =Parâmetros!$C$6 -> 0.8227 | G10: =E10*F10 -> 1215.1279 | H10: =IF(C10=0,"",G10/C10) -> 13.808272 | I10: =IF(D10="","",G10*D10) -> 20657.174 | J10: =SUMIFS(Trato_Diario!$J$4:$J$300,Trato_Diario!$B$4:$B$300,B10) -> 21561.29 | K10: =IF(C10=0,"",I10/C10) -> 234.74062 | L10: =SUMIFS(Cadastro_Animais!$N$3:$N$5001,Cadastro_Animais!$E$3:$E$5001,B10) -> 0 | M10: =IF(L10<=0,"",I10/L10)
B11: 6 | C11: =IFERROR(INDEX(Currais!$C:$C,MATCH(B11,Currais!$A:$A,0)),0) -> 85 | D11: =IFERROR(Parâmetros!$C$4-_xlfn.MINIFS(Cadastro_Animais!$F$3:$F$5001,Cadastro_Animais!$E$3:$E$5001,B11),"") -> 14 | E11: =IFERROR(INDEX(Calculadora_Trato!$G$8:$G$17,MATCH(B11,Calculadora_Trato!$B$8:$B$17,0)),0) -> 1451 | F11: =Parâmetros!$C$6 -> 0.8227 | G11: =E11*F11 -> 1193.7377 | H11: =IF(C11=0,"",G11/C11) -> 14.043973 | I11: =IF(D11="","",G11*D11) -> 16712.328 | J11: =SUMIFS(Trato_Diario!$J$4:$J$300,Trato_Diario!$B$4:$B$300,B11) -> 19605.439 | K11: =IF(C11=0,"",I11/C11) -> 196.61562 | L11: =SUMIFS(Cadastro_Animais!$N$3:$N$5001,Cadastro_Animais!$E$3:$E$5001,B11) -> 0 | M11: =IF(L11<=0,"",I11/L11)
B12: 7 | C12: =IFERROR(INDEX(Currais!$C:$C,MATCH(B12,Currais!$A:$A,0)),0) -> 85 | D12: =IFERROR(Parâmetros!$C$4-_xlfn.MINIFS(Cadastro_Animais!$F$3:$F$5001,Cadastro_Animais!$E$3:$E$5001,B12),"") -> 14 | E12: =IFERROR(INDEX(Calculadora_Trato!$G$8:$G$17,MATCH(B12,Calculadora_Trato!$B$8:$B$17,0)),0) -> 1560 | F12: =Parâmetros!$C$6 -> 0.8227 | G12: =E12*F12 -> 1283.412 | H12: =IF(C12=0,"",G12/C12) -> 15.098965 | I12: =IF(D12="","",G12*D12) -> 17967.768 | J12: =SUMIFS(Trato_Diario!$J$4:$J$300,Trato_Diario!$B$4:$B$300,B12) -> 21096.947 | K12: =IF(C12=0,"",I12/C12) -> 211.38551 | L12: =SUMIFS(Cadastro_Animais!$N$3:$N$5001,Cadastro_Animais!$E$3:$E$5001,B12) -> 0 | M12: =IF(L12<=0,"",I12/L12)
B13: 8 | C13: =IFERROR(INDEX(Currais!$C:$C,MATCH(B13,Currais!$A:$A,0)),0) -> 68 | D13: =IFERROR(Parâmetros!$C$4-_xlfn.MINIFS(Cadastro_Animais!$F$3:$F$5001,Cadastro_Animais!$E$3:$E$5001,B13),"") -> 13 | E13: =IFERROR(INDEX(Calculadora_Trato!$G$8:$G$17,MATCH(B13,Calculadora_Trato!$B$8:$B$17,0)),0) -> 1247 | F13: =Parâmetros!$C$6 -> 0.8227 | G13: =E13*F13 -> 1025.9069 | H13: =IF(C13=0,"",G13/C13) -> 15.086866 | I13: =IF(D13="","",G13*D13) -> 13336.79 | J13: =SUMIFS(Trato_Diario!$J$4:$J$300,Trato_Diario!$B$4:$B$300,B13) -> 15532.267 | K13: =IF(C13=0,"",I13/C13) -> 196.12926 | L13: =SUMIFS(Cadastro_Animais!$N$3:$N$5001,Cadastro_Animais!$E$3:$E$5001,B13) -> 0 | M13: =IF(L13<=0,"",I13/L13)
B14: 9 | C14: =IFERROR(INDEX(Currais!$C:$C,MATCH(B14,Currais!$A:$A,0)),0) -> 14 | D14: =IFERROR(Parâmetros!$C$4-_xlfn.MINIFS(Cadastro_Animais!$F$3:$F$5001,Cadastro_Animais!$E$3:$E$5001,B14),"") -> 13 | E14: =IFERROR(INDEX(Calculadora_Trato!$G$8:$G$17,MATCH(B14,Calculadora_Trato!$B$8:$B$17,0)),0) -> 211 | F14: =Parâmetros!$C$6 -> 0.8227 | G14: =E14*F14 -> 173.5897 | H14: =IF(C14=0,"",G14/C14) -> 12.399264 | I14: =IF(D14="","",G14*D14) -> 2256.6661 | J14: =SUMIFS(Trato_Diario!$J$4:$J$300,Trato_Diario!$B$4:$B$300,B14) -> 2706.7901 | K14: =IF(C14=0,"",I14/C14) -> 161.19044 | L14: =SUMIFS(Cadastro_Animais!$N$3:$N$5001,Cadastro_Animais!$E$3:$E$5001,B14) -> 0 | M14: =IF(L14<=0,"",I14/L14)
B15: 10 | C15: =IFERROR(INDEX(Currais!$C:$C,MATCH(B15,Currais!$A:$A,0)),0) -> 33 | D15: =IFERROR(Parâmetros!$C$4-_xlfn.MINIFS(Cadastro_Animais!$F$3:$F$5001,Cadastro_Animais!$E$3:$E$5001,B15),"") -> 11 | E15: =IFERROR(INDEX(Calculadora_Trato!$G$8:$G$17,MATCH(B15,Calculadora_Trato!$B$8:$B$17,0)),0) -> 555 | F15: =Parâmetros!$C$6 -> 0.8227 | G15: =E15*F15 -> 456.5985 | H15: =IF(C15=0,"",G15/C15) -> 13.836318 | I15: =IF(D15="","",G15*D15) -> 5022.5835 | J15: =SUMIFS(Trato_Diario!$J$4:$J$300,Trato_Diario!$B$4:$B$300,B15) -> 6551.8892 | K15: =IF(C15=0,"",I15/C15) -> 152.1995 | L15: =SUMIFS(Cadastro_Animais!$N$3:$N$5001,Cadastro_Animais!$E$3:$E$5001,B15) -> 0 | M15: =IF(L15<=0,"",I15/L15)
B16: TOTAL | C16: =SUM(C6:C15) -> 646 | G16: =SUM(G6:G15) -> 9707.86 | H16: =IF(C16=0,"",G16/C16) -> 15.027647 | I16: =SUM(I6:I15) -> 153111.05 | J16: =SUM(J6:J15) -> 166976.79 | K16: =IF(C16=0,"",I16/C16) -> 237.01401 | L16: =SUM(L6:L15) -> 0 | M16: =IF(L16<=0,"",I16/L16)

Sheet Custo_Diario_Cab
A1: CUSTO MÉDIO DIÁRIO DE RAÇÃO POR CABEÇA — POR CURRAL
A2: Custo REAL de ração por cabeça por dia (custo do trato do dia ÷ nº de cabeças). A linha MÉDIA DIÁRIA = custo total do período ÷ (dias × cabeças) de cada curral. Tudo atualiza conforme você lança os tratos.
B4: Curral 1 | C4: Curral 2 | D4: Curral 3 | E4: Curral 4 | F4: Curral 5 | G4: Curral 6 | H4: Curral 7 | I4: Curral 8 | J4: Curral 9 | K4: Curral 10 | L4: Rebanho
A5: Nº cabeças | B5: =IFERROR(INDEX(Currais!$C$3:$C$12,MATCH(1,Currais!$A$3:$A$12,0)),0) -> 76 | C5: =IFERROR(INDEX(Currais!$C$3:$C$12,MATCH(2,Currais!$A$3:$A$12,0)),0) -> 22 | D5: =IFERROR(INDEX(Currais!$C$3:$C$12,MATCH(3,Currais!$A$3:$A$12,0)),0) -> 85 | E5: =IFERROR(INDEX(Currais!$C$3:$C$12,MATCH(4,Currais!$A$3:$A$12,0)),0) -> 90 | F5: =IFERROR(INDEX(Currais!$C$3:$C$12,MATCH(5,Currais!$A$3:$A$12,0)),0) -> 88 | G5: =IFERROR(INDEX(Currais!$C$3:$C$12,MATCH(6,Currais!$A$3:$A$12,0)),0) -> 85 | H5: =IFERROR(INDEX(Currais!$C$3:$C$12,MATCH(7,Currais!$A$3:$A$12,0)),0) -> 85 | I5: =IFERROR(INDEX(Currais!$C$3:$C$12,MATCH(8,Currais!$A$3:$A$12,0)),0) -> 68 | J5: =IFERROR(INDEX(Currais!$C$3:$C$12,MATCH(9,Currais!$A$3:$A$12,0)),0) -> 14 | K5: =IFERROR(INDEX(Currais!$C$3:$C$12,MATCH(10,Currais!$A$3:$A$12,0)),0) -> 33 | L5: =SUM(B5:K5) -> 646
A6: Dias com trato | B6: =COUNTIFS(Trato_Diario!$B$4:$B$300,1,Trato_Diario!$F$4:$F$300,"<>") -> 24 | C6: =COUNTIFS(Trato_Diario!$B$4:$B$300,2,Trato_Diario!$F$4:$F$300,"<>") -> 24 | D6: =COUNTIFS(Trato_Diario!$B$4:$B$300,3,Trato_Diario!$F$4:$F$300,"<>") -> 24 | E6: =COUNTIFS(Trato_Diario!$B$4:$B$300,4,Trato_Diario!$F$4:$F$300,"<>") -> 23 | F6: =COUNTIFS(Trato_Diario!$B$4:$B$300,5,Trato_Diario!$F$4:$F$300,"<>") -> 23 | G6: =COUNTIFS(Trato_Diario!$B$4:$B$300,6,Trato_Diario!$F$4:$F$300,"<>") -> 20 | H6: =COUNTIFS(Trato_Diario!$B$4:$B$300,7,Trato_Diario!$F$4:$F$300,"<>") -> 20 | I6: =COUNTIFS(Trato_Diario!$B$4:$B$300,8,Trato_Diario!$F$4:$F$300,"<>") -> 19 | J6: =COUNTIFS(Trato_Diario!$B$4:$B$300,9,Trato_Diario!$F$4:$F$300,"<>") -> 19 | K6: =COUNTIFS(Trato_Diario!$B$4:$B$300,10,Trato_Diario!$F$4:$F$300,"<>") -> 17
A7: MÉDIA DIÁRIA (R$/cab/dia) | B7: =IFERROR(SUMIFS(Trato_Diario!$J$4:$J$300,Trato_Diario!$B$4:$B$300,1)/SUMIFS(Trato_Diario!$G$4:$G$300,Trato_Diario!$B$4:$B$300,1),"") -> 13.304841 | C7: =IFERROR(SUMIFS(Trato_Diario!$J$4:$J$300,Trato_Diario!$B$4:$B$300,2)/SUMIFS(Trato_Diario!$G$4:$G$300,Trato_Diario!$B$4:$B$300,2),"") -> 14.600055 | D7: =IFERROR(SUMIFS(Trato_Diario!$J$4:$J$300,Trato_Diario!$B$4:$B$300,3)/SUMIFS(Trato_Diario!$G$4:$G$300,Trato_Diario!$B$4:$B$300,3),"") -> 12.052185 | E7: =IFERROR(SUMIFS(Trato_Diario!$J$4:$J$300,Trato_Diario!$B$4:$B$300,4)/SUMIFS(Trato_Diario!$G$4:$G$300,Trato_Diario!$B$4:$B$300,4),"") -> 11.284471 | F7: =IFERROR(SUMIFS(Trato_Diario!$J$4:$J$300,Trato_Diario!$B$4:$B$300,5)/SUMIFS(Trato_Diario!$G$4:$G$300,Trato_Diario!$B$4:$B$300,5),"") -> 10.652811 | G7: =IFERROR(SUMIFS(Trato_Diario!$J$4:$J$300,Trato_Diario!$B$4:$B$300,6)/SUMIFS(Trato_Diario!$G$4:$G$300,Trato_Diario!$B$4:$B$300,6),"") -> 11.532611 | H7: =IFERROR(SUMIFS(Trato_Diario!$J$4:$J$300,Trato_Diario!$B$4:$B$300,7)/SUMIFS(Trato_Diario!$G$4:$G$300,Trato_Diario!$B$4:$B$300,7),"") -> 12.409969 | I7: =IFERROR(SUMIFS(Trato_Diario!$J$4:$J$300,Trato_Diario!$B$4:$B$300,8)/SUMIFS(Trato_Diario!$G$4:$G$300,Trato_Diario!$B$4:$B$300,8),"") -> 12.021879 | J7: =IFERROR(SUMIFS(Trato_Diario!$J$4:$J$300,Trato_Diario!$B$4:$B$300,9)/SUMIFS(Trato_Diario!$G$4:$G$300,Trato_Diario!$B$4:$B$300,9),"") -> 10.175903 | K7: =IFERROR(SUMIFS(Trato_Diario!$J$4:$J$300,Trato_Diario!$B$4:$B$300,10)/SUMIFS(Trato_Diario!$G$4:$G$300,Trato_Diario!$B$4:$B$300,10),"") -> 11.678947 | L7: =IFERROR(SUM(Trato_Diario!$J$4:$J$300)/SUM(Trato_Diario!$G$4:$G$300),"") -> 11.922656
A9: DETALHE DIA A DIA — custo do dia por cabeça (R$/cab/dia)
A10: Data | B10: Curral 1 | C10: Curral 2 | D10: Curral 3 | E10: Curral 4 | F10: Curral 5 | G10: Curral 6 | H10: Curral 7 | I10: Curral 8 | J10: Curral 9 | K10: Curral 10 | L10: Rebanho
A11: 46220 | B11: =IF(OR($A11>MAX(Trato_Diario!$A$4:$A$300),SUMIFS(Trato_Diario!$G$4:$G$300,Trato_Diario!$B$4:$B$300,1,Trato_Diario!$A$4:$A$300,$A11)=0),"",SUMIFS(Trato_Diario!$J$4:$J$300,Trato_Diario!$B$4:$B$300,1,Trato_Diario!$A$4:$A$300,$A11)/SUMIFS(Trato_Diario!$G$4:$G$300,Trato_Diario!$B$4:$B$300,1,Trato_Diario!$A$4:$A$300,$A11)) -> 11.495178 | C11: =IF(OR($A11>MAX(Trato_Diario!$A$4:$A$300),SUMIFS(Trato_Diario!$G$4:$G$300,Trato_Diario!$B$4:$B$300,2,Trato_Diario!$A$4:$A$300,$A11)=0),"",SUMIFS(Trato_Diario!$J$4:$J$300,Trato_Diario!$B$4:$B$300,2,Trato_Diario!$A$4:$A$300,$A11)/SUMIFS(Trato_Diario!$G$4:$G$300,Trato_Diario!$B$4:$B$300,2,Trato_Diario!$A$4:$A$300,$A11)) -> 12.714386 | D11: =IF(OR($A11>MAX(Trato_Diario!$A$4:$A$300),SUMIFS(Trato_Diario!$G$4:$G$300,Trato_Diario!$B$4:$B$300,3,Trato_Diario!$A$4:$A$300,$A11)=0),"",SUMIFS(Trato_Diario!$J$4:$J$300,Trato_Diario!$B$4:$B$300,3,Trato_Diario!$A$4:$A$300,$A11)/SUMIFS(Trato_Diario!$G$4:$G$300,Trato_Diario!$B$4:$B$300,3,Trato_Diario!$A$4:$A$300,$A11)) -> 10.414415 | E11: =IF(OR($A11>MAX(Trato_Diario!$A$4:$A$300),SUMIFS(Trato_Diario!$G$4:$G$300,Trato_Diario!$B$4:$B$300,4,Trato_Diario!$A$4:$A$300,$A11)=0),"",SUMIFS(Trato_Diario!$J$4:$J$300,Trato_Diario!$B$4:$B$300,4,Trato_Diario!$A$4:$A$300,$A11)/SUMIFS(Trato_Diario!$G$4:$G$300,Trato_Diario!$B$4:$B$300,4,Trato_Diario!$A$4:$A$300,$A11)) | F11: =IF(OR($A11>MAX(Trato_Diario!$A$4:$A$300),SUMIFS(Trato_Diario!$G$4:$G$300,Trato_Diario!$B$4:$B$300,5,Trato_Diario!$A$4:$A$300,$A11)=0),"",SUMIFS(Trato_Diario!$J$4:$J$300,Trato_Diario!$B$4:$B$300,5,Trato_Diario!$A$4:$A$300,$A11)/SUMIFS(Trato_Diario!$G$4:$G$300,Trato_Diario!$B$4:$B$300,5,Trato_Diario!$A$4:$A$300,$A11)) | G11: =IF(OR($A11>MAX(Trato_Diario!$A$4:$A$300),SUMIFS(Trato_Diario!$G$4:$G$300,Trato_Diario!$B$4:$B$300,6,Trato_Diario!$A$4:$A$300,$A11)=0),"",SUMIFS(Trato_Diario!$J$4:$J$300,Trato_Diario!$B$4:$B$300,6,Trato_Diario!$A$4:$A$300,$A11)/SUMIFS(Trato_Diario!$G$4:$G$300,Trato_Diario!$B$4:$B$300,6,Trato_Diario!$A$4:$A$300,$A11)) | H11: =IF(OR($A11>MAX(Trato_Diario!$A$4:$A$300),SUMIFS(Trato_Diario!$G$4:$G$300,Trato_Diario!$B$4:$B$300,7,Trato_Diario!$A$4:$A$300,$A11)=0),"",SUMIFS(Trato_Diario!$J$4:$J$300,Trato_Diario!$B$4:$B$300,7,Trato_Diario!$A$4:$A$300,$A11)/SUMIFS(Trato_Diario!$G$4:$G$300,Trato_Diario!$B$4:$B$300,7,Trato_Diario!$A$4:$A$300,$A11)) | I11: =IF(OR($A11>MAX(Trato_Diario!$A$4:$A$300),SUMIFS(Trato_Diario!$G$4:$G$300,Trato_Diario!$B$4:$B$300,8,Trato_Diario!$A$4:$A$300,$A11)=0),"",SUMIFS(Trato_Diario!$J$4:$J$300,Trato_Diario!$B$4:$B$300,8,Trato_Diario!$A$4:$A$300,$A11)/SUMIFS(Trato_Diario!$G$4:$G$300,Trato_Diario!$B$4:$B$300,8,Trato_Diario!$A$4:$A$300,$A11)) | J11: =IF(OR($A11>MAX(Trato_Diario!$A$4:$A$300),SUMIFS(Trato_Diario!$G$4:$G$300,Trato_Diario!$B$4:$B$300,9,Trato_Diario!$A$4:$A$300,$A11)=0),"",SUMIFS(Trato_Diario!$J$4:$J$300,Trato_Diario!$B$4:$B$300,9,Trato_Diario!$A$4:$A$300,$A11)/SUMIFS(Trato_Diario!$G$4:$G$300,Trato_Diario!$B$4:$B$300,9,Trato_Diario!$A$4:$A$300,$A11)) | K11: =IF(OR($A11>MAX(Trato_Diario!$A$4:$A$300),SUMIFS(Trato_Diario!$G$4:$G$300,Trato_Diario!$B$4:$B$300,10,Trato_Diario!$A$4:$A$300,$A11)=0),"",SUMIFS(Trato_Diario!$J$4:$J$300,Trato_Diario!$B$4:$B$300,10,Trato_Diario!$A$4:$A$300,$A11)/SUMIFS(Trato_Diario!$G$4:$G$300,Trato_Diario!$B$4:$B$300,10,Trato_Diario!$A$4:$A$300,$A11)) | L11: =IF(OR($A11>MAX(Trato_Diario!$A$4:$A$300),SUMIFS(Trato_Diario!$G$4:$G$300,Trato_Diario!$A$4:$A$300,$A11)=0),"",SUMIFS(Trato_Diario!$J$4:$J$300,Trato_Diario!$A$4:$A$300,$A11)/SUMIFS(Trato_Diario!$G$4:$G$300,Trato_Diario!$A$4:$A$300,$A11)) -> 11.139755
A12: 46221 | B12: =IF(OR($A12>MAX(Trato_Diario!$A$4:$A$300),SUMIFS(Trato_Diario!$G$4:$G$300,Trato_Diario!$B$4:$B$300,1,Trato_Diario!$A$4:$A$300,$A12)=0),"",SUMIFS(Trato_Diario!$J$4:$J$300,Trato_Diario!$B$4:$B$300,1,Trato_Diario!$A$4:$A$300,$A12)/SUMIFS(Trato_Diario!$G$4:$G$300,Trato_Diario!$B$4:$B$300,1,Trato_Diario!$A$4:$A$300,$A12)) -> 11.495178 | C12: =IF(OR($A12>MAX(Trato_Diario!$A$4:$A$300),SUMIFS(Trato_Diario!$G$4:$G$300,Trato_Diario!$B$4:$B$300,2,Trato_Diario!$A$4:$A$300,$A12)=0),"",SUMIFS(Trato_Diario!$J$4:$J$300,Trato_Diario!$B$4:$B$300,2,Trato_Diario!$A$4:$A$300,$A12)/SUMIFS(Trato_Diario!$G$4:$G$300,Trato_Diario!$B$4:$B$300,2,Trato_Diario!$A$4:$A$300,$A12)) -> 12.714386 | D12: =IF(OR($A12>MAX(Trato_Diario!$A$4:$A$300),SUMIFS(Trato_Diario!$G$4:$G$300,Trato_Diario!$B$4:$B$300,3,Trato_Diario!$A$4:$A$300,$A12)=0),"",SUMIFS(Trato_Diario!$J$4:$J$300,Trato_Diario!$B$4:$B$300,3,Trato_Diario!$A$4:$A$300,$A12)/SUMIFS(Trato_Diario!$G$4:$G$300,Trato_Diario!$B$4:$B$300,3,Trato_Diario!$A$4:$A$300,$A12)) -> 10.414415 | E12: =IF(OR($A12>MAX(Trato_Diario!$A$4:$A$300),SUMIFS(Trato_Diario!$G$4:$G$300,Trato_Diario!$B$4:$B$300,4,Trato_Diario!$A$4:$A$300,$A12)=0),"",SUMIFS(Trato_Diario!$J$4:$J$300,Trato_Diario!$B$4:$B$300,4,Trato_Diario!$A$4:$A$300,$A12)/SUMIFS(Trato_Diario!$G$4:$G$300,Trato_Diario!$B$4:$B$300,4,Trato_Diario!$A$4:$A$300,$A12)) -> 9.6921528 | F12: =IF(OR($A12>MAX(Trato_Diario!$A$4:$A$300),SUMIFS(Trato_Diario!$G$4:$G$300,Trato_Diario!$B$4:$B$300,5,Trato_Diario!$A$4:$A$300,$A12)=0),"",SUMIFS(Trato_Diario!$J$4:$J$300,Trato_Diario!$B$4:$B$300,5,Trato_Diario!$A$4:$A$300,$A12)/SUMIFS(Trato_Diario!$G$4:$G$300,Trato_Diario!$B$4:$B$300,5,Trato_Diario!$A$4:$A$300,$A12)) -> 9.1445881 | G12: =IF(OR($A12>MAX(Trato_Diario!$A$4:$A$300),SUMIFS(Trato_Diario!$G$4:$G$300,Trato_Diario!$B$4:$B$300,6,Trato_Diario!$A$4:$A$300,$A12)=0),"",SUMIFS(Trato_Diario!$J$4:$J$300,Trato_Diario!$B$4:$B$300,6,Trato_Diario!$A$4:$A$300,$A12)/SUMIFS(Trato_Diario!$G$4:$G$300,Trato_Diario!$B$4:$B$300,6,Trato_Diario!$A$4:$A$300,$A12)) | H12: =IF(OR($A12>MAX(Trato_Diario!$A$4:$A$300),SUMIFS(Trato_Diario!$G$4:$G$300,Trato_Diario!$B$4:$B$300,7,Trato_Diario!$A$4:$A$300,$A12)=0),"",SUMIFS(Trato_Diario!$J$4:$J$300,Trato_Diario!$B$4:$B$300,7,Trato_Diario!$A$4:$A$300,$A12)/SUMIFS(Trato_Diario!$G$4:$G$300,Trato_Diario!$B$4:$B$300,7,Trato_Diario!$A$4:$A$300,$A12)) | I12: =IF(OR($A12>MAX(Trato_Diario!$A$4:$A$300),SUMIFS(Trato_Diario!$G$4:$G$300,Trato_Diario!$B$4:$B$300,8,Trato_Diario!$A$4:$A$300,$A12)=0),"",SUMIFS(Trato_Diario!$J$4:$J$300,Trato_Diario!$B$4:$B$300,8,Trato_Diario!$A$4:$A$300,$A12)/SUMIFS(Trato_Diario!$G$4:$G$300,Trato_Diario!$B$4:$B$300,8,Trato_Diario!$A$4:$A$300,$A12)) | J12: =IF(OR($A12>MAX(Trato_Diario!$A$4:$A$300),SUMIFS(Trato_Diario!$G$4:$G$300,Trato_Diario!$B$4:$B$300,9,Trato_Diario!$A$4:$A$300,$A12)=0),"",SUMIFS(Trato_Diario!$J$4:$J$300,Trato_Diario!$B$4:$B$300,9,Trato_Diario!$A$4:$A$300,$A12)/SUMIFS(Trato_Diario!$G$4:$G$300,Trato_Diario!$B$4:$B$300,9,Trato_Diario!$A$4:$A$300,$A12)) | K12: =IF(OR($A12>MAX(Trato_Diario!$A$4:$A$300),SUMIFS(Trato_Diario!$G$4:$G$300,Trato_Diario!$B$4:$B$300,10,Trato_Diario!$A$4:$A$300,$A12)=0),"",SUMIFS(Trato_Diario!$J$4:$J$300,Trato_Diario!$B$4:$B$300,10,Trato_Diario!$A$4:$A$300,$A12)/SUMIFS(Trato_Diario!$G$4:$G$300,Trato_Diario!$B$4:$B$300,10,Trato_Diario!$A$4:$A$300,$A12)) | L12: =IF(OR($A12>MAX(Trato_Diario!$A$4:$A$300),SUMIFS(Trato_Diario!$G$4:$G$300,Trato_Diario!$A$4:$A$300,$A12)=0),"",SUMIFS(Trato_Diario!$J$4:$J$300,Trato_Diario!$A$4:$A$300,$A12)/SUMIFS(Trato_Diario!$G$4:$G$300,Trato_Diario!$A$4:$A$300,$A12)) -> 10.292501
A13: 46222 | B13: =IF(OR($A13>MAX(Trato_Diario!$A$4:$A$300),SUMIFS(Trato_Diario!$G$4:$G$300,Trato_Diario!$B$4:$B$300,1,Trato_Diario!$A$4:$A$300,$A13)=0),"",SUMIFS(Trato_Diario!$J$4:$J$300,Trato_Diario!$B$4:$B$300,1,Trato_Diario!$A$4:$A$300,$A13)/SUMIFS(Trato_Diario!$G$4:$G$300,Trato_Diario!$B$4:$B$300,1,Trato_Diario!$A$4:$A$300,$A13)) -> 11.495178 | C13: =IF(OR($A13>MAX(Trato_Diario!$A$4:$A$300),SUMIFS(Trato_Diario!$G$4:$G$300,Trato_Diario!$B$4:$B$300,2,Trato_Diario!$A$4:$A$300,$A13)=0),"",SUMIFS(Trato_Diario!$J$4:$J$300,Trato_Diario!$B$4:$B$300,2,Trato_Diario!$A$4:$A$300,$A13)/SUMIFS(Trato_Diario!$G$4:$G$300,Trato_Diario!$B$4:$B$300,2,Trato_Diario!$A$4:$A$300,$A13)) -> 12.714386 | D13: =IF(OR($A13>MAX(Trato_Diario!$A$4:$A$300),SUMIFS(Trato_Diario!$G$4:$G$300,Trato_Diario!$B$4:$B$300,3,Trato_Diario!$A$4:$A$300,$A13)=0),"",SUMIFS(Trato_Diario!$J$4:$J$300,Trato_Diario!$B$4:$B$300,3,Trato_Diario!$A$4:$A$300,$A13)/SUMIFS(Trato_Diario!$G$4:$G$300,Trato_Diario!$B$4:$B$300,3,Trato_Diario!$A$4:$A$300,$A13)) -> 10.414415 | E13: =IF(OR($A13>MAX(Trato_Diario!$A$4:$A$300),SUMIFS(Trato_Diario!$G$4:$G$300,Trato_Diario!$B$4:$B$300,4,Trato_Diario!$A$4:$A$300,$A13)=0),"",SUMIFS(Trato_Diario!$J$4:$J$300,Trato_Diario!$B$4:$B$300,4,Trato_Diario!$A$4:$A$300,$A13)/SUMIFS(Trato_Diario!$G$4:$G$300,Trato_Diario!$B$4:$B$300,4,Trato_Diario!$A$4:$A$300,$A13)) -> 9.6921528 | F13: =IF(OR($A13>MAX(Trato_Diario!$A$4:$A$300),SUMIFS(Trato_Diario!$G$4:$G$300,Trato_Diario!$B$4:$B$300,5,Trato_Diario!$A$4:$A$300,$A13)=0),"",SUMIFS(Trato_Diario!$J$4:$J$300,Trato_Diario!$B$4:$B$300,5,Trato_Diario!$A$4:$A$300,$A13)/SUMIFS(Trato_Diario!$G$4:$G$300,Trato_Diario!$B$4:$B$300,5,Trato_Diario!$A$4:$A$300,$A13)) -> 9.1445881 | G13: =IF(OR($A13>MAX(Trato_Diario!$A$4:$A$300),SUMIFS(Trato_Diario!$G$4:$G$300,Trato_Diario!$B$4:$B$300,6,Trato_Diario!$A$4:$A$300,$A13)=0),"",SUMIFS(Trato_Diario!$J$4:$J$300,Trato_Diario!$B$4:$B$300,6,Trato_Diario!$A$4:$A$300,$A13)/SUMIFS(Trato_Diario!$G$4:$G$300,Trato_Diario!$B$4:$B$300,6,Trato_Diario!$A$4:$A$300,$A13)) | H13: =IF(OR($A13>MAX(Trato_Diario!$A$4:$A$300),SUMIFS(Trato_Diario!$G$4:$G$300,Trato_Diario!$B$4:$B$300,7,Trato_Diario!$A$4:$A$300,$A13)=0),"",SUMIFS(Trato_Diario!$J$4:$J$300,Trato_Diario!$B$4:$B$300,7,Trato_Diario!$A$4:$A$300,$A13)/SUMIFS(Trato_Diario!$G$4:$G$300,Trato_Diario!$B$4:$B$300,7,Trato_Diario!$A$4:$A$300,$A13)) | I13: =IF(OR($A13>MAX(Trato_Diario!$A$4:$A$300),SUMIFS(Trato_Diario!$G$4:$G$300,Trato_Diario!$B$4:$B$300,8,Trato_Diario!$A$4:$A$300,$A13)=0),"",SUMIFS(Trato_Diario!$J$4:$J$300,Trato_Diario!$B$4:$B$300,8,Trato_Diario!$A$4:$A$300,$A13)/SUMIFS(Trato_Diario!$G$4:$G$300,Trato_Diario!$B$4:$B$300,8,Trato_Diario!$A$4:$A$300,$A13)) | J13: =IF(OR($A13>MAX(Trato_Diario!$A$4:$A$300),SUMIFS(Trato_Diario!$G$4:$G$300,Trato_Diario!$B$4:$B$300,9,Trato_Diario!$A$4:$A$300,$A13)=0),"",SUMIFS(Trato_Diario!$J$4:$J$300,Trato_Diario!$B$4:$B$300,9,Trato_Diario!$A$4:$A$300,$A13)/SUMIFS(Trato_Diario!$G$4:$G$300,Trato_Diario!$B$4:$B$300,9,Trato_Diario!$A$4:$A$300,$A13)) | K13: =IF(OR($A13>MAX(Trato_Diario!$A$4:$A$300),SUMIFS(Trato_Diario!$G$4:$G$300,Trato_Diario!$B$4:$B$300,10,Trato_Diario!$A$4:$A$300,$A13)=0),"",SUMIFS(Trato_Diario!$J$4:$J$300,Trato_Diario!$B$4:$B$300,10,Trato_Diario!$A$4:$A$300,$A13)/SUMIFS(Trato_Diario!$G$4:$G$300,Trato_Diario!$B$4:$B$300,10,Trato_Diario!$A$4:$A$300,$A13)) | L13: =IF(OR($A13>MAX(Trato_Diario!$A$4:$A$300),SUMIFS(Trato_Diario!$G$4:$G$300,Trato_Diario!$A$4:$A$300,$A13)=0),"",SUMIFS(Trato_Diario!$J$4:$J$300,Trato_Diario!$A$4:$A$300,$A13)/SUMIFS(Trato_Diario!$G$4:$G$300,Trato_Diario!$A$4:$A$300,$A13)) -> 10.292501
A14: 46223 | B14: =IF(OR($A14>MAX(Trato_Diario!$A$4:$A$300),SUMIFS(Trato_Diario!$G$4:$G$300,Trato_Diario!$B$4:$B$300,1,Trato_Diario!$A$4:$A$300,$A14)=0),"",SUMIFS(Trato_Diario!$J$4:$J$300,Trato_Diario!$B$4:$B$300,1,Trato_Diario!$A$4:$A$300,$A14)/SUMIFS(Trato_Diario!$G$4:$G$300,Trato_Diario!$B$4:$B$300,1,Trato_Diario!$A$4:$A$300,$A14)) -> 11.495178 | C14: =IF(OR($A14>MAX(Trato_Diario!$A$4:$A$300),SUMIFS(Trato_Diario!$G$4:$G$300,Trato_Diario!$B$4:$B$300,2,Trato_Diario!$A$4:$A$300,$A14)=0),"",SUMIFS(Trato_Diario!$J$4:$J$300,Trato_Diario!$B$4:$B$300,2,Trato_Diario!$A$4:$A$300,$A14)/SUMIFS(Trato_Diario!$G$4:$G$300,Trato_Diario!$B$4:$B$300,2,Trato_Diario!$A$4:$A$300,$A14)) -> 12.714386 | D14: =IF(OR($A14>MAX(Trato_Diario!$A$4:$A$300),SUMIFS(Trato_Diario!$G$4:$G$300,Trato_Diario!$B$4:$B$300,3,Trato_Diario!$A$4:$A$300,$A14)=0),"",SUMIFS(Trato_Diario!$J$4:$J$300,Trato_Diario!$B$4:$B$300,3,Trato_Diario!$A$4:$A$300,$A14)/SUMIFS(Trato_Diario!$G$4:$G$300,Trato_Diario!$B$4:$B$300,3,Trato_Diario!$A$4:$A$300,$A14)) -> 10.414415 | E14: =IF(OR($A14>MAX(Trato_Diario!$A$4:$A$300),SUMIFS(Trato_Diario!$G$4:$G$300,Trato_Diario!$B$4:$B$300,4,Trato_Diario!$A$4:$A$300,$A14)=0),"",SUMIFS(Trato_Diario!$J$4:$J$300,Trato_Diario!$B$4:$B$300,4,Trato_Diario!$A$4:$A$300,$A14)/SUMIFS(Trato_Diario!$G$4:$G$300,Trato_Diario!$B$4:$B$300,4,Trato_Diario!$A$4:$A$300,$A14)) -> 9.6921528 | F14: =IF(OR($A14>MAX(Trato_Diario!$A$4:$A$300),SUMIFS(Trato_Diario!$G$4:$G$300,Trato_Diario!$B$4:$B$300,5,Trato_Diario!$A$4:$A$300,$A14)=0),"",SUMIFS(Trato_Diario!$J$4:$J$300,Trato_Diario!$B$4:$B$300,5,Trato_Diario!$A$4:$A$300,$A14)/SUMIFS(Trato_Diario!$G$4:$G$300,Trato_Diario!$B$4:$B$300,5,Trato_Diario!$A$4:$A$300,$A14)) -> 9.1445881 | G14: =IF(OR($A14>MAX(Trato_Diario!$A$4:$A$300),SUMIFS(Trato_Diario!$G$4:$G$300,Trato_Diario!$B$4:$B$300,6,Trato_Diario!$A$4:$A$300,$A14)=0),"",SUMIFS(Trato_Diario!$J$4:$J$300,Trato_Diario!$B$4:$B$300,6,Trato_Diario!$A$4:$A$300,$A14)/SUMIFS(Trato_Diario!$G$4:$G$300,Trato_Diario!$B$4:$B$300,6,Trato_Diario!$A$4:$A$300,$A14)) | H14: =IF(OR($A14>MAX(Trato_Diario!$A$4:$A$300),SUMIFS(Trato_Diario!$G$4:$G$300,Trato_Diario!$B$4:$B$300,7,Trato_Diario!$A$4:$A$300,$A14)=0),"",SUMIFS(Trato_Diario!$J$4:$J$300,Trato_Diario!$B$4:$B$300,7,Trato_Diario!$A$4:$A$300,$A14)/SUMIFS(Trato_Diario!$G$4:$G$300,Trato_Diario!$B$4:$B$300,7,Trato_Diario!$A$4:$A$300,$A14)) | I14: =IF(OR($A14>MAX(Trato_Diario!$A$4:$A$300),SUMIFS(Trato_Diario!$G$4:$G$300,Trato_Diario!$B$4:$B$300,8,Trato_Diario!$A$4:$A$300,$A14)=0),"",SUMIFS(Trato_Diario!$J$4:$J$300,Trato_Diario!$B$4:$B$300,8,Trato_Diario!$A$4:$A$300,$A14)/SUMIFS(Trato_Diario!$G$4:$G$300,Trato_Diario!$B$4:$B$300,8,Trato_Diario!$A$4:$A$300,$A14)) | J14: =IF(OR($A14>MAX(Trato_Diario!$A$4:$A$300),SUMIFS(Trato_Diario!$G$4:$G$300,Trato_Diario!$B$4:$B$300,9,Trato_Diario!$A$4:$A$300,$A14)=0),"",SUMIFS(Trato_Diario!$J$4:$J$300,Trato_Diario!$B$4:$B$300,9,Trato_Diario!$A$4:$A$300,$A14)/SUMIFS(Trato_Diario!$G$4:$G$300,Trato_Diario!$B$4:$B$300,9,Trato_Diario!$A$4:$A$300,$A14)) | K14: =IF(OR($A14>MAX(Trato_Diario!$A$4:$A$300),SUMIFS(Trato_Diario!$G$4:$G$300,Trato_Diario!$B$4:$B$300,10,Trato_Diario!$A$4:$A$300,$A14)=0),"",SUMIFS(Trato_Diario!$J$4:$J$300,Trato_Diario!$B$4:$B$300,10,Trato_Diario!$A$4:$A$300,$A14)/SUMIFS(Trato_Diario!$G$4:$G$300,Trato_Diario!$B$4:$B$300,10,Trato_Diario!$A$4:$A$300,$A14)) | L14: =IF(OR($A14>MAX(Trato_Diario!$A$4:$A$300),SUMIFS(Trato_Diario!$G$4:$G$300,Trato_Diario!$A$4:$A$300,$A14)=0),"",SUMIFS(Trato_Diario!$J$4:$J$300,Trato_Diario!$A$4:$A$300,$A14)/SUMIFS(Trato_Diario!$G$4:$G$300,Trato_Diario!$A$4:$A$300,$A14)) -> 10.292501
A15: 46224 | B15: =IF(OR($A15>MAX(Trato_Diario!$A$4:$A$300),SUMIFS(Trato_Diario!$G$4:$G$300,Trato_Diario!$B$4:$B$300,1,Trato_Diario!$A$4:$A$300,$A15)=0),"",SUMIFS(Trato_Diario!$J$4:$J$300,Trato_Diario!$B$4:$B$300,1,Trato_Diario!$A$4:$A$300,$A15)/SUMIFS(Trato_Diario!$G$4:$G$300,Trato_Diario!$B$4:$B$300,1,Trato_Diario!$A$4:$A$300,$A15)) -> 11.495178 | C15: =IF(OR($A15>MAX(Trato_Diario!$A$4:$A$300),SUMIFS(Trato_Diario!$G$4:$G$300,Trato_Diario!$B$4:$B$300,2,Trato_Diario!$A$4:$A$300,$A15)=0),"",SUMIFS(Trato_Diario!$J$4:$J$300,Trato_Diario!$B$4:$B$300,2,Trato_Diario!$A$4:$A$300,$A15)/SUMIFS(Trato_Diario!$G$4:$G$300,Trato_Diario!$B$4:$B$300,2,Trato_Diario!$A$4:$A$300,$A15)) -> 12.714386 | D15: =IF(OR($A15>MAX(Trato_Diario!$A$4:$A$300),SUMIFS(Trato_Diario!$G$4:$G$300,Trato_Diario!$B$4:$B$300,3,Trato_Diario!$A$4:$A$300,$A15)=0),"",SUMIFS(Trato_Diario!$J$4:$J$300,Trato_Diario!$B$4:$B$300,3,Trato_Diario!$A$4:$A$300,$A15)/SUMIFS(Trato_Diario!$G$4:$G$300,Trato_Diario!$B$4:$B$300,3,Trato_Diario!$A$4:$A$300,$A15)) -> 10.414415 | E15: =IF(OR($A15>MAX(Trato_Diario!$A$4:$A$300),SUMIFS(Trato_Diario!$G$4:$G$300,Trato_Diario!$B$4:$B$300,4,Trato_Diario!$A$4:$A$300,$A15)=0),"",SUMIFS(Trato_Diario!$J$4:$J$300,Trato_Diario!$B$4:$B$300,4,Trato_Diario!$A$4:$A$300,$A15)/SUMIFS(Trato_Diario!$G$4:$G$300,Trato_Diario!$B$4:$B$300,4,Trato_Diario!$A$4:$A$300,$A15)) -> 9.6921528 | F15: =IF(OR($A15>MAX(Trato_Diario!$A$4:$A$300),SUMIFS(Trato_Diario!$G$4:$G$300,Trato_Diario!$B$4:$B$300,5,Trato_Diario!$A$4:$A$300,$A15)=0),"",SUMIFS(Trato_Diario!$J$4:$J$300,Trato_Diario!$B$4:$B$300,5,Trato_Diario!$A$4:$A$300,$A15)/SUMIFS(Trato_Diario!$G$4:$G$300,Trato_Diario!$B$4:$B$300,5,Trato_Diario!$A$4:$A$300,$A15)) -> 9.1445881 | G15: =IF(OR($A15>MAX(Trato_Diario!$A$4:$A$300),SUMIFS(Trato_Diario!$G$4:$G$300,Trato_Diario!$B$4:$B$300,6,Trato_Diario!$A$4:$A$300,$A15)=0),"",SUMIFS(Trato_Diario!$J$4:$J$300,Trato_Diario!$B$4:$B$300,6,Trato_Diario!$A$4:$A$300,$A15)/SUMIFS(Trato_Diario!$G$4:$G$300,Trato_Diario!$B$4:$B$300,6,Trato_Diario!$A$4:$A$300,$A15)) -> 9.786 | H15: =IF(OR($A15>MAX(Trato_Diario!$A$4:$A$300),SUMIFS(Trato_Diario!$G$4:$G$300,Trato_Diario!$B$4:$B$300,7,Trato_Diario!$A$4:$A$300,$A15)=0),"",SUMIFS(Trato_Diario!$J$4:$J$300,Trato_Diario!$B$4:$B$300,7,Trato_Diario!$A$4:$A$300,$A15)/SUMIFS(Trato_Diario!$G$4:$G$300,Trato_Diario!$B$4:$B$300,7,Trato_Diario!$A$4:$A$300,$A15)) -> 10.532971 | I15: =IF(OR($A15>MAX(Trato_Diario!$A$4:$A$300),SUMIFS(Trato_Diario!$G$4:$G$300,Trato_Diario!$B$4:$B$300,8,Trato_Diario!$A$4:$A$300,$A15)=0),"",SUMIFS(Trato_Diario!$J$4:$J$300,Trato_Diario!$B$4:$B$300,8,Trato_Diario!$A$4:$A$300,$A15)/SUMIFS(Trato_Diario!$G$4:$G$300,Trato_Diario!$B$4:$B$300,8,Trato_Diario!$A$4:$A$300,$A15)) | J15: =IF(OR($A15>MAX(Trato_Diario!$A$4:$A$300),SUMIFS(Trato_Diario!$G$4:$G$300,Trato_Diario!$B$4:$B$300,9,Trato_Diario!$A$4:$A$300,$A15)=0),"",SUMIFS(Trato_Diario!$J$4:$J$300,Trato_Diario!$B$4:$B$300,9,Trato_Diario!$A$4:$A$300,$A15)/SUMIFS(Trato_Diario!$G$4:$G$300,Trato_Diario!$B$4:$B$300,9,Trato_Diario!$A$4:$A$300,$A15)) | K15: =IF(OR($A15>MAX(Trato_Diario!$A$4:$A$300),SUMIFS(Trato_Diario!$G$4:$G$300,Trato_Diario!$B$4:$B$300,10,Trato_Diario!$A$4:$A$300,$A15)=0),"",SUMIFS(Trato_Diario!$J$4:$J$300,Trato_Diario!$B$4:$B$300,10,Trato_Diario!$A$4:$A$300,$A15)/SUMIFS(Trato_Diario!$G$4:$G$300,Trato_Diario!$B$4:$B$300,10,Trato_Diario!$A$4:$A$300,$A15)) | L15: =IF(OR($A15>MAX(Trato_Diario!$A$4:$A$300),SUMIFS(Trato_Diario!$G$4:$G$300,Trato_Diario!$A$4:$A$300,$A15)=0),"",SUMIFS(Trato_Diario!$J$4:$J$300,Trato_Diario!$A$4:$A$300,$A15)/SUMIFS(Trato_Diario!$G$4:$G$300,Trato_Diario!$A$4:$A$300,$A15)) -> 10.249916
A16: 46225 | B16: =IF(OR($A16>MAX(Trato_Diario!$A$4:$A$300),SUMIFS(Trato_Diario!$G$4:$G$300,Trato_Diario!$B$4:$B$300,1,Trato_Diario!$A$4:$A$300,$A16)=0),"",SUMIFS(Trato_Diario!$J$4:$J$300,Trato_Diario!$B$4:$B$300,1,Trato_Diario!$A$4:$A$300,$A16)/SUMIFS(Trato_Diario!$G$4:$G$300,Trato_Diario!$B$4:$B$300,1,Trato_Diario!$A$4:$A$300,$A16)) -> 11.495178 | C16: =IF(OR($A16>MAX(Trato_Diario!$A$4:$A$300),SUMIFS(Trato_Diario!$G$4:$G$300,Trato_Diario!$B$4:$B$300,2,Trato_Diario!$A$4:$A$300,$A16)=0),"",SUMIFS(Trato_Diario!$J$4:$J$300,Trato_Diario!$B$4:$B$300,2,Trato_Diario!$A$4:$A$300,$A16)/SUMIFS(Trato_Diario!$G$4:$G$300,Trato_Diario!$B$4:$B$300,2,Trato_Diario!$A$4:$A$300,$A16)) -> 12.714386 | D16: =IF(OR($A16>MAX(Trato_Diario!$A$4:$A$300),SUMIFS(Trato_Diario!$G$4:$G$300,Trato_Diario!$B$4:$B$300,3,Trato_Diario!$A$4:$A$300,$A16)=0),"",SUMIFS(Trato_Diario!$J$4:$J$300,Trato_Diario!$B$4:$B$300,3,Trato_Diario!$A$4:$A$300,$A16)/SUMIFS(Trato_Diario!$G$4:$G$300,Trato_Diario!$B$4:$B$300,3,Trato_Diario!$A$4:$A$300,$A16)) -> 10.414415 | E16: =IF(OR($A16>MAX(Trato_Diario!$A$4:$A$300),SUMIFS(Trato_Diario!$G$4:$G$300,Trato_Diario!$B$4:$B$300,4,Trato_Diario!$A$4:$A$300,$A16)=0),"",SUMIFS(Trato_Diario!$J$4:$J$300,Trato_Diario!$B$4:$B$300,4,Trato_Diario!$A$4:$A$300,$A16)/SUMIFS(Trato_Diario!$G$4:$G$300,Trato_Diario!$B$4:$B$300,4,Trato_Diario!$A$4:$A$300,$A16)) -> 9.6921528 | F16: =IF(OR($A16>MAX(Trato_Diario!$A$4:$A$300),SUMIFS(Trato_Diario!$G$4:$G$300,Trato_Diario!$B$4:$B$300,5,Trato_Diario!$A$4:$A$300,$A16)=0),"",SUMIFS(Trato_Diario!$J$4:$J$300,Trato_Diario!$B$4:$B$300,5,Trato_Diario!$A$4:$A$300,$A16)/SUMIFS(Trato_Diario!$G$4:$G$300,Trato_Diario!$B$4:$B$300,5,Trato_Diario!$A$4:$A$300,$A16)) -> 9.1445881 | G16: =IF(OR($A16>MAX(Trato_Diario!$A$4:$A$300),SUMIFS(Trato_Diario!$G$4:$G$300,Trato_Diario!$B$4:$B$300,6,Trato_Diario!$A$4:$A$300,$A16)=0),"",SUMIFS(Trato_Diario!$J$4:$J$300,Trato_Diario!$B$4:$B$300,6,Trato_Diario!$A$4:$A$300,$A16)/SUMIFS(Trato_Diario!$G$4:$G$300,Trato_Diario!$B$4:$B$300,6,Trato_Diario!$A$4:$A$300,$A16)) -> 9.786 | H16: =IF(OR($A16>MAX(Trato_Diario!$A$4:$A$300),SUMIFS(Trato_Diario!$G$4:$G$300,Trato_Diario!$B$4:$B$300,7,Trato_Diario!$A$4:$A$300,$A16)=0),"",SUMIFS(Trato_Diario!$J$4:$J$300,Trato_Diario!$B$4:$B$300,7,Trato_Diario!$A$4:$A$300,$A16)/SUMIFS(Trato_Diario!$G$4:$G$300,Trato_Diario!$B$4:$B$300,7,Trato_Diario!$A$4:$A$300,$A16)) -> 10.532971 | I16: =IF(OR($A16>MAX(Trato_Diario!$A$4:$A$300),SUMIFS(Trato_Diario!$G$4:$G$300,Trato_Diario!$B$4:$B$300,8,Trato_Diario!$A$4:$A$300,$A16)=0),"",SUMIFS(Trato_Diario!$J$4:$J$300,Trato_Diario!$B$4:$B$300,8,Trato_Diario!$A$4:$A$300,$A16)/SUMIFS(Trato_Diario!$G$4:$G$300,Trato_Diario!$B$4:$B$300,8,Trato_Diario!$A$4:$A$300,$A16)) -> 10.028423 | J16: =IF(OR($A16>MAX(Trato_Diario!$A$4:$A$300),SUMIFS(Trato_Diario!$G$4:$G$300,Trato_Diario!$B$4:$B$300,9,Trato_Diario!$A$4:$A$300,$A16)=0),"",SUMIFS(Trato_Diario!$J$4:$J$300,Trato_Diario!$B$4:$B$300,9,Trato_Diario!$A$4:$A$300,$A16)/SUMIFS(Trato_Diario!$G$4:$G$300,Trato_Diario!$B$4:$B$300,9,Trato_Diario!$A$4:$A$300,$A16)) -> 8.5502679 | K16: =IF(OR($A16>MAX(Trato_Diario!$A$4:$A$300),SUMIFS(Trato_Diario!$G$4:$G$300,Trato_Diario!$B$4:$B$300,10,Trato_Diario!$A$4:$A$300,$A16)=0),"",SUMIFS(Trato_Diario!$J$4:$J$300,Trato_Diario!$B$4:$B$300,10,Trato_Diario!$A$4:$A$300,$A16)/SUMIFS(Trato_Diario!$G$4:$G$300,Trato_Diario!$B$4:$B$300,10,Trato_Diario!$A$4:$A$300,$A16)) | L16: =IF(OR($A16>MAX(Trato_Diario!$A$4:$A$300),SUMIFS(Trato_Diario!$G$4:$G$300,Trato_Diario!$A$4:$A$300,$A16)=0),"",SUMIFS(Trato_Diario!$J$4:$J$300,Trato_Diario!$A$4:$A$300,$A16)/SUMIFS(Trato_Diario!$G$4:$G$300,Trato_Diario!$A$4:$A$300,$A16)) -> 10.186528
